Workbook

Sheet Portada
A1: 1. ANTECEDENTES DE LA EMPRESA | F1: N° de Puestos | G1: Evaluados | H1: Pendientes
A2: Razón Social | B2: FAENADORA SAN VICENTE LTDA | C2: RUT Empresa | D2: 78483600-2 | F2: =COUNTIF(Datos!A:T,"Procesos") -> 68 | G2: =COUNTIF(Datos!T:T,"SI") -> 65 | H2: =COUNTIF(Datos!T:T,"NO") -> 3
A3: Actividad Económica | B3: Explotación de mataderos de aves y de otros tipos de animales n.c.p. | C3: Código CIIU
A4: Dirección | B4: CARRETERA H 66 G KM 19,2 | C4: Comuna | D4: SAN VICENTE
A5: Nombre Representante Legal | B5: SANDRA CALDERON
A6: Organismo administrador al que está adherido | B6: INSTITUTO SALUD DEL TRABAJADOR | C6: Fecha inicio | D6: 45440
A7: 2.- CENTRO DE TRABAJO O LUGAR DE TRABAJO
A8: Nombre del centro de trabajo | B8: Procesos | C8: Nº de trabajadores centro de trabajo
A9: Dirección | B9: CARRETERA H 66 G KM 19,2 | C9: Hombres
A10: Comuna | B10: SAN VICENTE | C10: Mujeres
A11: 3.- RESPONSABLE IMPLEMENTACIÓN PROTOCOLO
A12: Nombre responsable | B12: CONSTANZA ANDREA MUÑOZ CARO | C12: Teléfono | D12: 722312747
A13: Cargo | B13: SUPERVISORA DE ACTIVIDADES ERGONOMICAS
A14: Correo electrónico | B14: CAMUNOZC@AGROSUPER.COM

Sheet Datos
A1: N° | B1: Área de trabajo | C1: Puesto de trabajo | D1: Tareas del puesto de trabajo | E1: Descripción de la tarea | F1: Horario de funcionamiento | G1: Horas extras POR DIA | H1: Horas extras POR SEMANA | I1: N° Trabajadores Expuestos HOMBRE | J1: N° Trabajadores Expuestos MUJER | K1: Tipo de contrato | L1: Tipo de remuneración | M1: Duración (min) | N1: Pausas de Trabajo | O1: Rotación de tarea | P1: Equipos y Herramienta | Q1: Características de los ambientes y espacios de trabajo (Espacios, barreras arquitectónicas, flujo de tránsito) | R1: Características y disposición espacial del puesto de trabajo (Ubicación de los elementos de trabajo, disposición física del espacio de trabajo) | S1: Características y herramientas utilizadas (Descripción de equipos, herramientas utilizadas, herramientas vibrantes, uso de EPP) | T1: Evaluacion SI/NO
A2: 1 | B2: Procesos | C2: Deshuesado de Pechugas | D2: Postura de Pechuga | E2: Colaborador toma pechugas de forma Bimanual posicionandola en porta producto | F2: 07:05 - 15:05 - 15:05 - 00:05 | G2: N/A | H2: 2 | I2: 209 | J2: 101 | K2: Indefinido | L2: Variable | M2: 120 min | N2: Preparatorias - Compensatorias | O2: SI | P2: N/A | Q2: Flujo de transito demarcado, uso de tarimas para transito y posicion frente a puesto de trabajo | R2: Mesa de trabajo que cuenta con tarima para brindar altura, ubicación del puesto dentro de linea productiva bajo techo. | S2: EPP tales como zapatos de seguridad, Proteccion auditiva | T2: SI
A3: 2 | B3: Procesos | C3: Deshuesado de Pechugas | D3: Bajado de Pechugas | E3: Trabajadores se posicionan frente a la linea sentados en silla y de forma bimanual toman la pechuga desplazandola desde el filete, utilizan cuchillo, luego depositan el producto en chute | F3: 07:05 - 15:05 - 15:05 - 00:05 | G3: N/A | H3: 2 | I3: 209 | J3: 101 | K3: Indefinido | L3: Variable | M3: 120 min | N3: Preparatorias - Compensatorias | O3: SI | P3: Cuchillo | Q3: Flujo de transito demarcado, uso de tarimas para transito, uso de silla para posicionarse frente a la linea | R3: Puesto de trabajo con mesa a la altura correspondiente, cuenta con silla parado sentado, sin tarimas, sin exposicion a rayos uv | S3: Utiliza cuhillo para el corte del prodcuto, utilizando EPP tales como guantes anticortes, zapatos de seguridad, Proteccion auditiva | T3: SI
A4: 3 | B4: Procesos | C4: Deshuesado de Pechugas | D4: Prolijado | E4: Deben tomar pechuga que va en porta producto pasando por la linea para posicionarla en meson y con cuchillo retirar grasa | F4: 07:05 - 15:05 - 15:05 - 00:05 | G4: N/A | H4: 2 | I4: 209 | J4: 101 | K4: Indefinido | L4: Variable | M4: 60 Min | N4: Preparatorias - Compensatorias | O4: SI | P4: Cuchillo | Q4: Flujo de transito despejado, cuenta con alfombra antifatiga | R4: Puesto de trabajo sobre alformbras antifatiga, mesa de trabajo a la altura de la cadera, sin tarimas, sin exposicion a rayos uv | S4: Utiliza cuhillo para el corte del prodcuto, utilizando EPP tales como guantes anticortes, zapatos de seguridad, Proteccion auditiva | T4: SI
A5: 4 | B5: Procesos | C5: Deshuesado de Pechugas | D5: Bajado de filete | E5: Trabajadores se posicionan frente a la linea sentados en silla y de forma bimanual toman el filete desplazandola desde la carcasa del pollo depositandolo en chute | F5: 07:05 - 15:05 - 15:05 - 00:05 | G5: N/A | H5: 2 | I5: 209 | J5: 101 | K5: Indefinido | L5: Variable | M5: 60 Min | N5: Preparatorias - Compensatorias | O5: SI | P5: N/A | Q5: Flujo de transito demarcado, cuentan con sillas para posicionarse frente a linea | R5: Puesto de trabajo con mesa a la altura correspondiente, cuenta con silla parado sentado, sin tarimas, sin exposicion a rayos uv | S5: Utiliza cuhillo para el corte del prodcuto, utilizando EPP tales como guantes anticortes, zapatos de seguridad, Proteccion auditiva | T5: SI
A6: 5 | B6: Procesos | C6: Deshuesado de Pechugas | D6: Selección de filete | E6: Con Ambas mano deben rotar las pechugas para su revision de y retiro de hueso | F6: 07:05 - 15:05 - 15:05 - 00:05 | G6: N/A | H6: 2 | I6: 209 | J6: 101 | K6: Indefinido | L6: Variable | M6: 60 Min | N6: Preparatorias - Compensatorias | O6: SI | P6: N/A | Q6: Flujo de transito demarcado, cuentan con tarimas para brindar altura y posicionarse frente a la linea | R6: Puesto de trabajo con mesa a la altura correspondiente, cuenta con silla parado sentado, sobre tarima, sin exposicion a rayos uv | S6: Utiliza cuhillo para el corte del prodcuto, utilizando EPP tales como guantes anticortes, zapatos de seguridad, Proteccion auditiva | T6: SI
A7: 6 | B7: Procesos | C7: Deshuesado de Pechugas | D7: Filete | E7: Colaborador se posiciona frente a la linea, de forma visual revisa el producto, si detecta uno con hueso lo retira para depositarlo en linea | F7: 07:05 - 15:05 - 15:05 - 00:05 | G7: N/A | H7: 2 | I7: 40 | J7: 20 | K7: Indefinido | L7: Variable | M7: 60 Min | N7: Preparatorias - Compensatorias | O7: SI | P7: N/A | Q7: Flujo de transito demarcado, cuentan con silla parado sentado para posicionarse frente a la linea | R7: Puesto de trabajo con linea a la altura del torax cuenta con tarimas, sin exposicion a rayos uv | S7: Utiliza cuhillo para el corte del prodcuto, utilizando EPP tales como guantes anticortes, zapatos de seguridad, Proteccion auditiva | T7: SI
A8: 7 | B8: Procesos | C8: Deshuesado de Pechugas | D8: Tiritas | E8: Colaboradores ordenan producto en linea para que este luego pase por equipo el cual realiza el corte | F8: 07:05 - 15:05 - 15:05 - 00:05 | G8: N/A | H8: 2 | I8: 40 | J8: 20 | K8: Indefinido | L8: Variable | M8: 60 Min | N8: Preparatorias - Compensatorias | O8: SI | P8: N/A | Q8: Flujo demarcado, libre de barreras. | R8: Puesto de trabajo con mesa a la altura correspondiente, sobre tarima, sin exposicion a rayos uv | S8: Utiliza cuhillo para el corte del prodcuto, utilizando EPP tales como guantes anticortes, zapatos de seguridad, Proteccion auditiva | T8: SI
A9: 8 | B9: Procesos | C9: Deshuesado de Pechugas | D9: Piel | E9: Inspeccionar que piel no presente otras estructuras (huesos), la cual una vez inspeccionada esta es desplazada a bins de manera manual (en ocasiones se ayudan de rastrillo que pesa 80 gramos). | F9: 07:05 - 15:05 - 15:05 - 00:05 | G9: N/A | H9: 2 | I9: 40 | J9: 20 | K9: Indefinido | L9: Variable | M9: 60 Min | N9: Preparatorias - Compensatorias | O9: SI | P9: Rastrillo | Q9: Flujos de transito demarcado cuentan con tarima para brindar altura al estar revisando producto | R9: Puesto de trabajo sin mesa de trabajo, cuenta con tarima, sin exposicion a rayos uv | S9: Utiliza cuhillo para el corte del prodcuto, utilizando EPP tales como guantes anticortes, zapatos de seguridad, Proteccion auditiva | T9: SI
A10: 9 | B10: Procesos | C10: Deshuesado de Pechugas | D10: Recepcion de bins | E10: Verificar llenado de bins y cambiarlo con ayuda de tras paletero. En ocaciones se utilizan combos (cajas de carton) | F10: 07:05 - 15:05 - 15:05 - 00:05 | G10: N/A | H10: 2 | I10: 40 | J10: 20 | K10: Indefinido | L10: Variable | M10: 60 Min | N10: Preparatorias - Compensatorias | O10: SI | P10: N/A | Q10: Flujos en sala con demarcaciones | R10: Puesto de trabajo sin exposicion a rayor uv, flujo de transpaletas en puesto de trabajo | S10: Utiliza cuhillo para el corte del prodcuto, utilizando EPP tales como guantes anticortes, zapatos de seguridad, Proteccion auditiva | T10: SI
A11: 10 | B11: Procesos | C11: Deshuesado de Pechugas | D11: Reproceso | E11: Colaborador cuenta con gancho de reproceso, recorre lineas recogiendo producto que se encuentre en el piso y depositandolo en bandeja para luego lavar y reprocesarlo | F11: 07:05 - 15:05 - 15:05 - 00:05 | G11: N/A | H11: 2 | I11: 40 | J11: 20 | K11: Indefinido | L11: Variable | M11: 60 Min | N11: Preparatorias - Compensatorias | O11: SI | P11: Gancho | Q11: Flujos en sala con demarcaciones | R11: Puesto de trabajo sin exposicion a rayor uv | S11: Utiliza cuhillo para el corte del prodcuto, utilizando EPP tales como guantes anticortes, zapatos de seguridad, Proteccion auditiva | T11: SI
A12: 11 | B12: Procesos | C12: Deshuesado de Pechugas | D12: Clavicula | E12: Colaborador recolecta pechugas que presentan hueso de clavicula, lo retira con ayuda de cuchillo | F12: 07:05 - 15:05 - 15:05 - 00:05 | G12: N/A | H12: 2 | I12: 40 | J12: 20 | K12: Indefinido | L12: Variable | M12: 60 Min | N12: Preparatorias - Compensatorias | O12: SI | P12: Cuchillo | Q12: Flujos de transito demarcado cuentan con tarima para brindar altura al estar revisando producto | R12: Puesto de trabajo con linea a la altura de la cadera cuenta con tarimas, sin exposicion a rayos uv | S12: Utiliza cuhillo para el corte del prodcuto, utilizando EPP tales como guantes anticortes, zapatos de seguridad, Proteccion auditiva | T12: SI
A13: 12 | B13: Procesos | C13: Deshuesado de Pechugas | D13: Transpaletero | E13: Transportar con transpaleta eléctrica productos en pallet o bins desde y hacia distintas aéreas | F13: 07:05 - 15:05 - 15:05 - 00:05 | G13: N/A | H13: 2 | I13: 40 | J13: 20 | K13: Indefinido | L13: Variable | M13: 60 Min | N13: Preparatorias - Compensatorias | O13: SI | P13: Equipo Rodante Transpaleta | Q13: Flujo de transito demarcado para transito de transpaletas | R13: Puesto de trabajo sobre equipo rodante que recorre planta general para traslado d eproductos sin exposicion a radiacion uv | S13: Utiliza cuhillo para el corte del prodcuto, utilizando EPP tales como guantes anticortes, zapatos de seguridad, Proteccion auditiva | T13: NO
... A22: 21 | B22: Procesos | C22: Envasado | D22: alimentador Envasado multicabezal | E22: Colaboradora alimenta maquina con cajas plasticas | F22: 07:20 - 15:30 / 15:30 - 01:05 | G22: N/A | H22: 2 | I22: 36 | J22: 52 | K22: Indefinido | L22: Variable | M22: 60 Min | N22: Preparatorias - Compensatorias | O22: SI | P22: N/A | Q22: Flujo demarcado, libre de barreras. | R22: Alcance libre de productos | S22: Utiliza cuhillo para el corte del prodcuto, utilizando EPP tales como guantes anticortes, zapatos de seguridad, Proteccion auditiva | T22: SI
A23: 22 | B23: Procesos | C23: Envasado | D23: Carro materiales | E23: Personal de desplay y maquinista entran materiales de bodega con carro de cuatro ruedas o manualmente cuando es poca cantidad | F23: 07:20 - 15:30 / 15:30 - 01:05 | G23: N/A | H23: 2 | I23: 36 | J23: 52 | K23: Indefinido | L23: Variable | N23: Preparatorias - Compensatorias | O23: SI | P23: Carro transporte | Q23: Flujo demarcado, libre de barreras. | R23: Sin exposicion a UV, alcance de productos sin disficultad | S23: Utiliza cuhillo para el corte del prodcuto, utilizando EPP tales como guantes anticortes, zapatos de seguridad, Proteccion auditiva | T23: SI
A24: 23 | B24: Procesos | C24: Envasado | D24: Maquinista Termoselladora | E24: Da partida y detiene maquina,regulan, ponen rollos de desplay, traen rollos de bodega en carro de 4 ruedas mantiene limpieza de maquina, | F24: 07:00 - 15:00 / 16:00 - 01:05 | G24: N/A | H24: 2 | I24: 36 | J24: 52 | K24: Indefinido | L24: Variable | M24: 360 Min | N24: Preparatorias - Compensatorias | O24: SI | P24: Carro de transporte | Q24: Flujo demarcado, libre de barreras. | R24: Puesto de trabajo libre de obstaculos sin mesa de trabajo fija | S24: Utiliza cuhillo para el corte del prodcuto, utilizando EPP tales como guantes anticortes, zapatos de seguridad, Proteccion auditiva | T24: SI
A25: 24 | B25: Procesos | C25: Envasado | D25: Llenado de bandeja con pala | E25: Se realiza movimiento de producto desde bins a linea con pala plastica en todas las lineas envasado. | F25: 07:20 - 15:30 / 15:30 - 01:05 | G25: N/A | H25: 2 | I25: 36 | J25: 0 | K25: Indefinido | L25: Variable | M25: 120 min | N25: Preparatorias - Compensatorias | O25: SI | P25: Pala | Q25: Flujo demarcado, libre de barreras. | R25: Libre de obstaculos, sin mesa de trabajo | S25: Utiliza cuhillo para el corte del prodcuto, utilizando EPP tales como guantes anticortes, zapatos de seguridad, Proteccion auditiva | T25: SI
A26: 25 | B26: Procesos | C26: Envasado | D26: Levantamiento de bandeja | E26: Colaborador saca producto en bandeja para ser distribuida. | F26: 07:20 - 15:30 / 15:30 - 01:05 | G26: N/A | H26: 2 | I26: 36 | J26: 0 | K26: Indefinido | L26: Variable | M26: 60 Min | N26: Preparatorias - Compensatorias | O26: SI | P26: N/A | Q26: Flujo demarcado, libre de barreras. | R26: Libre de manipulacion de objetos de trabajo, sin exposicion a UV | S26: Utiliza cuhillo para el corte del prodcuto, utilizando EPP tales como guantes anticortes, zapatos de seguridad, Proteccion auditiva | T26: SI
A27: 26 | B27: Procesos | C27: Mesanina | D27: Puesto Fijo | E27: Revision visual de ave que pasa por carrusel y retiro de esta en caso de cumplir por calidad, siendo sacada y depositada en bandeja | G27: N/A | H27: 2 | I27: 32 | J27: 20 | K27: Indefinido | L27: Variable | M27: 120 Min | N27: Preparatorias - Compensatorias | O27: SI | P27: Gancho | Q27: Flujo demarcado, libre de barreras. | R27: sin mesa de trabajo linea aerea para observar aves | S27: Utiliza cuhillo para el corte del prodcuto, utilizando EPP tales como guantes anticortes, zapatos de seguridad, Proteccion auditiva | T27: SI
A28: 27 | B28: Procesos | C28: Mesanina | D28: Centro Punta | E28: Colaborador retira ala desde linea posiciona en bandeja y va separando la punta de ala desde centro de ala mediante corte con cuchillo | G28: N/A | H28: 2 | I28: 32 | J28: 20 | K28: Indefinido | L28: Variable | M28: 60 Min | N28: Preparatorias - Compensatorias | O28: SI | P28: cuchillo | Q28: Flujo demarcado, libre de barreras. | R28: Mesa de trabajo a la altura del torax, con alcances de linea adecuados. | S28: Utiliza cuhillo para el corte del prodcuto, utilizando EPP tales como guantes anticortes, zapatos de seguridad, Proteccion auditiva | T28: SI
A29: 28 | B29: Procesos | C29: Mesanina | D29: Reenganchador | E29: Inspeccion visual de ave que pasa por carrusel, revisa pollos colgados de una pata para colgar, y cuelga en ganchos vacios aves. | G29: N/A | H29: 2 | I29: 32 | J29: 20 | K29: Indefinido | L29: Variable | M29: 120 min | N29: Preparatorias - Compensatorias | O29: SI | P29: N/A | Q29: Flujo demarcado, libre de barreras. | R29: sin mesa de trabajo, libre de obstaculos. | S29: Utiliza cuhillo para el corte del prodcuto, utilizando EPP tales como guantes anticortes, zapatos de seguridad, Proteccion auditiva | T29: SI
A30: 29 | B30: Procesos | C30: Mesanina | D30: Cazuelero | E30: Pollo que es retirado de carrusel debe ser trozado de forma manual depositando diferentes partes del ave en bandejas | G30: N/A | H30: 2 | I30: 32 | J30: 20 | K30: Indefinido | L30: Variable | M30: 60 min | N30: Preparatorias - Compensatorias | O30: SI | P30: cuchillo | Q30: Flujo demarcado, libre de barreras. | R30: Mesa de trabajo con porta cuchillo | S30: Utiliza cuhillo para el corte del prodcuto, utilizando EPP tales como guantes anticortes, zapatos de seguridad, Proteccion auditiva | T30: SI
A31: 30 | B31: Procesos | C31: Mesanina | D31: Reproceso | E31: Recoge producto de piso de todas la líneas las cuales son depositadas en bandejas las cuales son trasladadas a las estación de reproceso para sanitizarlo. Utilizan gancho para acercar productos que se encuentren bajo las lineas | G31: N/A | H31: 2 | I31: 32 | J31: 20 | K31: Indefinido | L31: Variable | M31: 60 min | N31: Preparatorias - Compensatorias | O31: SI | P31: Gancho | Q31: Flujo demarcado, libre de barreras. | R31: Elementos a la altura necesaria para el alcance con porta gancho en el carro | S31: Utiliza cuhillo para el corte del prodcuto, utilizando EPP tales como guantes anticortes, zapatos de seguridad, Proteccion auditiva | T31: SI
A32: 31 | B32: Procesos | C32: Mesanina | D32: Transporte Cazuela | E32: Realiza transporte de producto (Cazuela) en carro para luego depositarlo en linea. | G32: N/A | H32: 3 | I32: 32 | J32: 20 | K32: Indefinido | L32: Variable | N32: Preparatorias - Compensatorias | O32: SI | P32: N/A | Q32: Flujo demarcado, libre de barreras. | R32: Sin mesa de trabajo, con carro de transporte de 4 ruedas y aza para manipulacion | S32: Utiliza cuhillo para el corte del prodcuto, utilizando EPP tales como guantes anticortes, zapatos de seguridad, Proteccion auditiva | T32: SI
A33: 32 | B33: Procesos | C33: Mesanina | D33: Maquinista | E33: Da partida y detiene maquina,regulan, ponen rollos de desplay, traen rollos de bodega en carro de 4 ruedas mantiene limpieza de maquina, | G33: N/A | H33: 2 | I33: 2 | J33: 0 | K33: Indefinido | L33: Variable | M33: 60 Min | N33: Preparatorias - Compensatorias | O33: SI | P33: N/A | Q33: Flujo demarcado, libre de barreras. | R33: Puesto de trabajo sin exposicion a radiacion UV | S33: Utiliza cuhillo para el corte del prodcuto, utilizando EPP tales como guantes anticortes, zapatos de seguridad, Proteccion auditiva | T33: SI
A34: 33 | B34: Procesos | C34: Paletizado Fresco | D34: Postura de bolsa y pañal | E34: Extrae cajas desde línea aérea para luego colocar bolsa y pañal en su interior | F34: 06:45 - 15:55 / 14:55 - 00:20 | G34: N/A | H34: 2 | I34: 96 | J34: 6 | K34: Indefinido | L34: Variable | M34: 150 Min | N34: Preparatorias | O34: SI | P34: N/A | Q34: Flujo demarcado, libre de barreras. | R34: Mesa de trabajo con polines para arrastre de cajas | S34: Utiliza cuhillo para el corte del zuncho, utilizando EPP tales, zapatos de seguridad, Proteccion auditiva | T34: SI
A35: 34 | B35: Procesos | C35: Paletizado Fresco | D35: PC global | E35: Con pistola verificadora de códigos captura códigos de cajas que vienen por linea, los imprime y pega en cajas | F35: 06:45 - 15:55 / 14:55 - 00:20 | G35: N/A | H35: 2 | I35: 13 | J35: 1 | K35: Indefinido | L35: Variable | M35: 300 min | N35: Preparatorias | O35: SI | P35: Computador - Pistola capturadora | Q35: Flujo demarcado, libre de barreras. | R35: Mesa de trabajo con polines para arrastre de cajas | S35: Utiliza cuhillo para el corte del prodcuto, utilizando EPP tales, zapatos de seguridad, Proteccion auditiva | T35: SI
A36: 35 | B36: Procesos | C36: Paletizado Fresco | D36: Transpaletero | E36: Transportar con transpaleta electrica productos en pallet o bins desde y hacia distintas áreas | F36: 06:45 - 15:55 / 14:55 - 00:20 | G36: N/A | H36: 2 | I36: 96 | J36: 6 | K36: Indefinido | L36: Variable | N36: Preparatorias | O36: SI | P36: Transpaleta | Q36: Flujo demarcado, libre de barreras. | S36: Utiliza cuhillo para el corte del prodcuto, utilizando EPP tales, zapatos de seguridad, Proteccion auditiva y chaleco reflectante | T36: NO
A37: 36 | B37: Procesos | C37: Paletizado Fresco | D37: Maquinista | E37: Verifica visualmente Funcionamiento de maquinas, realizar limpieza tunel semil, tunel POLYPACK 1,2 y3 y tunel selladora ROCHMAN 1 Y 2 | F37: 06:45 - 15:55 / 14:55 - 00:20 | G37: N/A | H37: 2 | I37: 96 | J37: 6 | K37: Indefinido | L37: Variable | N37: Preparatorias | O37: SI | P37: Maquina Critica | Q37: Flujo demarcado, libre de barreras. | R37: Labores desarrolladas en maquina | S37: Utiliza cuhillo para el corte del prodcuto, utilizando EPP tales, zapatos de seguridad, Proteccion auditiva | T37: SI
A38: 37 | B38: Procesos | C38: Paletizado Fresco | D38: Administrativo | E38: Realiza Digitación en PC | F38: 06:45 - 15:55 / 14:55 - 00:20 | G38: N/A | H38: 2 | I38: 96 | J38: 6 | K38: Indefinido | L38: Variable | N38: Preparatorias | O38: SI | P38: Computador | Q38: Flujo demarcado, libre de barreras. | R38: Computador en oficina, libre de filtro UV | S38: Utiliza cuhillo para el corte del prodcuto, utilizando EPP tales, zapatos de seguridad, Proteccion auditiva | T38: SI
A39: 38 | B39: Procesos | C39: Paletizado Fresco | D39: Jefe de Línea | E39: Inspeccionar y velar por el correcto funcionamiento productivo y seguridad de los trabajadores. | F39: 06:45 - 15:55 / 14:55 - 00:20 | G39: N/A | H39: 2 | I39: 96 | J39: 6 | K39: Indefinido | L39: Variable | N39: Preparatorias | O39: SI | P39: N/A | Q39: Flujo demarcado, libre de barreras. | R39: Computador en oficina, libre de filtro UV | S39: Utiliza cuhillo para el corte del prodcuto, utilizando EPP tales, zapatos de seguridad, Proteccion auditiva | T39: SI
A40: 39 | B40: Procesos | C40: Paletizado Fresco | D40: Paletizador | E40: Paletizan cajas con producto. Al terminar colocan esquineros de cartón en pallets con producto terminado, en donde también envuelven estos pallets con film manual. | F40: 06:45 - 15:55 / 14:55 - 00:20 | G40: N/A | H40: 2 | I40: 96 | J40: 6 | K40: Indefinido | L40: Variable | M40: 150 Min | N40: Preparatorias | O40: SI | P40: N/A | Q40: Flujo demarcado, libre de barreras. | R40: Libre de obstaculos con mesa de polines para deslizamiento de carga | S40: Utiliza cuhillo para el corte del prodcuto, utilizando EPP tales, zapatos de seguridad, Proteccion auditiva | T40: SI
A41: 40 | B41: Procesos | C41: Paletizado Fresco | D41: Supervisor | E41: Inspeccionar y velar por el correcto funcionamiento productivo y seguridad de los trabajadores. | F41: 06:45 - 15:55 / 14:55 - 00:20 | G41: N/A | H41: 2 | I41: 96 | J41: 6 | K41: Indefinido | L41: Variable | N41: Preparatorias | O41: SI | P41: N/A | Q41: Flujo demarcado, libre de barreras. | R41: Libre de exposicion a radiacion uv, trabajo de oficina | S41: Utiliza cuhillo para el corte del prodcuto, utilizando EPP tales, zapatos de seguridad, Proteccion auditiva | T41: SI
A42: 41 | B42: Procesos | C42: Trozado L1 | D42: Pesador de producto derecha | E42: Se llenan cajas con productos de pollos los cuales son sacados de cintas transportadoras, pesan las cajas en balanzas, se embalan para luego depositarlas en cintas. | F42: 07:05 - 15:05 15:15 - 00:15 | G42: N/A | H42: 2 | I42: 66 | J42: 73 | K42: Indefinido | L42: Variable | M42: 120 Min | N42: Preparatorias - Compensatorias | O42: SI | P42: N/A | Q42: Flujo demarcado, libre de barreras. | R42: Mesa de trabajo a la altura de la cadera alcalces adecuado | S42: Utiliza cuhillo para el corte del prodcuto, utilizando EPP tales, zapatos de seguridad, Proteccion auditiva | T42: SI
A43: 42 | B43: Procesos | C43: Trozado L2 | D43: Pesador de producto izquierda | E43: Se llenan cajas con productos de pollos los cuales son sacados de cintas transportadoras, pesan las cajas en balanzas, se embalan para luego depositarlas en cintas. | F43: 07:05 - 15:05 15:15 - 00:15 | G43: N/A | H43: 2 | I43: 66 | J43: 73 | K43: Indefinido | L43: Variable | M43: 120 Min | N43: Preparatorias - Compensatorias | O43: SI | P43: N/A | Q43: Flujo demarcado, libre de barreras. | R43: Mesa de trabajo a la altura de la cadera alcalces adecuado | S43: Utiliza cuhillo para el corte del prodcuto, utilizando EPP tales, zapatos de seguridad, Proteccion auditiva | T43: SI
A44: 43 | B44: Procesos | C44: Trozado L5 | D44: Selección de (trutro) | E44: Se extrae todo trutro que presente costilla. | F44: 07:05 - 15:05 15:15 - 00:15 | G44: N/A | H44: 2 | I44: 66 | J44: 73 | K44: Indefinido | L44: Variable | M44: 60 min | N44: Preparatorias - Compensatorias | O44: SI | P44: N/A | Q44: Flujo demarcado, libre de barreras. | R44: Sobre tarima, con sillas para trabajar linealmente | S44: Utiliza cuhillo para el corte del producto, utilizando EPP tales, zapatos de seguridad, Proteccion auditiva | T44: SI
A45: 44 | B45: Procesos | C45: Trozado L1 | D45: Embalado de producto en termoformadora | E45: Se extrae producto desde tolva y es embalado en cajas pequeñas | F45: 07:05 - 15:05 15:15 - 00:15 | G45: N/A | H45: 2 | I45: 66 | J45: 73 | K45: Indefinido | L45: Variable | M45: 60 min | N45: Preparatorias - Compensatorias | O45: SI | P45: N/A | Q45: Flujo demarcado, libre de barreras. | R45: Colaboradores sobre tarimas, con mesa de trabajo a la altura de la cadera | S45: Utiliza cuhillo para el corte del prodcuto, utilizando EPP tales, zapatos de seguridad, Proteccion auditiva | T45: SI
A46: 45 | B46: Procesos | C46: Trozado L1 | D46: Chequeador de peso | E46: Colaborador supervisa producto de forma visual y debe regular el peso establecidos con las cajas con producto, de ser necesario | F46: 07:05 - 15:05 15:15 - 00:15 | G46: N/A | H46: 2 | I46: 66 | J46: 73 | K46: Indefinido | L46: Variable | M46: 60 Min | N46: Preparatorias - Compensatorias | O46: SI | P46: N/A | Q46: Flujo demarcado, libre de barreras. | R46: Mesa con polines para arrastre de cajas | S46: Utiliza cuhillo para el corte del prodcuto, utilizando EPP tales, zapatos de seguridad, Proteccion auditiva | T46: SI
A47: 46 | B47: Procesos | C47: Trozado L2 | D47: Traslape | E47: Colaborador supervisa producto y lo tapa de ser requerido. | F47: 06:45 - 15:05 15:05 - 23:55 | G47: N/A | H47: 2 | I47: 66 | J47: 73 | K47: Indefinido | L47: Variable | M47: 60 min | N47: Preparatorias - Compensatorias | O47: SI | P47: N/A | Q47: Flujo demarcado, libre de barreras. | R47: mesa de trabajo lineal, libre de obstaculos. | S47: Utiliza cuhillo para el corte del prodcuto, utilizando EPP tales, zapatos de seguridad, Proteccion auditiva | T47: SI
A48: 47 | B48: Procesos | C48: Trozado L1 | D48: Volteador de bins | E48: Colaborado es encargado de abastecer de producto a speet batcher. Con transpaleta posicionan bins con producto en volteador automatizado. Luego retiran bins desocupando de manera manual. | F48: 07:05 - 15:05 15:15 - 00:15 | G48: N/A | H48: 2 | I48: 66 | J48: 0 | K48: Indefinido | L48: Variable | M48: 60 Min | N48: Preparatorias - Compensatorias | O48: SI | P48: Transpaleta | Q48: Flujo demarcado, libre de barreras. | R48: Sin mesa de trabajo, manipulación desde botonera | S48: Utiliza cuhillo para el corte del prodcuto, utilizando EPP tales, zapatos de seguridad, Proteccion auditiva | T48: SI
...

Sheet Inicial
A1: N° | C1: Puesto de trabajo | D1: Tareas del puesto de trabajo | E1: Horario de funcionamiento | F1: Horas extras POR DIA | G1: Horas extras POR SEMANA | H1: N° Trabajadores Expuestos HOMBRE | I1: N° Trabajadores Expuestos MUJER | J1: Trabajo repetitivo de miembros superiores. | K1: Postura de trabajo estática - Forzada | L1: MMC Levantamiento/Descenso | M1: MMC Empuje/Arrastre | N1: Manejo manual de pacientes / personas | O1: Vibración de cuerpo completo | P1: Vibración segmento mano – brazo | Q1: Resultado identificación inicial
B2: Area | J2: ¿Existe una o más tareas donde utilice las manos y miembros superiores con una duración total de una hora o más durante la jornada laboral y con un tiempo total de 5 o más horas a la semana? Por ejemplo: Donde se tenga que armar, limpiar, apretar, lanzar, cortar, presionar, desarmar, atornillar, desatornillar, digitar. 1 tarea repetitiva: conjunto de ciclos de trabajo realizados por uno o más segmentos de las extremidades superiores, donde repetitividad se caracteriza por al menos uno de los siguientes criterios: i) El tiempo de ciclo es inferior a 30 segundos en promedio. ii) Los mismos patrones biomecánicos se repiten por más del 50% del ciclo. En general, el ritmo de trabajo está determinado por factor externo al trabajador, ejemplo, líneas de producción, velocidad de una máquina, entre otros | K2: Existen posturas de trabajo estáticas de cabeza/cuello, tronco y/o miembros superiores e inferiores, mantenidas durante más de 4 segundos, en la que se pueden dar ligeras variaciones alrededor de un mismo nivel de fuerza generado por los músculos y otras estructuras corporales? Por ejemplo: Donde se observe estar con la cabeza inclinada hacia adelante o atrás, cabeza rotada permanentemente hacia algún lado, hombros situados por delante de las caderas de manera continua, tronco rotado o inclinado para sostener o movilizar objetos | L2: Para el Levantamiento/Descenso/Transporte: ¿Existe levantamiento, descenso o transporte manual de un objeto de 3kg o más? Por ejemplo: Se observa que levanta, sostiene, transporta, desplaza, moviliza, ubica con precisión ordenando, apila, paletiza. | M2: Tracción/Empuje ¿Existe empuje o arrastre de una carga utilizando el cuerpo completo con 1 o 2 manos? Se observa el empuje y/o arrastre de diferentes maneras carros, plataformas con rueda, superficies deslizantes, detención de objetos en movimiento, camillas, camas, sillas de rueda, paletizadores, grúas de uso manual mecanizadas, formas de tracción y empuje hechizas, carretillas. No se considera empuje y arrastre carros motorizados y controlados manualmente (conducción) | N2: ¿Se realiza alguna actividad que requiere fuerza para empujar, tirar, levantar, descender, transferir o de alguna manera mover o sostener una persona o parte del cuerpo de una persona? *NOTA: La condición a identificar debe incluir la actividad de manipulación, ya sea que se realice con o sin dispositivos de asistencia. Esta condición está determinada por el riesgo asociado a las características de la carga humana que requiere control sensible de la masa corporal por parte del operador. | O2: Están los trabajadores en contacto con una fuente de vibración de cuerpo entero perceptible por el trabajador/a? Se presenta en cercanía de máquinas donde se percibe la vibración, superficies vibrantes donde se está de pie o sentado como en maquinaria pesada y de conducción. | P2: Están los trabajadores/as en contacto con una fuente de vibración perceptible por el trabajador del segmento mano-brazo? Por ejemplo: Se presenta en situaciones de manejo de herramientas neumáticas o eléctricas, atornilladores o destornilladores neumáticos o eléctricos, uso de herramientas con impacto como martillos, cinceles, herramientas percutoras como taladros
A3: =Datos!A2 -> 1 | B3: =Datos!B2 -> Procesos | C3: =Datos!C2 -> Deshuesado de Pechugas | D3: =Datos!D2 -> Postura de Pechuga | E3: =Datos!F2 -> 07:05 - 15:05 - 15:05 - 00:05 | F3: =Datos!G2 -> N/A | G3: =Datos!H2 -> 2 | H3: =Datos!I2 -> 209 | I3: =Datos!J2 -> 101 | J3: SI | K3: NO | L3: NO | M3: NO | N3: NO | O3: NO | P3: NO | Q3: =IF(AND(J3="NO",K3="NO",L3="NO",M3="NO",N3="NO",O3="NO",P3="NO"),"Ausencia total del riesgo, reevaluar cada 3 años con nueva identificación inicial","Aplicar identificación avanzada-condición aceptable para cada tipo de factor de riesgo identificado") -> Aplicar identificación avanzada-condición aceptable para cada tipo de factor de riesgo identificado
A4: =Datos!A3 -> 2 | B4: =Datos!B3 -> Procesos | C4: =Datos!C3 -> Deshuesado de Pechugas | D4: =Datos!D3 -> Bajado de Pechugas | E4: =Datos!F3 -> 07:05 - 15:05 - 15:05 - 00:05 | F4: =Datos!G3 -> N/A | G4: =Datos!H3 -> 2 | H4: =Datos!I3 -> 209 | I4: =Datos!J3 -> 101 | J4: SI | K4: NO | L4: NO | M4: NO | N4: NO | O4: NO | P4: NO | Q4: =IF(AND(J4="NO",K4="NO",L4="NO",M4="NO",N4="NO",O4="NO",P4="NO"),"Ausencia total del riesgo, reevaluar cada 3 años con nueva identificación inicial","Aplicar identificación avanzada-condición aceptable para cada tipo de factor de riesgo identificado") -> Aplicar identificación avanzada-condición aceptable para cada tipo de factor de riesgo identificado
A5: =Datos!A4 -> 3 | B5: =Datos!B4 -> Procesos | C5: =Datos!C4 -> Deshuesado de Pechugas | D5: =Datos!D4 -> Prolijado | E5: =Datos!F4 -> 07:05 - 15:05 - 15:05 - 00:05 | F5: =Datos!G4 -> N/A | G5: =Datos!H4 -> 2 | H5: =Datos!I4 -> 209 | I5: =Datos!J4 -> 101 | J5: SI | K5: NO | L5: NO | M5: NO | N5: NO | O5: NO | P5: NO | Q5: =IF(AND(J5="NO",K5="NO",L5="NO",M5="NO",N5="NO",O5="NO",P5="NO"),"Ausencia total del riesgo, reevaluar cada 3 años con nueva identificación inicial","Aplicar identificación avanzada-condición aceptable para cada tipo de factor de riesgo identificado") -> Aplicar identificación avanzada-condición aceptable para cada tipo de factor de riesgo identificado
A6: =Datos!A5 -> 4 | B6: =Datos!B5 -> Procesos | C6: =Datos!C5 -> Deshuesado de Pechugas | D6: =Datos!D5 -> Bajado de filete | E6: =Datos!F5 -> 07:05 - 15:05 - 15:05 - 00:05 | F6: =Datos!G5 -> N/A | G6: =Datos!H5 -> 2 | H6: =Datos!I5 -> 209 | I6: =Datos!J5 -> 101 | J6: SI | K6: NO | L6: NO | M6: NO | N6: NO | O6: NO | P6: NO | Q6: =IF(AND(J6="NO",K6="NO",L6="NO",M6="NO",N6="NO",O6="NO",P6="NO"),"Ausencia total del riesgo, reevaluar cada 3 años con nueva identificación inicial","Aplicar identificación avanzada-condición aceptable para cada tipo de factor de riesgo identificado") -> Aplicar identificación avanzada-condición aceptable para cada tipo de factor de riesgo identificado
A7: =Datos!A6 -> 5 | B7: =Datos!B6 -> Procesos | C7: =Datos!C6 -> Deshuesado de Pechugas | D7: =Datos!D6 -> Selección de filete | E7: =Datos!F6 -> 07:05 - 15:05 - 15:05 - 00:05 | F7: =Datos!G6 -> N/A | G7: =Datos!H6 -> 2 | H7: =Datos!I6 -> 209 | I7: =Datos!J6 -> 101 | J7: SI | K7: NO | L7: NO | M7: NO | N7: NO | O7: NO | P7: NO | Q7: =IF(AND(J7="NO",K7="NO",L7="NO",M7="NO",N7="NO",O7="NO",P7="NO"),"Ausencia total del riesgo, reevaluar cada 3 años con nueva identificación inicial","Aplicar identificación avanzada-condición aceptable para cada tipo de factor de riesgo identificado") -> Aplicar identificación avanzada-condición aceptable para cada tipo de factor de riesgo identificado
A8: =Datos!A7 -> 6 | B8: =Datos!B7 -> Procesos | C8: =Datos!C7 -> Deshuesado de Pechugas | D8: =Datos!D7 -> Filete | E8: =Datos!F7 -> 07:05 - 15:05 - 15:05 - 00:05 | F8: =Datos!G7 -> N/A | G8: =Datos!H7 -> 2 | H8: =Datos!I7 -> 40 | I8: =Datos!J7 -> 20 | J8: SI | K8: NO | L8: NO | M8: NO | N8: NO | O8: NO | P8: NO | Q8: =IF(AND(J8="NO",K8="NO",L8="NO",M8="NO",N8="NO",O8="NO",P8="NO"),"Ausencia total del riesgo, reevaluar cada 3 años con nueva identificación inicial","Aplicar identificación avanzada-condición aceptable para cada tipo de factor de riesgo identificado") -> Aplicar identificación avanzada-condición aceptable para cada tipo de factor de riesgo identificado
A9: =Datos!A8 -> 7 | B9: =Datos!B8 -> Procesos | C9: =Datos!C8 -> Deshuesado de Pechugas | D9: =Datos!D8 -> Tiritas | E9: =Datos!F8 -> 07:05 - 15:05 - 15:05 - 00:05 | F9: =Datos!G8 -> N/A | G9: =Datos!H8 -> 2 | H9: =Datos!I8 -> 40 | I9: =Datos!J8 -> 20 | J9: SI | K9: NO | L9: NO | M9: NO | N9: NO | O9: NO | P9: NO | Q9: =IF(AND(J9="NO",K9="NO",L9="NO",M9="NO",N9="NO",O9="NO",P9="NO"),"Ausencia total del riesgo, reevaluar cada 3 años con nueva identificación inicial","Aplicar identificación avanzada-condición aceptable para cada tipo de factor de riesgo identificado") -> Aplicar identificación avanzada-condición aceptable para cada tipo de factor de riesgo identificado
A10: =Datos!A9 -> 8 | B10: =Datos!B9 -> Procesos | C10: =Datos!C9 -> Deshuesado de Pechugas | D10: =Datos!D9 -> Piel | E10: =Datos!F9 -> 07:05 - 15:05 - 15:05 - 00:05 | F10: =Datos!G9 -> N/A | G10: =Datos!H9 -> 2 | H10: =Datos!I9 -> 40 | I10: =Datos!J9 -> 20 | J10: SI | K10: NO | L10: NO | M10: NO | N10: NO | O10: NO | P10: NO | Q10: =IF(AND(J10="NO",K10="NO",L10="NO",M10="NO",N10="NO",O10="NO",P10="NO"),"Ausencia total del riesgo, reevaluar cada 3 años con nueva identificación inicial","Aplicar identificación avanzada-condición aceptable para cada tipo de factor de riesgo identificado") -> Aplicar identificación avanzada-condición aceptable para cada tipo de factor de riesgo identificado
A11: =Datos!A10 -> 9 | B11: =Datos!B10 -> Procesos | C11: =Datos!C10 -> Deshuesado de Pechugas | D11: =Datos!D10 -> Recepcion de bins | E11: =Datos!F10 -> 07:05 - 15:05 - 15:05 - 00:05 | F11: =Datos!G10 -> N/A | G11: =Datos!H10 -> 2 | H11: =Datos!I10 -> 40 | I11: =Datos!J10 -> 20 | J11: NO | K11: NO | L11: SI | M11: SI | N11: NO | O11: NO | P11: NO | Q11: =IF(AND(J11="NO",K11="NO",L11="NO",M11="NO",N11="NO",O11="NO",P11="NO"),"Ausencia total del riesgo, reevaluar cada 3 años con nueva identificación inicial","Aplicar identificación avanzada-condición aceptable para cada tipo de factor de riesgo identificado") -> Aplicar identificación avanzada-condición aceptable para cada tipo de factor de riesgo identificado
A12: =Datos!A11 -> 10 | B12: =Datos!B11 -> Procesos | C12: =Datos!C11 -> Deshuesado de Pechugas | D12: =Datos!D11 -> Reproceso | E12: =Datos!F11 -> 07:05 - 15:05 - 15:05 - 00:05 | F12: =Datos!G11 -> N/A | G12: =Datos!H11 -> 2 | H12: =Datos!I11 -> 40 | I12: =Datos!J11 -> 20 | J12: SI | K12: NO | L12: SI | M12: SI | N12: NO | O12: NO | P12: NO | Q12: =IF(AND(J12="NO",K12="NO",L12="NO",M12="NO",N12="NO",O12="NO",P12="NO"),"Ausencia total del riesgo, reevaluar cada 3 años con nueva identificación inicial","Aplicar identificación avanzada-condición aceptable para cada tipo de factor de riesgo identificado") -> Aplicar identificación avanzada-condición aceptable para cada tipo de factor de riesgo identificado
A13: =Datos!A12 -> 11 | B13: =Datos!B12 -> Procesos | C13: =Datos!C12 -> Deshuesado de Pechugas | D13: =Datos!D12 -> Clavicula | E13: =Datos!F12 -> 07:05 - 15:05 - 15:05 - 00:05 | F13: =Datos!G12 -> N/A | G13: =Datos!H12 -> 2 | H13: =Datos!I12 -> 40 | I13: =Datos!J12 -> 20 | J13: SI | K13: NO | L13: NO | M13: NO | N13: NO | O13: NO | P13: NO | Q13: =IF(AND(J13="NO",K13="NO",L13="NO",M13="NO",N13="NO",O13="NO",P13="NO"),"Ausencia total del riesgo, reevaluar cada 3 años con nueva identificación inicial","Aplicar identificación avanzada-condición aceptable para cada tipo de factor de riesgo identificado") -> Aplicar identificación avanzada-condición aceptable para cada tipo de factor de riesgo identificado
A14: =Datos!A13 -> 12 | B14: =Datos!B13 -> Procesos | C14: =Datos!C13 -> Deshuesado de Pechugas | D14: =Datos!D13 -> Transpaletero | E14: =Datos!F13 -> 07:05 - 15:05 - 15:05 - 00:05 | F14: =Datos!G13 -> N/A | G14: =Datos!H13 -> 2 | H14: =Datos!I13 -> 40 | I14: =Datos!J13 -> 20 | J14: NO | K14: NO | L14: NO | M14: NO | N14: NO | O14: NO | P14: NO | Q14: =IF(AND(J14="NO",K14="NO",L14="NO",M14="NO",N14="NO",O14="NO",P14="NO"),"Ausencia total del riesgo, reevaluar cada 3 años con nueva identificación inicial","Aplicar identificación avanzada-condición aceptable para cada tipo de factor de riesgo identificado") -> Ausencia total del riesgo, reevaluar cada 3 años con nueva identificación inicial
... A70: =Datos!A69 -> 68 | B70: =Datos!B69 -> Procesos | C70: =Datos!C69 -> Deshuesado Trutro | D70: =Datos!D69 -> Deshuesado Trutro | E70: =Datos!F69 -> 0 | F70: =Datos!G69 -> N/A | G70: =Datos!H69 -> 2 | H70: =Datos!I69 -> 0 | I70: =Datos!J69 -> 0 | J70: SI | K70: NO | L70: NO | M70: NO | N70: NO | O70: NO | P70: NO | Q70: =IF(AND(J70="NO",K70="NO",L70="NO",M70="NO",N70="NO",O70="NO",P70="NO"),"Ausencia total del riesgo, reevaluar cada 3 años con nueva identificación inicial","Aplicar identificación avanzada-condición aceptable para cada tipo de factor de riesgo identificado") -> Aplicar identificación avanzada-condición aceptable para cada tipo de factor de riesgo identificado
A71: =Datos!A70 -> 0 | B71: =Datos!B70 -> 0 | C71: =Datos!C70 -> 0 | D71: =Datos!D70 -> 0 | E71: =Datos!F70 -> 0 | F71: =Datos!G70 -> 0 | G71: =Datos!H70 -> 0 | H71: =Datos!I70 -> 0 | I71: =Datos!J70 -> 0

Sheet Mov. Rep.
A1: MOVIMIENTO REPETITIVO | F1: Horas extras | H1: N° Trabajadores Expuestos | J1: Tabla II. IDENTIFICACIÓN AVANZADA – Trabajo Repetitivo de Miembros Superiores– Condición Aceptable | Q1: Tabla VI. IDENTIFICACIÓN AVANZADA – Tarea(s) Repetitiva(s) de miembros superiores –– Condición Crítica | X1: Plan de acción
A2: N° | B2: Área de trabajo | C2: Puesto de trabajo | D2: Tareas del puesto de trabajo | E2: Horario de funcionamiento | F2: Por dia | G2: Por Semana | H2: HOMBRE | I2: MUJER | J2: ¿Los miembros superiores trabajan por menos del 50% de la duración total de la tarea repetitiva? | K2: ¿Los codos se mantienen por debajo del nivel de los hombros por al menos el 90% del total de la duración de la(s) tarea(s) repetitiva? | L2: ¿Existe esfuerzo moderado ejercido por el trabajador (Percepción de Esfuerzo máximo 4 según Escala de Borg CR-10) ejercidas por el trabajador por no más de 1 hora mientras dura la(s) tarea(s) repetitiva? | M2: Ausencias de esfuerzo máximo (esfuerzo percibido = 5 o más en la Escala de Borg CR-10) | N2: Presencia de pausas programadas (excluyendo la pausa para almuerzo) | O2: ¿La duración total de las tareas repetitivas no excede las 4 horas totales dentro de la jornada laboral? | P2: Condición Aceptable | Q2: ¿Las acciones técnicas del miembro superior son tan rápidas que no se pueden contar con una simple observación directa? | R2: Uno o ambos brazos están realizando la tarea con el codo sobre el nivel del hombro por el 50% o más, del tiempo total de trabajo repetitivo | S2: ¿Se utiliza agarre en “pinza" (o todo tipo de tomada usando las puntas de los dedos) por más del 80% de la duración total del trabajo repetitivo? | T2: ¿Se aplica fuerza máxima por el trabajador (esfuerzo percibido = 5 o más en la Escala de Borg CR-10) por 10% o más del tiempo total de la tarea repetitiva? | U2: ¿No hay más de una pausa (Incluyendo el almuerzo) en un turno de 8 horas? | V2: ¿La duración total de las tareas repetitivas excede 4 horas totales dentro de la jornada laboral? | W2: Condición Crítica | X2: Fecha aplicación identificación avanzada | Y2: Medidas de control (administrativas) | Z2: Medidas de control (Ingeniería) | AA2: Responsable aplicación medida | AB2: Fecha de implementación medidas (Max 90 días) | AC2: Evidencia
A3: =Inicial!A3 -> 1 | B3: =Inicial!B3 -> Procesos | C3: =Inicial!C3 -> Deshuesado de Pechugas | D3: =Inicial!D3 -> Postura de Pechuga | E3: =IF(Inicial!J3="SI",Inicial!E3,"N/A") -> 07:05 - 15:05 - 15:05 - 00:05 | F3: =IF(Inicial!J3="SI",Inicial!F3,"N/A") -> N/A | G3: =IF(Inicial!J3="SI",Inicial!G3,"N/A") -> 2 | H3: =IF(Inicial!J3="SI",Inicial!H3,"N/A") -> 209 | I3: =IF(Inicial!J3="SI",Inicial!I3,"N/A") -> 101 | J3: NO | K3: SI | L3: SI | M3: SI | N3: SI | O3: SI | P3: =IF(OR(J3="NO",K3="NO",L3="NO",M3="NO",N3="NO",O3="NO"),"No Aceptable","Aceptable") -> No Aceptable | Q3: NO | R3: NO | S3: NO | T3: NO | U3: NO | V3: NO | W3: =IF(AND(Q3="NO",R3="NO",S3="NO",T3="NO",U3="NO",V3="NO"),"No Critico","Critico") -> No Critico
A4: =Inicial!A4 -> 2 | B4: =Inicial!B4 -> Procesos | C4: =Inicial!C4 -> Deshuesado de Pechugas | D4: =Inicial!D4 -> Bajado de Pechugas | E4: =IF(Inicial!J4="SI",Inicial!E4,"N/A") -> 07:05 - 15:05 - 15:05 - 00:05 | F4: =IF(Inicial!J4="SI",Inicial!F4,"N/A") -> N/A | G4: =IF(Inicial!J4="SI",Inicial!G4,"N/A") -> 2 | H4: =IF(Inicial!J4="SI",Inicial!H4,"N/A") -> 209 | I4: =IF(Inicial!J4="SI",Inicial!I4,"N/A") -> 101 | J4: NO | K4: SI | L4: SI | M4: SI | N4: SI | O4: SI | P4: =IF(OR(J4="NO",K4="NO",L4="NO",M4="NO",N4="NO",O4="NO"),"No Aceptable","Aceptable") -> No Aceptable | Q4: NO | R4: NO | S4: NO | T4: NO | U4: NO | V4: NO | W4: =IF(AND(Q4="NO",R4="NO",S4="NO",T4="NO",U4="NO",V4="NO"),"No Critico","Critico") -> No Critico
A5: =Inicial!A5 -> 3 | B5: =Inicial!B5 -> Procesos | C5: =Inicial!C5 -> Deshuesado de Pechugas | D5: =Inicial!D5 -> Prolijado | E5: =IF(Inicial!J5="SI",Inicial!E5,"N/A") -> 07:05 - 15:05 - 15:05 - 00:05 | F5: =IF(Inicial!J5="SI",Inicial!F5,"N/A") -> N/A | G5: =IF(Inicial!J5="SI",Inicial!G5,"N/A") -> 2 | H5: =IF(Inicial!J5="SI",Inicial!H5,"N/A") -> 209 | I5: =IF(Inicial!J5="SI",Inicial!I5,"N/A") -> 101 | J5: NO | K5: SI | L5: SI | M5: SI | N5: SI | O5: SI | P5: =IF(OR(J5="NO",K5="NO",L5="NO",M5="NO",N5="NO",O5="NO"),"No Aceptable","Aceptable") -> No Aceptable | Q5: NO | R5: NO | S5: NO | T5: NO | U5: NO | V5: NO | W5: =IF(AND(Q5="NO",R5="NO",S5="NO",T5="NO",U5="NO",V5="NO"),"No Critico","Critico") -> No Critico
A6: =Inicial!A6 -> 4 | B6: =Inicial!B6 -> Procesos | C6: =Inicial!C6 -> Deshuesado de Pechugas | D6: =Inicial!D6 -> Bajado de filete | E6: =IF(Inicial!J6="SI",Inicial!E6,"N/A") -> 07:05 - 15:05 - 15:05 - 00:05 | F6: =IF(Inicial!J6="SI",Inicial!F6,"N/A") -> N/A | G6: =IF(Inicial!J6="SI",Inicial!G6,"N/A") -> 2 | H6: =IF(Inicial!J6="SI",Inicial!H6,"N/A") -> 209 | I6: =IF(Inicial!J6="SI",Inicial!I6,"N/A") -> 101 | J6: NO | K6: SI | L6: SI | M6: SI | N6: SI | O6: SI | P6: =IF(OR(J6="NO",K6="NO",L6="NO",M6="NO",N6="NO",O6="NO"),"No Aceptable","Aceptable") -> No Aceptable | Q6: NO | R6: NO | S6: NO | T6: NO | U6: NO | V6: NO | W6: =IF(AND(Q6="NO",R6="NO",S6="NO",T6="NO",U6="NO",V6="NO"),"No Critico","Critico") -> No Critico
A7: =Inicial!A7 -> 5 | B7: =Inicial!B7 -> Procesos | C7: =Inicial!C7 -> Deshuesado de Pechugas | D7: =Inicial!D7 -> Selección de filete | E7: =IF(Inicial!J7="SI",Inicial!E7,"N/A") -> 07:05 - 15:05 - 15:05 - 00:05 | F7: =IF(Inicial!J7="SI",Inicial!F7,"N/A") -> N/A | G7: =IF(Inicial!J7="SI",Inicial!G7,"N/A") -> 2 | H7: =IF(Inicial!J7="SI",Inicial!H7,"N/A") -> 209 | I7: =IF(Inicial!J7="SI",Inicial!I7,"N/A") -> 101 | J7: NO | K7: SI | L7: SI | M7: SI | N7: SI | O7: SI | P7: =IF(OR(J7="NO",K7="NO",L7="NO",M7="NO",N7="NO",O7="NO"),"No Aceptable","Aceptable") -> No Aceptable | Q7: NO | R7: NO | S7: NO | T7: NO | U7: NO | V7: NO | W7: =IF(AND(Q7="NO",R7="NO",S7="NO",T7="NO",U7="NO",V7="NO"),"No Critico","Critico") -> No Critico
A8: =Inicial!A8 -> 6 | B8: =Inicial!B8 -> Procesos | C8: =Inicial!C8 -> Deshuesado de Pechugas | D8: =Inicial!D8 -> Filete | E8: =IF(Inicial!J8="SI",Inicial!E8,"N/A") -> 07:05 - 15:05 - 15:05 - 00:05 | F8: =IF(Inicial!J8="SI",Inicial!F8,"N/A") -> N/A | G8: =IF(Inicial!J8="SI",Inicial!G8,"N/A") -> 2 | H8: =IF(Inicial!J8="SI",Inicial!H8,"N/A") -> 40 | I8: =IF(Inicial!J8="SI",Inicial!I8,"N/A") -> 20 | J8: NO | K8: SI | L8: SI | M8: SI | N8: SI | O8: SI | P8: =IF(OR(J8="NO",K8="NO",L8="NO",M8="NO",N8="NO",O8="NO"),"No Aceptable","Aceptable") -> No Aceptable | Q8: NO | R8: NO | S8: NO | T8: NO | U8: NO | V8: NO | W8: =IF(AND(Q8="NO",R8="NO",S8="NO",T8="NO",U8="NO",V8="NO"),"No Critico","Critico") -> No Critico
A9: =Inicial!A9 -> 7 | B9: =Inicial!B9 -> Procesos | C9: =Inicial!C9 -> Deshuesado de Pechugas | D9: =Inicial!D9 -> Tiritas | E9: =IF(Inicial!J9="SI",Inicial!E9,"N/A") -> 07:05 - 15:05 - 15:05 - 00:05 | F9: =IF(Inicial!J9="SI",Inicial!F9,"N/A") -> N/A | G9: =IF(Inicial!J9="SI",Inicial!G9,"N/A") -> 2 | H9: =IF(Inicial!J9="SI",Inicial!H9,"N/A") -> 40 | I9: =IF(Inicial!J9="SI",Inicial!I9,"N/A") -> 20 | J9: NO | K9: SI | L9: SI | M9: SI | N9: SI | O9: SI | P9: =IF(OR(J9="NO",K9="NO",L9="NO",M9="NO",N9="NO",O9="NO"),"No Aceptable","Aceptable") -> No Aceptable | Q9: NO | R9: NO | S9: NO | T9: NO | U9: NO | V9: NO | W9: =IF(AND(Q9="NO",R9="NO",S9="NO",T9="NO",U9="NO",V9="NO"),"No Critico","Critico") -> No Critico
A10: =Inicial!A10 -> 8 | B10: =Inicial!B10 -> Procesos | C10: =Inicial!C10 -> Deshuesado de Pechugas | D10: =Inicial!D10 -> Piel | E10: =IF(Inicial!J10="SI",Inicial!E10,"N/A") -> 07:05 - 15:05 - 15:05 - 00:05 | F10: =IF(Inicial!J10="SI",Inicial!F10,"N/A") -> N/A | G10: =IF(Inicial!J10="SI",Inicial!G10,"N/A") -> 2 | H10: =IF(Inicial!J10="SI",Inicial!H10,"N/A") -> 40 | I10: =IF(Inicial!J10="SI",Inicial!I10,"N/A") -> 20 | J10: SI | K10: SI | L10: SI | M10: SI | N10: SI | O10: SI | P10: =IF(OR(J10="NO",K10="NO",L10="NO",M10="NO",N10="NO",O10="NO"),"No Aceptable","Aceptable") -> Aceptable | Q10: NO | R10: NO | S10: NO | T10: NO | U10: NO | V10: NO | W10: =IF(AND(Q10="NO",R10="NO",S10="NO",T10="NO",U10="NO",V10="NO"),"No Critico","Critico") -> No Critico
A11: =Inicial!A11 -> 9 | B11: =Inicial!B11 -> Procesos | C11: =Inicial!C11 -> Deshuesado de Pechugas | D11: =Inicial!D11 -> Recepcion de bins | E11: =IF(Inicial!J11="SI",Inicial!E11,"N/A") -> N/A | F11: =IF(Inicial!J11="SI",Inicial!F11,"N/A") -> N/A | G11: =IF(Inicial!J11="SI",Inicial!G11,"N/A") -> N/A | H11: =IF(Inicial!J11="SI",Inicial!H11,"N/A") -> N/A | I11: =IF(Inicial!J11="SI",Inicial!I11,"N/A") -> N/A | P11: =IF(OR(J11="NO",K11="NO",L11="NO",M11="NO",N11="NO",O11="NO"),"No Aceptable","Aceptable") -> Aceptable | W11: =IF(AND(Q11="NO",R11="NO",S11="NO",T11="NO",U11="NO",V11="NO"),"No Critico","Critico") -> Critico
A12: =Inicial!A12 -> 10 | B12: =Inicial!B12 -> Procesos | C12: =Inicial!C12 -> Deshuesado de Pechugas | D12: =Inicial!D12 -> Reproceso | E12: =IF(Inicial!J12="SI",Inicial!E12,"N/A") -> 07:05 - 15:05 - 15:05 - 00:05 | F12: =IF(Inicial!J12="SI",Inicial!F12,"N/A") -> N/A | G12: =IF(Inicial!J12="SI",Inicial!G12,"N/A") -> 2 | H12: =IF(Inicial!J12="SI",Inicial!H12,"N/A") -> 40 | I12: =IF(Inicial!J12="SI",Inicial!I12,"N/A") -> 20 | J12: NO | K12: SI | L12: SI | M12: SI | N12: SI | O12: SI | P12: =IF(OR(J12="NO",K12="NO",L12="NO",M12="NO",N12="NO",O12="NO"),"No Aceptable","Aceptable") -> No Aceptable | Q12: NO | R12: NO | S12: NO | T12: NO | U12: NO | V12: NO | W12: =IF(AND(Q12="NO",R12="NO",S12="NO",T12="NO",U12="NO",V12="NO"),"No Critico","Critico") -> No Critico
A13: =Inicial!A13 -> 11 | B13: =Inicial!B13 -> Procesos | C13: =Inicial!C13 -> Deshuesado de Pechugas | D13: =Inicial!D13 -> Clavicula | E13: =IF(Inicial!J13="SI",Inicial!E13,"N/A") -> 07:05 - 15:05 - 15:05 - 00:05 | F13: =IF(Inicial!J13="SI",Inicial!F13,"N/A") -> N/A | G13: =IF(Inicial!J13="SI",Inicial!G13,"N/A") -> 2 | H13: =IF(Inicial!J13="SI",Inicial!H13,"N/A") -> 40 | I13: =IF(Inicial!J13="SI",Inicial!I13,"N/A") -> 20 | J13: NO | K13: SI | L13: SI | M13: SI | N13: SI | O13: SI | P13: =IF(OR(J13="NO",K13="NO",L13="NO",M13="NO",N13="NO",O13="NO"),"No Aceptable","Aceptable") -> No Aceptable | Q13: NO | R13: NO | S13: NO | T13: NO | U13: NO | V13: NO | W13: =IF(AND(Q13="NO",R13="NO",S13="NO",T13="NO",U13="NO",V13="NO"),"No Critico","Critico") -> No Critico
A14: =Inicial!A14 -> 12 | B14: =Inicial!B14 -> Procesos | C14: =Inicial!C14 -> Deshuesado de Pechugas | D14: =Inicial!D14 -> Transpaletero | E14: =IF(Inicial!J14="SI",Inicial!E14,"N/A") -> N/A | F14: =IF(Inicial!J14="SI",Inicial!F14,"N/A") -> N/A | G14: =IF(Inicial!J14="SI",Inicial!G14,"N/A") -> N/A | H14: =IF(Inicial!J14="SI",Inicial!H14,"N/A") -> N/A | I14: =IF(Inicial!J14="SI",Inicial!I14,"N/A") -> N/A | P14: =IF(OR(J14="NO",K14="NO",L14="NO",M14="NO",N14="NO",O14="NO"),"No Aceptable","Aceptable") -> Aceptable | W14: =IF(AND(Q14="NO",R14="NO",S14="NO",T14="NO",U14="NO",V14="NO"),"No Critico","Critico") -> Critico
A15: =Inicial!A15 -> 13 | B15: =Inicial!B15 -> Procesos | C15: =Inicial!C15 -> Deshuesado de Pechugas | D15: =Inicial!D15 -> Maquinista | E15: =IF(Inicial!J15="SI",Inicial!E15,"N/A") -> N/A | F15: =IF(Inicial!J15="SI",Inicial!F15,"N/A") -> N/A | G15: =IF(Inicial!J15="SI",Inicial!G15,"N/A") -> N/A | H15: =IF(Inicial!J15="SI",Inicial!H15,"N/A") -> N/A | I15: =IF(Inicial!J15="SI",Inicial!I15,"N/A") -> N/A | P15: =IF(OR(J15="NO",K15="NO",L15="NO",M15="NO",N15="NO",O15="NO"),"No Aceptable","Aceptable") -> Aceptable | W15: =IF(AND(Q15="NO",R15="NO",S15="NO",T15="NO",U15="NO",V15="NO"),"No Critico","Critico") -> Critico
A16: =Inicial!A16 -> 14 | B16: =Inicial!B16 -> Procesos | C16: =Inicial!C16 -> Deshuesado de Pechugas | D16: =Inicial!D16 -> Laminado | E16: =IF(Inicial!J16="SI",Inicial!E16,"N/A") -> 07:05 - 15:05 - 15:05 - 00:05 | F16: =IF(Inicial!J16="SI",Inicial!F16,"N/A") -> N/A | G16: =IF(Inicial!J16="SI",Inicial!G16,"N/A") -> 2 | H16: =IF(Inicial!J16="SI",Inicial!H16,"N/A") -> 40 | I16: =IF(Inicial!J16="SI",Inicial!I16,"N/A") -> 20 | J16: NO | K16: SI | L16: SI | M16: SI | N16: SI | O16: SI | P16: =IF(OR(J16="NO",K16="NO",L16="NO",M16="NO",N16="NO",O16="NO"),"No Aceptable","Aceptable") -> No Aceptable | Q16: NO | R16: NO | S16: NO | T16: NO | U16: NO | V16: NO | W16: =IF(AND(Q16="NO",R16="NO",S16="NO",T16="NO",U16="NO",V16="NO"),"No Critico","Critico") -> No Critico
A17: =Inicial!A17 -> 15 | B17: =Inicial!B17 -> Procesos | C17: =Inicial!C17 -> Deshuesado de Pechugas | D17: =Inicial!D17 -> Rectificador de cuchillos | E17: =IF(Inicial!J17="SI",Inicial!E17,"N/A") -> 07:05 - 15:05 - 15:05 - 00:05 | F17: =IF(Inicial!J17="SI",Inicial!F17,"N/A") -> N/A | G17: =IF(Inicial!J17="SI",Inicial!G17,"N/A") -> 2 | H17: =IF(Inicial!J17="SI",Inicial!H17,"N/A") -> 2 | I17: =IF(Inicial!J17="SI",Inicial!I17,"N/A") -> 0 | J17: SI | K17: SI | L17: SI | M17: SI | N17: SI | O17: SI | P17: =IF(OR(J17="NO",K17="NO",L17="NO",M17="NO",N17="NO",O17="NO"),"No Aceptable","Aceptable") -> Aceptable | W17: =IF(AND(Q17="NO",R17="NO",S17="NO",T17="NO",U17="NO",V17="NO"),"No Critico","Critico") -> Critico
A18: =Inicial!A18 -> 16 | B18: =Inicial!B18 -> Procesos | C18: =Inicial!C18 -> Deshuesado de Pechugas | D18: =Inicial!D18 -> Jefe de Línea | E18: =IF(Inicial!J18="SI",Inicial!E18,"N/A") -> N/A | F18: =IF(Inicial!J18="SI",Inicial!F18,"N/A") -> N/A | G18: =IF(Inicial!J18="SI",Inicial!G18,"N/A") -> N/A | H18: =IF(Inicial!J18="SI",Inicial!H18,"N/A") -> N/A | I18: =IF(Inicial!J18="SI",Inicial!I18,"N/A") -> N/A | P18: =IF(OR(J18="NO",K18="NO",L18="NO",M18="NO",N18="NO",O18="NO"),"No Aceptable","Aceptable") -> Aceptable | W18: =IF(AND(Q18="NO",R18="NO",S18="NO",T18="NO",U18="NO",V18="NO"),"No Critico","Critico") -> Critico
A19: =Inicial!A19 -> 17 | B19: =Inicial!B19 -> Procesos | C19: =Inicial!C19 -> Deshuesado de Pechugas | D19: =Inicial!D19 -> Supervisor | E19: =IF(Inicial!J19="SI",Inicial!E19,"N/A") -> N/A | F19: =IF(Inicial!J19="SI",Inicial!F19,"N/A") -> N/A | G19: =IF(Inicial!J19="SI",Inicial!G19,"N/A") -> N/A | H19: =IF(Inicial!J19="SI",Inicial!H19,"N/A") -> N/A | I19: =IF(Inicial!J19="SI",Inicial!I19,"N/A") -> N/A | P19: =IF(OR(J19="NO",K19="NO",L19="NO",M19="NO",N19="NO",O19="NO"),"No Aceptable","Aceptable") -> Aceptable | W19: =IF(AND(Q19="NO",R19="NO",S19="NO",T19="NO",U19="NO",V19="NO"),"No Critico","Critico") -> Critico
A20: =Inicial!A20 -> 18 | B20: =Inicial!B20 -> Procesos | C20: =Inicial!C20 -> Envasado | D20: =Inicial!D20 -> Pesador de producto | E20: =IF(Inicial!J20="SI",Inicial!E20,"N/A") -> 07:20 - 15:30 / 15:30 - 01:05 | F20: =IF(Inicial!J20="SI",Inicial!F20,"N/A") -> N/A | G20: =IF(Inicial!J20="SI",Inicial!G20,"N/A") -> 2 | H20: =IF(Inicial!J20="SI",Inicial!H20,"N/A") -> 36 | I20: =IF(Inicial!J20="SI",Inicial!I20,"N/A") -> 52 | J20: NO | K20: SI | L20: SI | M20: SI | N20: SI | O20: SI | P20: =IF(OR(J20="NO",K20="NO",L20="NO",M20="NO",N20="NO",O20="NO"),"No Aceptable","Aceptable") -> No Aceptable | Q20: NO | R20: NO | S20: NO | T20: NO | U20: NO | V20: NO | W20: =IF(AND(Q20="NO",R20="NO",S20="NO",T20="NO",U20="NO",V20="NO"),"No Critico","Critico") -> No Critico
A21: =Inicial!A21 -> 19 | B21: =Inicial!B21 -> Procesos | C21: =Inicial!C21 -> Envasado | D21: =Inicial!D21 -> Distribuidor de producto | E21: =IF(Inicial!J21="SI",Inicial!E21,"N/A") -> 07:20 - 15:30 / 15:30 - 01:05 | F21: =IF(Inicial!J21="SI",Inicial!F21,"N/A") -> N/A | G21: =IF(Inicial!J21="SI",Inicial!G21,"N/A") -> 2 | H21: =IF(Inicial!J21="SI",Inicial!H21,"N/A") -> 36 | I21: =IF(Inicial!J21="SI",Inicial!I21,"N/A") -> 0 | J21: NO | K21: SI | L21: SI | M21: SI | N21: SI | O21: SI | P21: =IF(OR(J21="NO",K21="NO",L21="NO",M21="NO",N21="NO",O21="NO"),"No Aceptable","Aceptable") -> No Aceptable | Q21: NO | R21: NO | S21: NO | T21: NO | U21: NO | V21: NO | W21: =IF(AND(Q21="NO",R21="NO",S21="NO",T21="NO",U21="NO",V21="NO"),"No Critico","Critico") -> No Critico
A22: =Inicial!A22 -> 20 | B22: =Inicial!B22 -> Procesos | C22: =Inicial!C22 -> Envasado | D22: =Inicial!D22 -> Envasador trutro corto/largo | E22: =IF(Inicial!J22="SI",Inicial!E22,"N/A") -> 07:20 - 15:30 / 15:30 - 01:05 | F22: =IF(Inicial!J22="SI",Inicial!F22,"N/A") -> N/A | G22: =IF(Inicial!J22="SI",Inicial!G22,"N/A") -> 2 | H22: =IF(Inicial!J22="SI",Inicial!H22,"N/A") -> 36 | I22: =IF(Inicial!J22="SI",Inicial!I22,"N/A") -> 52 | J22: NO | K22: SI | L22: SI | M22: SI | N22: SI | O22: SI | P22: =IF(OR(J22="NO",K22="NO",L22="NO",M22="NO",N22="NO",O22="NO"),"No Aceptable","Aceptable") -> No Aceptable | Q22: NO | R22: NO | S22: NO | T22: NO | U22: NO | V22: NO | W22: =IF(AND(Q22="NO",R22="NO",S22="NO",T22="NO",U22="NO",V22="NO"),"No Critico","Critico") -> No Critico
A23: =Inicial!A23 -> 21 | B23: =Inicial!B23 -> Procesos | C23: =Inicial!C23 -> Envasado | D23: =Inicial!D23 -> alimentador Envasado multicabezal | E23: =IF(Inicial!J23="SI",Inicial!E23,"N/A") -> 07:20 - 15:30 / 15:30 - 01:05 | F23: =IF(Inicial!J23="SI",Inicial!F23,"N/A") -> N/A | G23: =IF(Inicial!J23="SI",Inicial!G23,"N/A") -> 2 | H23: =IF(Inicial!J23="SI",Inicial!H23,"N/A") -> 36 | I23: =IF(Inicial!J23="SI",Inicial!I23,"N/A") -> 52 | J23: SI | K23: SI | L23: SI | M23: SI | N23: SI | O23: SI | P23: =IF(OR(J23="NO",K23="NO",L23="NO",M23="NO",N23="NO",O23="NO"),"No Aceptable","Aceptable") -> Aceptable | W23: =IF(AND(Q23="NO",R23="NO",S23="NO",T23="NO",U23="NO",V23="NO"),"No Critico","Critico") -> Critico
A24: =Inicial!#REF! -> #REF! | B24: =Inicial!#REF! -> #REF! | C24: =Inicial!#REF! -> #REF! | D24: =Inicial!#REF! -> #REF! | E24: =IF(Inicial!#REF!="SI",Inicial!#REF!,"N/A") -> #REF! | F24: =IF(Inicial!#REF!="SI",Inicial!#REF!,"N/A") -> #REF! | G24: =IF(Inicial!#REF!="SI",Inicial!#REF!,"N/A") -> #REF! | H24: =IF(Inicial!#REF!="SI",Inicial!#REF!,"N/A") -> #REF! | I24: =IF(Inicial!#REF!="SI",Inicial!#REF!,"N/A") -> #REF! | P24: =IF(OR(J24="NO",K24="NO",L24="NO",M24="NO",N24="NO",O24="NO"),"No Aceptable","Aceptable") -> Aceptable | W24: =IF(AND(Q24="NO",R24="NO",S24="NO",T24="NO",U24="NO",V24="NO"),"No Critico","Critico") -> Critico
A25: =Inicial!A24 -> 22 | B25: =Inicial!B24 -> Procesos | C25: =Inicial!C24 -> Envasado | D25: =Inicial!D24 -> Carro materiales | E25: =IF(Inicial!J24="SI",Inicial!E24,"N/A") -> 07:20 - 15:30 / 15:30 - 01:05 | F25: =IF(Inicial!J24="SI",Inicial!F24,"N/A") -> N/A | G25: =IF(Inicial!J24="SI",Inicial!G24,"N/A") -> 2 | H25: =IF(Inicial!J24="SI",Inicial!H24,"N/A") -> 36 | I25: =IF(Inicial!J24="SI",Inicial!I24,"N/A") -> 52 | J25: SI | K25: SI | L25: SI | M25: SI | N25: SI | O25: SI | P25: =IF(OR(J25="NO",K25="NO",L25="NO",M25="NO",N25="NO",O25="NO"),"No Aceptable","Aceptable") -> Aceptable | Q25: NO | R25: NO | S25: NO | T25: NO | U25: NO | V25: NO | W25: =IF(AND(Q25="NO",R25="NO",S25="NO",T25="NO",U25="NO",V25="NO"),"No Critico","Critico") -> No Critico
A26: =Inicial!A25 -> 23 | B26: =Inicial!B25 -> Procesos | C26: =Inicial!C25 -> Envasado | D26: =Inicial!D25 -> Maquinista Termoselladora | E26: =IF(Inicial!J25="SI",Inicial!E25,"N/A") -> N/A | F26: =IF(Inicial!J25="SI",Inicial!F25,"N/A") -> N/A | G26: =IF(Inicial!J25="SI",Inicial!G25,"N/A") -> N/A | H26: =IF(Inicial!J25="SI",Inicial!H25,"N/A") -> N/A | I26: =IF(Inicial!J25="SI",Inicial!I25,"N/A") -> N/A | P26: =IF(OR(J26="NO",K26="NO",L26="NO",M26="NO",N26="NO",O26="NO"),"No Aceptable","Aceptable") -> Aceptable | W26: =IF(AND(Q26="NO",R26="NO",S26="NO",T26="NO",U26="NO",V26="NO"),"No Critico","Critico") -> Critico
A27: =Inicial!A26 -> 24 | B27: =Inicial!B26 -> Procesos | C27: =Inicial!C26 -> Envasado | D27: =Inicial!D26 -> Llenado de bandeja con pala | E27: =IF(Inicial!J26="SI",Inicial!E26,"N/A") -> 07:20 - 15:30 / 15:30 - 01:05 | F27: =IF(Inicial!J26="SI",Inicial!F26,"N/A") -> N/A | G27: =IF(Inicial!J26="SI",Inicial!G26,"N/A") -> 2 | H27: =IF(Inicial!J26="SI",Inicial!H26,"N/A") -> 36 | I27: =IF(Inicial!J26="SI",Inicial!I26,"N/A") -> 0 | J27: NO | K27: SI | L27: NO | M27: SI | N27: SI | O27: SI | P27: =IF(OR(J27="NO",K27="NO",L27="NO",M27="NO",N27="NO",O27="NO"),"No Aceptable","Aceptable") -> No Aceptable | Q27: NO | R27: NO | S27: NO | T27: NO | U27: NO | V27: NO | W27: =IF(AND(Q27="NO",R27="NO",S27="NO",T27="NO",U27="NO",V27="NO"),"No Critico","Critico") -> No Critico
