Workbook

Sheet Portada
A1: 1. ANTECEDENTES DE LA EMPRESA | F1: N° de Puestos | G1: Evaluados | H1: Pendientes
A2: Razón Social | B2: FAENADORA SAN VICENTE LTDA | C2: RUT Empresa | D2: 78483600-2 | F2: =COUNTIF(Datos!B:B,"Despacho") -> 7 | G2: =COUNTIF(Datos!T:T,"SI") -> 5 | H2: =COUNTIF(Datos!T:T,"NO") -> 2
A3: Actividad Económica | B3: Explotación de mataderos de aves y de otros tipos de animales n.c.p. | C3: Código CIIU
A4: Dirección | B4: CARRETERA H 66 G KM 19,2 | C4: Comuna | D4: SAN VICENTE
A5: Nombre Representante Legal | B5: SANDRA CALDERON
A6: Organismo administrador al que está adherido | B6: INSTITUTO SALUD DEL TRABAJADOR | C6: Fecha inicio | D6: 45440
A7: 2.- CENTRO DE TRABAJO O LUGAR DE TRABAJO
A8: Nombre del centro de trabajo | B8: Despacho | C8: Nº de trabajadores centro de trabajo
A9: Dirección | B9: CARRETERA H 66 G KM 19,2 | C9: Hombres
A10: Comuna | B10: SAN VICENTE | C10: Mujeres | D10: 0
A11: 3.- RESPONSABLE IMPLEMENTACIÓN PROTOCOLO
A12: Nombre responsable | B12: CONSTANZA ANDREA MUÑOZ CARO | C12: Teléfono | D12: 722312747
A13: Cargo | B13: SUPERVISORA DE ACTIVIDADES ERGONOMICAS
A14: Correo electrónico | B14: CAMUNOZC@AGROSUPER.COM

Sheet Datos
B1: Área de trabajo | C1: Puesto de trabajo | D1: Tareas del puesto de trabajo | E1: Descripción de la tarea | F1: Horario de funcionamiento | G1: Horas extras POR DIA | H1: Horas extras POR SEMANA | I1: N° Trabajadores Expuestos HOMBRE | J1: N° Trabajadores Expuestos MUJER | K1: Tipo de contrato | L1: Tipo de remuneración | M1: Duración (min) | N1: Pausas de Trabajo | O1: Rotación de tarea | P1: Equipos y Herramienta | Q1: Características de los ambientes y espacios de trabajo (Espacios, barreras arquitectónicas, flujo de tránsito) | R1: Características y disposición espacial del puesto de trabajo (Ubicación de los elementos de trabajo, disposición física del espacio de trabajo) | S1: Características y herramientas utilizadas (Descripción de equipos, herramientas utilizadas, herramientas vibrantes, uso de EPP) | T1: Evaluacion SI/NO
A2: 1 | B2: Despacho | C2: Carton Frezzer | D2: Pinchador | E2: Colaborador arrastra cajas por mesa de polines, luego realiza pinchado de codigo para registro en PC | F2: 06:00 - 14:00 14:00 - 22:00 22:00 - 06:00 | G2: 0 | H2: 2 | I2: 6 | J2: 0 | K2: Indefinido | L2: Variable | M2: 90 min | N2: Preparatoria - Compensatoria | O2: SI | P2: Pistola y PC | Q2: Libre de transito, sin barreras arquitectonicas en su espacio de trabajo | R2: PC a la altura del torax con facil accesos a los elementos de oficina | S2: EEP tales como Zapatos de seguridad,fonos, guantes anticortes | T2: SI
A3: 2 | B3: Despacho | C3: Carton Frezzer | D3: Depaletizador | E3: Colaborador toma cajas desde pallet y las posiciona en linea para ser registradas | F3: 06:00 - 14:00 14:00 - 22:00 22:00 - 06:00 | G3: 0 | H3: 2 | I3: 24 | J3: 0 | K3: Indefinido | L3: Variable | M3: 90 min | N3: Preparatoria - Compensatoria | O3: SI | P3: Pistola y PC | Q3: Libre de transito, sin barreras arquitectonicas en su espacio de trabajo | R3: PC a la altura del torax con facil accesos a los elementos de oficina | S3: EEP tales como Zapatos de seguridad,fonos, guantes anticortes | T3: SI
A4: 3 | B4: Despacho | C4: Carton Frezzer | D4: Pinchador | E4: Colaborador toma cajas desde linea para posicionar en pallet armando pedidos. | F4: 06:00 - 14:00 14:00 - 22:00 22:00 - 06:00 | G4: 0 | H4: 2 | I4: 24 | J4: 0 | K4: Indefinido | L4: Variable | M4: 90 min | N4: Preparatoria - Compensatoria | O4: SI | P4: Pistola y PC | Q4: Libre de transito, sin barreras arquitectonicas en su espacio de trabajo | R4: PC a la altura del torax con facil accesos a los elementos de oficina | S4: EEP tales como Zapatos de seguridad,fonos, guantes anticortes | T4: SI
A5: 4 | B5: Despacho | C5: Despacho congelado | D5: Gruero | E5: Conduce grua BT bajando cargas en forma mecanica para trasladar a otro punto | F5: 06:00 - 14:00 14:00 - 22:00 22:00 - 06:00 | G5: 0 | H5: 2 | K5: Indefinido | L5: Variable | M5: 58 min | N5: Preparatorias | O5: Si | P5: Rollo de film , cuchillo | Q5: Sin barreras arquitectonicas | R5: Sin mesas de trabajo, no expuesto a radiacion UV | S5: EPP tales como Zapato de seguridad y chalecos reflectantes | T5: NO
A6: 5 | B6: Despacho | C6: Despacho congelado | D6: Transpaletero | E6: Maneja transpaleta para el transporte de producto de un lado a otro | F6: 06:00 - 14:00 14:00 - 22:00 22:00 - 06:00 | G6: 0 | H6: 2 | K6: Indefinido | L6: Variable | M6: 59 min | N6: Preparatorias | O6: Si | P6: Rollo de film , cuchillo | Q6: Sin barreras arquitectonicas | R6: Sin mesas de trabajo, no expuesto a radiacion UV | S6: EPP tales como Zapato de seguridad y chalecos reflectantes | T6: NO
A7: 6 | B7: Despacho | C7: Despacho congelado | D7: Postura de films | E7: Arma pallet con cajas según su pedido, pone films para fijar productos | F7: 06:00 - 14:00 14:00 - 22:00 22:00 - 06:00 | G7: 0 | H7: 2 | K7: Indefinido | L7: Variable | M7: 60 min | N7: Preparatorias | O7: Si | P7: Rollo de film cuchillo | Q7: Sin barreras arquitectonicas | R7: Sin mesas de trabajo, no expuesto a radiacion UV | S7: EPP tales como Zapato de seguridad y chalecos reflectantes | T7: SI
A8: 7 | B8: Despacho | C8: Despacho congelado | D8: Reprocesos de producto | E8: Desarman cajas de productos y echan los productos en bins para decomiso | F8: 06:00 - 14:00 14:00 - 22:00 22:00 - 06:00 | G8: 0 | H8: 2 | K8: Indefinido | L8: Variable | M8: 61 min | N8: Preparatorias | O8: SI | P8: Cuchillo ceramico | Q8: Sin barreras arquitectonicas | R8: Sin mesa de trabajo, directo a bins | S8: EPP tales como Zapato de seguridad y chalecos reflectantes | T8: SI
A9: 8
A10: 9
A11: 10
A12: 11
A13: 12
A14: 13
A15: 14
A16: 15
A17: 16
A18: 17
A19: 18
A20: 19
... A25: 24

Sheet Inicial
A1: N° | C1: Puesto de trabajo | D1: Tareas del puesto de trabajo | E1: Horario de funcionamiento | F1: Horas extras POR DIA | G1: Horas extras POR SEMANA | H1: N° Trabajadores Expuestos HOMBRE | I1: N° Trabajadores Expuestos MUJER | J1: Trabajo repetitivo de miembros superiores. | K1: Postura de trabajo estática - Forzada | L1: MMC Levantamiento/Descenso | M1: MMC Empuje/Arrastre | N1: Manejo manual de pacientes / personas | O1: Vibración de cuerpo completo | P1: Vibración segmento mano – brazo | Q1: Resultado identificación inicial
B2: Area | J2: ¿Existe una o más tareas donde utilice las manos y miembros superiores con una duración total de una hora o más durante la jornada laboral y con un tiempo total de 5 o más horas a la semana? Por ejemplo: Donde se tenga que armar, limpiar, apretar, lanzar, cortar, presionar, desarmar, atornillar, desatornillar, digitar. 1 tarea repetitiva: conjunto de ciclos de trabajo realizados por uno o más segmentos de las extremidades superiores, donde repetitividad se caracteriza por al menos uno de los siguientes criterios: i) El tiempo de ciclo es inferior a 30 segundos en promedio. ii) Los mismos patrones biomecánicos se repiten por más del 50% del ciclo. En general, el ritmo de trabajo está determinado por factor externo al trabajador, ejemplo, líneas de producción, velocidad de una máquina, entre otros | K2: Existen posturas de trabajo estáticas de cabeza/cuello, tronco y/o miembros superiores e inferiores, mantenidas durante más de 4 segundos, en la que se pueden dar ligeras variaciones alrededor de un mismo nivel de fuerza generado por los músculos y otras estructuras corporales? Por ejemplo: Donde se observe estar con la cabeza inclinada hacia adelante o atrás, cabeza rotada permanentemente hacia algún lado, hombros situados por delante de las caderas de manera continua, tronco rotado o inclinado para sostener o movilizar objetos | L2: Para el Levantamiento/Descenso/Transporte: ¿Existe levantamiento, descenso o transporte manual de un objeto de 3kg o más? Por ejemplo: Se observa que levanta, sostiene, transporta, desplaza, moviliza, ubica con precisión ordenando, apila, paletiza. | M2: Tracción/Empuje ¿Existe empuje o arrastre de una carga utilizando el cuerpo completo con 1 o 2 manos? Se observa el empuje y/o arrastre de diferentes maneras carros, plataformas con rueda, superficies deslizantes, detención de objetos en movimiento, camillas, camas, sillas de rueda, paletizadores, grúas de uso manual mecanizadas, formas de tracción y empuje hechizas, carretillas. No se considera empuje y arrastre carros motorizados y controlados manualmente (conducción) | N2: ¿Se realiza alguna actividad que requiere fuerza para empujar, tirar, levantar, descender, transferir o de alguna manera mover o sostener una persona o parte del cuerpo de una persona? *NOTA: La condición a identificar debe incluir la actividad de manipulación, ya sea que se realice con o sin dispositivos de asistencia. Esta condición está determinada por el riesgo asociado a las características de la carga humana que requiere control sensible de la masa corporal por parte del operador. | O2: Están los trabajadores en contacto con una fuente de vibración de cuerpo entero perceptible por el trabajador/a? Se presenta en cercanía de máquinas donde se percibe la vibración, superficies vibrantes donde se está de pie o sentado como en maquinaria pesada y de conducción. | P2: Están los trabajadores/as en contacto con una fuente de vibración perceptible por el trabajador del segmento mano-brazo? Por ejemplo: Se presenta en situaciones de manejo de herramientas neumáticas o eléctricas, atornilladores o destornilladores neumáticos o eléctricos, uso de herramientas con impacto como martillos, cinceles, herramientas percutoras como taladros
A3: =Datos!A2 -> 1 | B3: =Datos!B2 -> Despacho | C3: =Datos!C2 -> Carton Frezzer | D3: =Datos!D2 -> Pinchador | E3: =Datos!F2 -> 06:00 - 14:00 14:00 - 22:00 22:00 - 06:00 | F3: =Datos!G2 -> 0 | G3: =Datos!H2 -> 2 | H3: =Datos!I2 -> 6 | I3: =Datos!J2 -> 0 | J3: SI | K3: NO | L3: SI | M3: SI | N3: NO | O3: NO | P3: NO | Q3: =IF(AND(J3="NO",K3="NO",L3="NO",M3="NO",N3="NO",O3="NO",P3="NO"),"Ausencia total del riesgo, reevaluar cada 3 años con nueva identificación inicial","Aplicar identificación avanzada-condición aceptable para cada tipo de factor de riesgo identificado") -> Aplicar identificación avanzada-condición aceptable para cada tipo de factor de riesgo identificado
A4: =Datos!A3 -> 2 | B4: =Datos!B3 -> Despacho | C4: =Datos!C3 -> Carton Frezzer | D4: =Datos!D3 -> Depaletizador | E4: =Datos!F3 -> 06:00 - 14:00 14:00 - 22:00 22:00 - 06:00 | F4: =Datos!G3 -> 0 | G4: =Datos!H3 -> 2 | H4: =Datos!I3 -> 24 | I4: =Datos!J3 -> 0 | J4: SI | K4: NO | L4: SI | M4: SI | N4: NO | O4: NO | P4: NO | Q4: =IF(AND(J4="NO",K4="NO",L4="NO",M4="NO",N4="NO",O4="NO",P4="NO"),"Ausencia total del riesgo, reevaluar cada 3 años con nueva identificación inicial","Aplicar identificación avanzada-condición aceptable para cada tipo de factor de riesgo identificado") -> Aplicar identificación avanzada-condición aceptable para cada tipo de factor de riesgo identificado
A5: =Datos!A4 -> 3 | B5: =Datos!B4 -> Despacho | C5: =Datos!C4 -> Carton Frezzer | D5: =Datos!D4 -> Pinchador | E5: =Datos!F4 -> 06:00 - 14:00 14:00 - 22:00 22:00 - 06:00 | F5: =Datos!G4 -> 0 | G5: =Datos!H4 -> 2 | H5: =Datos!I4 -> 24 | I5: =Datos!J4 -> 0 | J5: SI | K5: NO | L5: SI | M5: SI | N5: NO | O5: NO | P5: NO | Q5: =IF(AND(J5="NO",K5="NO",L5="NO",M5="NO",N5="NO",O5="NO",P5="NO"),"Ausencia total del riesgo, reevaluar cada 3 años con nueva identificación inicial","Aplicar identificación avanzada-condición aceptable para cada tipo de factor de riesgo identificado") -> Aplicar identificación avanzada-condición aceptable para cada tipo de factor de riesgo identificado
A6: =Datos!A5 -> 4 | B6: =Datos!B5 -> Despacho | C6: =Datos!C5 -> Despacho congelado | D6: =Datos!D5 -> Gruero | E6: =Datos!F5 -> 06:00 - 14:00 14:00 - 22:00 22:00 - 06:00 | F6: =Datos!G5 -> 0 | G6: =Datos!H5 -> 2 | H6: =Datos!I5 -> 0 | I6: =Datos!J5 -> 0 | J6: NO | K6: NO | L6: NO | M6: NO | N6: NO | O6: NO | P6: NO | Q6: =IF(AND(J6="NO",K6="NO",L6="NO",M6="NO",N6="NO",O6="NO",P6="NO"),"Ausencia total del riesgo, reevaluar cada 3 años con nueva identificación inicial","Aplicar identificación avanzada-condición aceptable para cada tipo de factor de riesgo identificado") -> Ausencia total del riesgo, reevaluar cada 3 años con nueva identificación inicial
A7: =Datos!A6 -> 5 | B7: =Datos!B6 -> Despacho | C7: =Datos!C6 -> Despacho congelado | D7: =Datos!D6 -> Transpaletero | E7: =Datos!F6 -> 06:00 - 14:00 14:00 - 22:00 22:00 - 06:00 | F7: =Datos!G6 -> 0 | G7: =Datos!H6 -> 2 | H7: =Datos!I6 -> 0 | I7: =Datos!J6 -> 0 | J7: NO | K7: NO | L7: NO | M7: NO | N7: NO | O7: NO | P7: NO | Q7: =IF(AND(J7="NO",K7="NO",L7="NO",M7="NO",N7="NO",O7="NO",P7="NO"),"Ausencia total del riesgo, reevaluar cada 3 años con nueva identificación inicial","Aplicar identificación avanzada-condición aceptable para cada tipo de factor de riesgo identificado") -> Ausencia total del riesgo, reevaluar cada 3 años con nueva identificación inicial
A8: =Datos!A7 -> 6 | B8: =Datos!B7 -> Despacho | C8: =Datos!C7 -> Despacho congelado | D8: =Datos!D7 -> Postura de films | E8: =Datos!F7 -> 06:00 - 14:00 14:00 - 22:00 22:00 - 06:00 | F8: =Datos!G7 -> 0 | G8: =Datos!H7 -> 2 | H8: =Datos!I7 -> 0 | I8: =Datos!J7 -> 0 | J8: SI | K8: NO | L8: NO | M8: NO | N8: NO | O8: NO | P8: NO | Q8: =IF(AND(J8="NO",K8="NO",L8="NO",M8="NO",N8="NO",O8="NO",P8="NO"),"Ausencia total del riesgo, reevaluar cada 3 años con nueva identificación inicial","Aplicar identificación avanzada-condición aceptable para cada tipo de factor de riesgo identificado") -> Aplicar identificación avanzada-condición aceptable para cada tipo de factor de riesgo identificado
A9: =Datos!A8 -> 7 | B9: Despacho | C9: Despacho Congelado | D9: =Datos!D8 -> Reprocesos de producto | E9: =Datos!F8 -> 06:00 - 14:00 14:00 - 22:00 22:00 - 06:00 | F9: =Datos!G8 -> 0 | G9: =Datos!H8 -> 2 | H9: =Datos!I8 -> 0 | I9: =Datos!J8 -> 0 | J9: SI | K9: NO | L9: SI | M9: NO | N9: NO | O9: NO | P9: NO | Q9: =IF(AND(J9="NO",K9="NO",L9="NO",M9="NO",N9="NO",O9="NO",P9="NO"),"Ausencia total del riesgo, reevaluar cada 3 años con nueva identificación inicial","Aplicar identificación avanzada-condición aceptable para cada tipo de factor de riesgo identificado") -> Aplicar identificación avanzada-condición aceptable para cada tipo de factor de riesgo identificado

Sheet Mov. Rep.
A1: MOVIMIENTO REPETITIVO | F1: Horas extras | H1: N° Trabajadores Expuestos | J1: Tabla II. IDENTIFICACIÓN AVANZADA – Trabajo Repetitivo de Miembros Superiores– Condición Aceptable | Q1: Tabla VI. IDENTIFICACIÓN AVANZADA – Tarea(s) Repetitiva(s) de miembros superiores –– Condición Crítica | X1: Plan de acción
A2: N° | B2: Área de trabajo | C2: Puesto de trabajo | D2: Tareas del puesto de trabajo | E2: Horario de funcionamiento | F2: Por dia | G2: Por Semana | H2: HOMBRE | I2: MUJER | J2: ¿Los miembros superiores trabajan por menos del 50% de la duración total de la tarea repetitiva? | K2: ¿Los codos se mantienen por debajo del nivel de los hombros por al menos el 90% del total de la duración de la(s) tarea(s) repetitiva? | L2: ¿Existe esfuerzo moderado ejercido por el trabajador (Percepción de Esfuerzo máximo 4 según Escala de Borg CR-10) ejercidas por el trabajador por no más de 1 hora mientras dura la(s) tarea(s) repetitiva? | M2: Ausencias de esfuerzo máximo (esfuerzo percibido = 5 o más en la Escala de Borg CR-10) | N2: Presencia de pausas programadas (excluyendo la pausa para almuerzo) | O2: ¿La duración total de las tareas repetitivas no excede las 4 horas totales dentro de la jornada laboral? | P2: Condición Aceptable | Q2: ¿Las acciones técnicas del miembro superior son tan rápidas que no se pueden contar con una simple observación directa? | R2: Uno o ambos brazos están realizando la tarea con el codo sobre el nivel del hombro por el 50% o más, del tiempo total de trabajo repetitivo | S2: ¿Se utiliza agarre en “pinza" (o todo tipo de tomada usando las puntas de los dedos) por más del 80% de la duración total del trabajo repetitivo? | T2: ¿Se aplica fuerza máxima por el trabajador (esfuerzo percibido = 5 o más en la Escala de Borg CR-10) por 10% o más del tiempo total de la tarea repetitiva? | U2: ¿No hay más de una pausa (Incluyendo el almuerzo) en un turno de 8 horas? | V2: ¿La duración total de las tareas repetitivas excede 4 horas totales dentro de la jornada laboral? | W2: Condición Crítica | X2: Fecha aplicación identificación avanzada | Y2: Medidas de control (administrativas) | Z2: Medidas de control (Ingeniería) | AA2: Responsable aplicación medida | AB2: Fecha de implementación medidas (Max 90 días) | AC2: Evidencia
A3: =Inicial!A3 -> 1 | B3: =Inicial!B3 -> Despacho | C3: =Inicial!C3 -> Carton Frezzer | D3: =Inicial!D3 -> Pinchador | E3: =IF(Inicial!J3="SI",Inicial!E3,"N/A") -> 06:00 - 14:00 14:00 - 22:00 22:00 - 06:00 | F3: =IF(Inicial!J3="SI",Inicial!F3,"N/A") -> 0 | G3: =IF(Inicial!J3="SI",Inicial!G3,"N/A") -> 2 | H3: =IF(Inicial!J3="SI",Inicial!H3,"N/A") -> 6 | I3: =IF(Inicial!J3="SI",Inicial!I3,"N/A") -> 0 | J3: NO | K3: SI | L3: SI | M3: SI | N3: SI | O3: SI | P3: =IF(OR(J3="NO",K3="NO",L3="NO",M3="NO",N3="NO",O3="NO"),"No Aceptable","Aceptable") -> No Aceptable | Q3: NO | R3: NO | S3: NO | T3: NO | U3: NO | V3: NO | W3: =IF(AND(Q3="NO",R3="NO",S3="NO",T3="NO",U3="NO",V3="NO"),"No Critico","Critico") -> No Critico
A4: =Inicial!A4 -> 2 | B4: =Inicial!B4 -> Despacho | C4: =Inicial!C4 -> Carton Frezzer | D4: =Inicial!D4 -> Depaletizador | E4: =IF(Inicial!J4="SI",Inicial!E4,"N/A") -> 06:00 - 14:00 14:00 - 22:00 22:00 - 06:00 | F4: =IF(Inicial!J4="SI",Inicial!F4,"N/A") -> 0 | G4: =IF(Inicial!J4="SI",Inicial!G4,"N/A") -> 2 | H4: =IF(Inicial!J4="SI",Inicial!H4,"N/A") -> 24 | I4: =IF(Inicial!J4="SI",Inicial!I4,"N/A") -> 0 | J4: NO | K4: SI | L4: SI | M4: SI | N4: SI | O4: SI | P4: =IF(OR(J4="NO",K4="NO",L4="NO",M4="NO",N4="NO",O4="NO"),"No Aceptable","Aceptable") -> No Aceptable | Q4: NO | R4: NO | S4: NO | T4: NO | U4: NO | V4: NO | W4: =IF(AND(Q4="NO",R4="NO",S4="NO",T4="NO",U4="NO",V4="NO"),"No Critico","Critico") -> No Critico
A5: =Inicial!A5 -> 3 | B5: =Inicial!B5 -> Despacho | C5: =Inicial!C5 -> Carton Frezzer | D5: =Inicial!D5 -> Pinchador | E5: =IF(Inicial!J5="SI",Inicial!E5,"N/A") -> 06:00 - 14:00 14:00 - 22:00 22:00 - 06:00 | F5: =IF(Inicial!J5="SI",Inicial!F5,"N/A") -> 0 | G5: =IF(Inicial!J5="SI",Inicial!G5,"N/A") -> 2 | H5: =IF(Inicial!J5="SI",Inicial!H5,"N/A") -> 24 | I5: =IF(Inicial!J5="SI",Inicial!I5,"N/A") -> 0 | J5: NO | K5: SI | L5: SI | M5: SI | N5: SI | O5: SI | P5: =IF(OR(J5="NO",K5="NO",L5="NO",M5="NO",N5="NO",O5="NO"),"No Aceptable","Aceptable") -> No Aceptable | Q5: NO | R5: NO | S5: NO | T5: NO | U5: NO | V5: NO | W5: =IF(AND(Q5="NO",R5="NO",S5="NO",T5="NO",U5="NO",V5="NO"),"No Critico","Critico") -> No Critico
A6: =Inicial!A6 -> 4 | B6: =Inicial!B6 -> Despacho | C6: =Inicial!C6 -> Despacho congelado | D6: =Inicial!D6 -> Gruero | E6: =IF(Inicial!J6="SI",Inicial!E6,"N/A") -> N/A | F6: =IF(Inicial!J6="SI",Inicial!F6,"N/A") -> N/A | G6: =IF(Inicial!J6="SI",Inicial!G6,"N/A") -> N/A | H6: =IF(Inicial!J6="SI",Inicial!H6,"N/A") -> N/A | I6: =IF(Inicial!J6="SI",Inicial!I6,"N/A") -> N/A | P6: =IF(OR(J6="NO",K6="NO",L6="NO",M6="NO",N6="NO",O6="NO"),"No Aceptable","Aceptable") -> Aceptable | W6: =IF(AND(Q6="NO",R6="NO",S6="NO",T6="NO",U6="NO",V6="NO"),"No Critico","Critico") -> Critico
A7: =Inicial!A7 -> 5 | B7: =Inicial!B7 -> Despacho | C7: =Inicial!C7 -> Despacho congelado | D7: =Inicial!D7 -> Transpaletero | E7: =IF(Inicial!J7="SI",Inicial!E7,"N/A") -> N/A | F7: =IF(Inicial!J7="SI",Inicial!F7,"N/A") -> N/A | G7: =IF(Inicial!J7="SI",Inicial!G7,"N/A") -> N/A | H7: =IF(Inicial!J7="SI",Inicial!H7,"N/A") -> N/A | I7: =IF(Inicial!J7="SI",Inicial!I7,"N/A") -> N/A | P7: =IF(OR(J7="NO",K7="NO",L7="NO",M7="NO",N7="NO",O7="NO"),"No Aceptable","Aceptable") -> Aceptable | W7: =IF(AND(Q7="NO",R7="NO",S7="NO",T7="NO",U7="NO",V7="NO"),"No Critico","Critico") -> Critico
A8: =Inicial!A8 -> 6 | B8: =Inicial!B8 -> Despacho | C8: =Inicial!C8 -> Despacho congelado | D8: =Inicial!D8 -> Postura de films | E8: =IF(Inicial!J8="SI",Inicial!E8,"N/A") -> 06:00 - 14:00 14:00 - 22:00 22:00 - 06:00 | F8: =IF(Inicial!J8="SI",Inicial!F8,"N/A") -> 0 | G8: =IF(Inicial!J8="SI",Inicial!G8,"N/A") -> 2 | H8: =IF(Inicial!J8="SI",Inicial!H8,"N/A") -> 0 | I8: =IF(Inicial!J8="SI",Inicial!I8,"N/A") -> 0 | J8: SI | K8: SI | L8: SI | M8: SI | N8: SI | O8: SI | P8: =IF(OR(J8="NO",K8="NO",L8="NO",M8="NO",N8="NO",O8="NO"),"No Aceptable","Aceptable") -> Aceptable | W8: =IF(AND(Q8="NO",R8="NO",S8="NO",T8="NO",U8="NO",V8="NO"),"No Critico","Critico") -> Critico
A9: =Inicial!A9 -> 7 | B9: =Inicial!B9 -> Despacho | C9: =Inicial!C9 -> Despacho Congelado | D9: =Inicial!D9 -> Reprocesos de producto | E9: =IF(Inicial!J9="SI",Inicial!E9,"N/A") -> 06:00 - 14:00 14:00 - 22:00 22:00 - 06:00 | F9: =IF(Inicial!J9="SI",Inicial!F9,"N/A") -> 0 | G9: =IF(Inicial!J9="SI",Inicial!G9,"N/A") -> 2 | H9: =IF(Inicial!J9="SI",Inicial!H9,"N/A") -> 0 | I9: =IF(Inicial!J9="SI",Inicial!I9,"N/A") -> 0 | P9: =IF(OR(J9="NO",K9="NO",L9="NO",M9="NO",N9="NO",O9="NO"),"No Aceptable","Aceptable") -> Aceptable | W9: =IF(AND(Q9="NO",R9="NO",S9="NO",T9="NO",U9="NO",V9="NO"),"No Critico","Critico") -> Critico
A10: =Inicial!#REF! -> #REF! | B10: =Inicial!#REF! -> #REF! | C10: =Inicial!#REF! -> #REF! | D10: =Inicial!#REF! -> #REF! | E10: =IF(Inicial!#REF!="SI",Inicial!#REF!,"N/A") -> #REF! | F10: =IF(Inicial!#REF!="SI",Inicial!#REF!,"N/A") -> #REF! | G10: =IF(Inicial!#REF!="SI",Inicial!#REF!,"N/A") -> #REF! | H10: =IF(Inicial!#REF!="SI",Inicial!#REF!,"N/A") -> #REF! | I10: =IF(Inicial!#REF!="SI",Inicial!#REF!,"N/A") -> #REF! | P10: =IF(OR(J10="NO",K10="NO",L10="NO",M10="NO",N10="NO",O10="NO"),"No Aceptable","Aceptable") -> Aceptable | W10: =IF(AND(Q10="NO",R10="NO",S10="NO",T10="NO",U10="NO",V10="NO"),"No Critico","Critico") -> Critico
A11: =Inicial!#REF! -> #REF! | B11: =Inicial!#REF! -> #REF! | C11: =Inicial!#REF! -> #REF! | D11: =Inicial!#REF! -> #REF! | E11: =IF(Inicial!#REF!="SI",Inicial!#REF!,"N/A") -> #REF! | F11: =IF(Inicial!#REF!="SI",Inicial!#REF!,"N/A") -> #REF! | G11: =IF(Inicial!#REF!="SI",Inicial!#REF!,"N/A") -> #REF! | H11: =IF(Inicial!#REF!="SI",Inicial!#REF!,"N/A") -> #REF! | I11: =IF(Inicial!#REF!="SI",Inicial!#REF!,"N/A") -> #REF! | P11: =IF(OR(J11="NO",K11="NO",L11="NO",M11="NO",N11="NO",O11="NO"),"No Aceptable","Aceptable") -> Aceptable | W11: =IF(AND(Q11="NO",R11="NO",S11="NO",T11="NO",U11="NO",V11="NO"),"No Critico","Critico") -> Critico
A12: =Inicial!#REF! -> #REF! | B12: =Inicial!#REF! -> #REF! | C12: =Inicial!#REF! -> #REF! | D12: =Inicial!#REF! -> #REF! | E12: =IF(Inicial!#REF!="SI",Inicial!#REF!,"N/A") -> #REF! | F12: =IF(Inicial!#REF!="SI",Inicial!#REF!,"N/A") -> #REF! | G12: =IF(Inicial!#REF!="SI",Inicial!#REF!,"N/A") -> #REF! | H12: =IF(Inicial!#REF!="SI",Inicial!#REF!,"N/A") -> #REF! | I12: =IF(Inicial!#REF!="SI",Inicial!#REF!,"N/A") -> #REF! | P12: =IF(OR(J12="NO",K12="NO",L12="NO",M12="NO",N12="NO",O12="NO"),"No Aceptable","Aceptable") -> Aceptable | W12: =IF(AND(Q12="NO",R12="NO",S12="NO",T12="NO",U12="NO",V12="NO"),"No Critico","Critico") -> Critico
A13: =Inicial!#REF! -> #REF! | B13: =Inicial!#REF! -> #REF! | C13: =Inicial!#REF! -> #REF! | D13: =Inicial!#REF! -> #REF! | E13: =IF(Inicial!#REF!="SI",Inicial!#REF!,"N/A") -> #REF! | F13: =IF(Inicial!#REF!="SI",Inicial!#REF!,"N/A") -> #REF! | G13: =IF(Inicial!#REF!="SI",Inicial!#REF!,"N/A") -> #REF! | H13: =IF(Inicial!#REF!="SI",Inicial!#REF!,"N/A") -> #REF! | I13: =IF(Inicial!#REF!="SI",Inicial!#REF!,"N/A") -> #REF! | P13: =IF(OR(J13="NO",K13="NO",L13="NO",M13="NO",N13="NO",O13="NO"),"No Aceptable","Aceptable") -> Aceptable | W13: =IF(AND(Q13="NO",R13="NO",S13="NO",T13="NO",U13="NO",V13="NO"),"No Critico","Critico") -> Critico
A14: =Inicial!#REF! -> #REF! | B14: =Inicial!#REF! -> #REF! | C14: =Inicial!#REF! -> #REF! | D14: =Inicial!#REF! -> #REF! | E14: =IF(Inicial!#REF!="SI",Inicial!#REF!,"N/A") -> #REF! | F14: =IF(Inicial!#REF!="SI",Inicial!#REF!,"N/A") -> #REF! | G14: =IF(Inicial!#REF!="SI",Inicial!#REF!,"N/A") -> #REF! | H14: =IF(Inicial!#REF!="SI",Inicial!#REF!,"N/A") -> #REF! | I14: =IF(Inicial!#REF!="SI",Inicial!#REF!,"N/A") -> #REF! | P14: =IF(OR(J14="NO",K14="NO",L14="NO",M14="NO",N14="NO",O14="NO"),"No Aceptable","Aceptable") -> Aceptable | W14: =IF(AND(Q14="NO",R14="NO",S14="NO",T14="NO",U14="NO",V14="NO"),"No Critico","Critico") -> Critico
A15: =Inicial!#REF! -> #REF! | B15: =Inicial!#REF! -> #REF! | C15: =Inicial!#REF! -> #REF! | D15: =Inicial!#REF! -> #REF! | E15: =IF(Inicial!#REF!="SI",Inicial!#REF!,"N/A") -> #REF! | F15: =IF(Inicial!#REF!="SI",Inicial!#REF!,"N/A") -> #REF! | G15: =IF(Inicial!#REF!="SI",Inicial!#REF!,"N/A") -> #REF! | H15: =IF(Inicial!#REF!="SI",Inicial!#REF!,"N/A") -> #REF! | I15: =IF(Inicial!#REF!="SI",Inicial!#REF!,"N/A") -> #REF! | P15: =IF(OR(J15="NO",K15="NO",L15="NO",M15="NO",N15="NO",O15="NO"),"No Aceptable","Aceptable") -> Aceptable | W15: =IF(AND(Q15="NO",R15="NO",S15="NO",T15="NO",U15="NO",V15="NO"),"No Critico","Critico") -> Critico
A16: =Inicial!#REF! -> #REF! | B16: =Inicial!#REF! -> #REF! | C16: =Inicial!#REF! -> #REF! | D16: =Inicial!#REF! -> #REF! | E16: =IF(Inicial!#REF!="SI",Inicial!#REF!,"N/A") -> #REF! | F16: =IF(Inicial!#REF!="SI",Inicial!#REF!,"N/A") -> #REF! | G16: =IF(Inicial!#REF!="SI",Inicial!#REF!,"N/A") -> #REF! | H16: =IF(Inicial!#REF!="SI",Inicial!#REF!,"N/A") -> #REF! | I16: =IF(Inicial!#REF!="SI",Inicial!#REF!,"N/A") -> #REF! | P16: =IF(OR(J16="NO",K16="NO",L16="NO",M16="NO",N16="NO",O16="NO"),"No Aceptable","Aceptable") -> Aceptable | W16: =IF(AND(Q16="NO",R16="NO",S16="NO",T16="NO",U16="NO",V16="NO"),"No Critico","Critico") -> Critico
A17: =Inicial!#REF! -> #REF! | B17: =Inicial!#REF! -> #REF! | C17: =Inicial!#REF! -> #REF! | D17: =Inicial!#REF! -> #REF! | E17: =IF(Inicial!#REF!="SI",Inicial!#REF!,"N/A") -> #REF! | F17: =IF(Inicial!#REF!="SI",Inicial!#REF!,"N/A") -> #REF! | G17: =IF(Inicial!#REF!="SI",Inicial!#REF!,"N/A") -> #REF! | H17: =IF(Inicial!#REF!="SI",Inicial!#REF!,"N/A") -> #REF! | I17: =IF(Inicial!#REF!="SI",Inicial!#REF!,"N/A") -> #REF! | P17: =IF(OR(J17="NO",K17="NO",L17="NO",M17="NO",N17="NO",O17="NO"),"No Aceptable","Aceptable") -> Aceptable | W17: =IF(AND(Q17="NO",R17="NO",S17="NO",T17="NO",U17="NO",V17="NO"),"No Critico","Critico") -> Critico
A18: =Inicial!#REF! -> #REF! | B18: =Inicial!#REF! -> #REF! | C18: =Inicial!#REF! -> #REF! | D18: =Inicial!#REF! -> #REF! | E18: =IF(Inicial!#REF!="SI",Inicial!#REF!,"N/A") -> #REF! | F18: =IF(Inicial!#REF!="SI",Inicial!#REF!,"N/A") -> #REF! | G18: =IF(Inicial!#REF!="SI",Inicial!#REF!,"N/A") -> #REF! | H18: =IF(Inicial!#REF!="SI",Inicial!#REF!,"N/A") -> #REF! | I18: =IF(Inicial!#REF!="SI",Inicial!#REF!,"N/A") -> #REF! | P18: =IF(OR(J18="NO",K18="NO",L18="NO",M18="NO",N18="NO",O18="NO"),"No Aceptable","Aceptable") -> Aceptable | W18: =IF(AND(Q18="NO",R18="NO",S18="NO",T18="NO",U18="NO",V18="NO"),"No Critico","Critico") -> Critico
A19: =Inicial!#REF! -> #REF! | B19: =Inicial!#REF! -> #REF! | C19: =Inicial!#REF! -> #REF! | D19: =Inicial!#REF! -> #REF! | E19: =IF(Inicial!#REF!="SI",Inicial!#REF!,"N/A") -> #REF! | F19: =IF(Inicial!#REF!="SI",Inicial!#REF!,"N/A") -> #REF! | G19: =IF(Inicial!#REF!="SI",Inicial!#REF!,"N/A") -> #REF! | H19: =IF(Inicial!#REF!="SI",Inicial!#REF!,"N/A") -> #REF! | I19: =IF(Inicial!#REF!="SI",Inicial!#REF!,"N/A") -> #REF! | P19: =IF(OR(J19="NO",K19="NO",L19="NO",M19="NO",N19="NO",O19="NO"),"No Aceptable","Aceptable") -> Aceptable | W19: =IF(AND(Q19="NO",R19="NO",S19="NO",T19="NO",U19="NO",V19="NO"),"No Critico","Critico") -> Critico
A20: =Inicial!#REF! -> #REF! | B20: =Inicial!#REF! -> #REF! | C20: =Inicial!#REF! -> #REF! | D20: =Inicial!#REF! -> #REF! | E20: =IF(Inicial!#REF!="SI",Inicial!#REF!,"N/A") -> #REF! | F20: =IF(Inicial!#REF!="SI",Inicial!#REF!,"N/A") -> #REF! | G20: =IF(Inicial!#REF!="SI",Inicial!#REF!,"N/A") -> #REF! | H20: =IF(Inicial!#REF!="SI",Inicial!#REF!,"N/A") -> #REF! | I20: =IF(Inicial!#REF!="SI",Inicial!#REF!,"N/A") -> #REF! | P20: =IF(OR(J20="NO",K20="NO",L20="NO",M20="NO",N20="NO",O20="NO"),"No Aceptable","Aceptable") -> Aceptable | W20: =IF(AND(Q20="NO",R20="NO",S20="NO",T20="NO",U20="NO",V20="NO"),"No Critico","Critico") -> Critico
A21: =Inicial!#REF! -> #REF! | B21: =Inicial!#REF! -> #REF! | C21: =Inicial!#REF! -> #REF! | D21: =Inicial!#REF! -> #REF! | E21: =IF(Inicial!#REF!="SI",Inicial!#REF!,"N/A") -> #REF! | F21: =IF(Inicial!#REF!="SI",Inicial!#REF!,"N/A") -> #REF! | G21: =IF(Inicial!#REF!="SI",Inicial!#REF!,"N/A") -> #REF! | H21: =IF(Inicial!#REF!="SI",Inicial!#REF!,"N/A") -> #REF! | I21: =IF(Inicial!#REF!="SI",Inicial!#REF!,"N/A") -> #REF! | P21: =IF(OR(J21="NO",K21="NO",L21="NO",M21="NO",N21="NO",O21="NO"),"No Aceptable","Aceptable") -> Aceptable | W21: =IF(AND(Q21="NO",R21="NO",S21="NO",T21="NO",U21="NO",V21="NO"),"No Critico","Critico") -> Critico
... A47: =Inicial!#REF! -> #REF! | B47: =Inicial!#REF! -> #REF! | C47: =Inicial!#REF! -> #REF! | D47: =Inicial!#REF! -> #REF! | E47: =IF(Inicial!#REF!="SI",Inicial!#REF!,"N/A") -> #REF! | F47: =IF(Inicial!#REF!="SI",Inicial!#REF!,"N/A") -> #REF! | G47: =IF(Inicial!#REF!="SI",Inicial!#REF!,"N/A") -> #REF! | H47: =IF(Inicial!#REF!="SI",Inicial!#REF!,"N/A") -> #REF! | I47: =IF(Inicial!#REF!="SI",Inicial!#REF!,"N/A") -> #REF! | P47: =IF(OR(J47="NO",K47="NO",L47="NO",M47="NO",N47="NO",O47="NO"),"No Aceptable","Aceptable") -> Aceptable | W47: =IF(AND(Q47="NO",R47="NO",S47="NO",T47="NO",U47="NO",V47="NO"),"No Critico","Critico") -> Critico
A48: =Inicial!A10 -> 0 | B48: =Inicial!B10 -> 0 | C48: =Inicial!C10 -> 0 | D48: =Inicial!D10 -> 0 | E48: =IF(Inicial!J10="SI",Inicial!E10,"N/A") -> N/A | F48: =IF(Inicial!J10="SI",Inicial!F10,"N/A") -> N/A | G48: =IF(Inicial!J10="SI",Inicial!G10,"N/A") -> N/A | H48: =IF(Inicial!J10="SI",Inicial!H10,"N/A") -> N/A | I48: =IF(Inicial!J10="SI",Inicial!I10,"N/A") -> N/A | P48: =IF(OR(J48="NO",K48="NO",L48="NO",M48="NO",N48="NO",O48="NO"),"No Aceptable","Aceptable") -> Aceptable | W48: =IF(AND(Q48="NO",R48="NO",S48="NO",T48="NO",U48="NO",V48="NO"),"No Critico","Critico") -> Critico
A49: =Inicial!A11 -> 0 | B49: =Inicial!B11 -> 0 | C49: =Inicial!C11 -> 0 | D49: =Inicial!D11 -> 0 | E49: =IF(Inicial!J11="SI",Inicial!E11,"N/A") -> N/A | F49: =IF(Inicial!J11="SI",Inicial!F11,"N/A") -> N/A | G49: =IF(Inicial!J11="SI",Inicial!G11,"N/A") -> N/A | H49: =IF(Inicial!J11="SI",Inicial!H11,"N/A") -> N/A | I49: =IF(Inicial!J11="SI",Inicial!I11,"N/A") -> N/A | P49: =IF(OR(J49="NO",K49="NO",L49="NO",M49="NO",N49="NO",O49="NO"),"No Aceptable","Aceptable") -> Aceptable | W49: =IF(AND(Q49="NO",R49="NO",S49="NO",T49="NO",U49="NO",V49="NO"),"No Critico","Critico") -> Critico
A50: =Inicial!A12 -> 0 | B50: =Inicial!B12 -> 0 | C50: =Inicial!C12 -> 0 | D50: =Inicial!D12 -> 0 | E50: =IF(Inicial!J12="SI",Inicial!E12,"N/A") -> N/A | F50: =IF(Inicial!J12="SI",Inicial!F12,"N/A") -> N/A | G50: =IF(Inicial!J12="SI",Inicial!G12,"N/A") -> N/A | H50: =IF(Inicial!J12="SI",Inicial!H12,"N/A") -> N/A | I50: =IF(Inicial!J12="SI",Inicial!I12,"N/A") -> N/A | P50: =IF(OR(J50="NO",K50="NO",L50="NO",M50="NO",N50="NO",O50="NO"),"No Aceptable","Aceptable") -> Aceptable | W50: =IF(AND(Q50="NO",R50="NO",S50="NO",T50="NO",U50="NO",V50="NO"),"No Critico","Critico") -> Critico
A51: =Inicial!A13 -> 0 | B51: =Inicial!B13 -> 0 | C51: =Inicial!C13 -> 0 | D51: =Inicial!D13 -> 0 | E51: =IF(Inicial!J13="SI",Inicial!E13,"N/A") -> N/A | F51: =IF(Inicial!J13="SI",Inicial!F13,"N/A") -> N/A | G51: =IF(Inicial!J13="SI",Inicial!G13,"N/A") -> N/A | H51: =IF(Inicial!J13="SI",Inicial!H13,"N/A") -> N/A | I51: =IF(Inicial!J13="SI",Inicial!I13,"N/A") -> N/A | P51: =IF(OR(J51="NO",K51="NO",L51="NO",M51="NO",N51="NO",O51="NO"),"No Aceptable","Aceptable") -> Aceptable | W51: =IF(AND(Q51="NO",R51="NO",S51="NO",T51="NO",U51="NO",V51="NO"),"No Critico","Critico") -> Critico
A52: =Inicial!A14 -> 0 | B52: =Inicial!B14 -> 0 | C52: =Inicial!C14 -> 0 | D52: =Inicial!D14 -> 0 | E52: =IF(Inicial!J14="SI",Inicial!E14,"N/A") -> N/A | F52: =IF(Inicial!J14="SI",Inicial!F14,"N/A") -> N/A | G52: =IF(Inicial!J14="SI",Inicial!G14,"N/A") -> N/A | H52: =IF(Inicial!J14="SI",Inicial!H14,"N/A") -> N/A | I52: =IF(Inicial!J14="SI",Inicial!I14,"N/A") -> N/A | P52: =IF(OR(J52="NO",K52="NO",L52="NO",M52="NO",N52="NO",O52="NO"),"No Aceptable","Aceptable") -> Aceptable | W52: =IF(AND(Q52="NO",R52="NO",S52="NO",T52="NO",U52="NO",V52="NO"),"No Critico","Critico") -> Critico
A53: =Inicial!A15 -> 0 | B53: =Inicial!B15 -> 0 | C53: =Inicial!C15 -> 0 | D53: =Inicial!D15 -> 0 | E53: =IF(Inicial!J15="SI",Inicial!E15,"N/A") -> N/A | F53: =IF(Inicial!J15="SI",Inicial!F15,"N/A") -> N/A | G53: =IF(Inicial!J15="SI",Inicial!G15,"N/A") -> N/A | H53: =IF(Inicial!J15="SI",Inicial!H15,"N/A") -> N/A | I53: =IF(Inicial!J15="SI",Inicial!I15,"N/A") -> N/A | P53: =IF(OR(J53="NO",K53="NO",L53="NO",M53="NO",N53="NO",O53="NO"),"No Aceptable","Aceptable") -> Aceptable | W53: =IF(AND(Q53="NO",R53="NO",S53="NO",T53="NO",U53="NO",V53="NO"),"No Critico","Critico") -> Critico
A54: =Inicial!A16 -> 0 | B54: =Inicial!B16 -> 0 | C54: =Inicial!C16 -> 0 | D54: =Inicial!D16 -> 0 | E54: =IF(Inicial!J16="SI",Inicial!E16,"N/A") -> N/A | F54: =IF(Inicial!J16="SI",Inicial!F16,"N/A") -> N/A | G54: =IF(Inicial!J16="SI",Inicial!G16,"N/A") -> N/A | H54: =IF(Inicial!J16="SI",Inicial!H16,"N/A") -> N/A | I54: =IF(Inicial!J16="SI",Inicial!I16,"N/A") -> N/A | P54: =IF(OR(J54="NO",K54="NO",L54="NO",M54="NO",N54="NO",O54="NO"),"No Aceptable","Aceptable") -> Aceptable | W54: =IF(AND(Q54="NO",R54="NO",S54="NO",T54="NO",U54="NO",V54="NO"),"No Critico","Critico") -> Critico
A55: =Inicial!A17 -> 0 | B55: =Inicial!B17 -> 0 | C55: =Inicial!C17 -> 0 | D55: =Inicial!D17 -> 0 | E55: =IF(Inicial!J17="SI",Inicial!E17,"N/A") -> N/A | F55: =IF(Inicial!J17="SI",Inicial!F17,"N/A") -> N/A | G55: =IF(Inicial!J17="SI",Inicial!G17,"N/A") -> N/A | H55: =IF(Inicial!J17="SI",Inicial!H17,"N/A") -> N/A | I55: =IF(Inicial!J17="SI",Inicial!I17,"N/A") -> N/A | P55: =IF(OR(J55="NO",K55="NO",L55="NO",M55="NO",N55="NO",O55="NO"),"No Aceptable","Aceptable") -> Aceptable | W55: =IF(AND(Q55="NO",R55="NO",S55="NO",T55="NO",U55="NO",V55="NO"),"No Critico","Critico") -> Critico
A56: =Inicial!A18 -> 0 | B56: =Inicial!B18 -> 0 | C56: =Inicial!C18 -> 0 | D56: =Inicial!D18 -> 0 | E56: =IF(Inicial!J18="SI",Inicial!E18,"N/A") -> N/A | F56: =IF(Inicial!J18="SI",Inicial!F18,"N/A") -> N/A | G56: =IF(Inicial!J18="SI",Inicial!G18,"N/A") -> N/A | H56: =IF(Inicial!J18="SI",Inicial!H18,"N/A") -> N/A | I56: =IF(Inicial!J18="SI",Inicial!I18,"N/A") -> N/A | P56: =IF(OR(J56="NO",K56="NO",L56="NO",M56="NO",N56="NO",O56="NO"),"No Aceptable","Aceptable") -> Aceptable | W56: =IF(AND(Q56="NO",R56="NO",S56="NO",T56="NO",U56="NO",V56="NO"),"No Critico","Critico") -> Critico
A57: =Inicial!A19 -> 0 | B57: =Inicial!B19 -> 0 | C57: =Inicial!C19 -> 0 | D57: =Inicial!D19 -> 0 | E57: =IF(Inicial!J19="SI",Inicial!E19,"N/A") -> N/A | F57: =IF(Inicial!J19="SI",Inicial!F19,"N/A") -> N/A | G57: =IF(Inicial!J19="SI",Inicial!G19,"N/A") -> N/A | H57: =IF(Inicial!J19="SI",Inicial!H19,"N/A") -> N/A | I57: =IF(Inicial!J19="SI",Inicial!I19,"N/A") -> N/A | P57: =IF(OR(J57="NO",K57="NO",L57="NO",M57="NO",N57="NO",O57="NO"),"No Aceptable","Aceptable") -> Aceptable | W57: =IF(AND(Q57="NO",R57="NO",S57="NO",T57="NO",U57="NO",V57="NO"),"No Critico","Critico") -> Critico
A58: =Inicial!A20 -> 0 | B58: =Inicial!B20 -> 0 | C58: =Inicial!C20 -> 0 | D58: =Inicial!D20 -> 0 | E58: =IF(Inicial!J20="SI",Inicial!E20,"N/A") -> N/A | F58: =IF(Inicial!J20="SI",Inicial!F20,"N/A") -> N/A | G58: =IF(Inicial!J20="SI",Inicial!G20,"N/A") -> N/A | H58: =IF(Inicial!J20="SI",Inicial!H20,"N/A") -> N/A | I58: =IF(Inicial!J20="SI",Inicial!I20,"N/A") -> N/A | P58: =IF(OR(J58="NO",K58="NO",L58="NO",M58="NO",N58="NO",O58="NO"),"No Aceptable","Aceptable") -> Aceptable | W58: =IF(AND(Q58="NO",R58="NO",S58="NO",T58="NO",U58="NO",V58="NO"),"No Critico","Critico") -> Critico
A59: =Inicial!A21 -> 0 | B59: =Inicial!B21 -> 0 | C59: =Inicial!C21 -> 0 | D59: =Inicial!D21 -> 0 | E59: =IF(Inicial!J21="SI",Inicial!E21,"N/A") -> N/A | F59: =IF(Inicial!J21="SI",Inicial!F21,"N/A") -> N/A | G59: =IF(Inicial!J21="SI",Inicial!G21,"N/A") -> N/A | H59: =IF(Inicial!J21="SI",Inicial!H21,"N/A") -> N/A | I59: =IF(Inicial!J21="SI",Inicial!I21,"N/A") -> N/A | P59: =IF(OR(J59="NO",K59="NO",L59="NO",M59="NO",N59="NO",O59="NO"),"No Aceptable","Aceptable") -> Aceptable | W59: =IF(AND(Q59="NO",R59="NO",S59="NO",T59="NO",U59="NO",V59="NO"),"No Critico","Critico") -> Critico
... A219: =Inicial!A181 -> 0 | B219: =Inicial!B181 -> 0 | C219: =Inicial!C181 -> 0 | D219: =Inicial!D181 -> 0 | E219: =IF(Inicial!J181="SI",Inicial!E181,"N/A") -> N/A | F219: =IF(Inicial!J181="SI",Inicial!F181,"N/A") -> N/A | G219: =IF(Inicial!J181="SI",Inicial!G181,"N/A") -> N/A | H219: =IF(Inicial!J181="SI",Inicial!H181,"N/A") -> N/A | I219: =IF(Inicial!J181="SI",Inicial!I181,"N/A") -> N/A | P219: =IF(OR(J219="NO",K219="NO",L219="NO",M219="NO",N219="NO",O219="NO"),"No Aceptable","Aceptable") -> Aceptable | W219: =IF(AND(Q219="NO",R219="NO",S219="NO",T219="NO",U219="NO",V219="NO"),"No Critico","Critico") -> Critico
A220: =Inicial!A182 -> 0 | P220: =IF(OR(J220="NO",K220="NO",L220="NO",M220="NO",N220="NO",O220="NO"),"No Aceptable","Aceptable") -> Aceptable | W220: =IF(AND(Q220="NO",R220="NO",S220="NO",T220="NO",U220="NO",V220="NO"),"No Critico","Critico") -> Critico
A221: =Inicial!A183 -> 0 | P221: =IF(OR(J221="NO",K221="NO",L221="NO",M221="NO",N221="NO",O221="NO"),"No Aceptable","Aceptable") -> Aceptable | W221: =IF(AND(Q221="NO",R221="NO",S221="NO",T221="NO",U221="NO",V221="NO"),"No Critico","Critico") -> Critico
A222: =Inicial!A184 -> 0 | P222: =IF(OR(J222="NO",K222="NO",L222="NO",M222="NO",N222="NO",O222="NO"),"No Aceptable","Aceptable") -> Aceptable | W222: =IF(AND(Q222="NO",R222="NO",S222="NO",T222="NO",U222="NO",V222="NO"),"No Critico","Critico") -> Critico
A223: =Inicial!A185 -> 0 | P223: =IF(OR(J223="NO",K223="NO",L223="NO",M223="NO",N223="NO",O223="NO"),"No Aceptable","Aceptable") -> Aceptable | W223: =IF(AND(Q223="NO",R223="NO",S223="NO",T223="NO",U223="NO",V223="NO"),"No Critico","Critico") -> Critico
A224: =Inicial!A186 -> 0 | P224: =IF(OR(J224="NO",K224="NO",L224="NO",M224="NO",N224="NO",O224="NO"),"No Aceptable","Aceptable") -> Aceptable | W224: =IF(AND(Q224="NO",R224="NO",S224="NO",T224="NO",U224="NO",V224="NO"),"No Critico","Critico") -> Critico
...

Sheet MMC Levantamiento-Descenso
A1: Levantamiento y Descenso | F1: Horas extras | H1: N° Trabajadores Expuestos | J1: IDENTIFICACIÓN AVANZADA – Tarea(s) con MMC: Levantamiento, Descenso y Transporte de cargas de 3kg o más – Condición Aceptable AMBIENTE TRABAJO | M1: IDENTIFICACIÓN AVANZADA – Tarea(s) con MMC: Levantamiento, Descenso y Transporte de cargas de 3kg o más – Condición Aceptable CARACTERITICA DE LA CARGA | Q1: IDENTIFICACIÓN AVANZADA – Tarea(s) con MMC: Levantamiento, Descenso y Transporte de cargas de 3kg o más – Condición Aceptable PESO DE CARGA 3KG A 5 KG | U1: IDENTIFICACIÓN AVANZADA – Tarea(s) con MMC: Levantamiento, Descenso y Transporte de cargas de 3kg o más – Condición Aceptable PESO DE CARGA 5 KG A 10 KG | Y1: IDENTIFICACIÓN AVANZADA – Tarea(s) con MMC: Levantamiento, Descenso y Transporte de cargas de 3kg o más – Condición Aceptable SOBRE 10 KG | Z1: Transporte manual de carga. ¿El peso acumulado transportado* es menor a los valores recomendados? Distancia <= 10 metros | AC1: Transporte manual de carga. ¿El peso acumulado transportado* es menor a los valores recomendados? Distancia > = 10 metros | AF1: Transporte manual de cargas | AG1: RESULTADO | AH1: IDENTIFICACIÓN AVANZADA – Tarea(s) con MMC: Levantamiento, Descenso y Transporte de cargas de 3kg o más – Condición Crítica AMBIENTE TRABAJO | AK1: IDENTIFICACIÓN AVANZADA – Tarea(s) con MMC: Levantamiento, Descenso y Transporte de cargas de 3kg o más – Condición Crítica CARACTERISTICA DE LA CARGA | AO1: IDENTIFICACIÓN AVANZADA – Tarea(s) con MMC: Levantamiento, Descenso y Transporte de cargas de 3kg o más – Condición Crítica HORAS DE TRABAJO | AP1: Presencia de tarea de levantamiento/descenso y transporte de carga con condiciones de diseño y frecuencia que exceden los valores máximos sugeridos | AW1: Condición crítica: presencia de tarea de levantamiento/descenso y transporte con peso de la carga que exceda los siguientes límites | BB1: Levantamiento / descenso y transporte manual de carga | BD1: RESULTADO | BE1: Plan de acción
A2: N° | B2: Área de trabajo | C2: Puesto de trabajo | D2: Tareas del puesto de trabajo | E2: Horario de funcionamiento | F2: Por dia | G2: Por Semana | H2: HOMBRE | I2: MUJER | J2: La temperatura en donde se realiza la tarea está entre los 18° y 26° (grados Celsius). | K2: El piso se encuentra en buenas condiciones (regular, seco y estable) | L2: El espacio de trabajo permite el normal movimiento de los trabajadores (sin generar posturas incómodas) durante el levantamiento/descenso y/o transporte | M2: El tamaño de la carga permite la visibilidad y movimientos normales del trabajador | N2: El centro de gravedad de la carga es estable | O2: La carga permite su agarre sin riesgo de cortes, compresión o quemaduras. | P2: La tarea de levantamiento/descenso o transporte de carga dura menos de 8 horas. | Q2: Se observa ausencia de asimetría (Ej: cuerpo rotado, torsión y/o inclinación de tronco) | R2: La carga es mantenida cerca del cuerpo | S2: El desplazamiento vertical de la carga se realiza entre las caderas y los hombros | T2: Frecuencia máxima de MMC: el levantamiento/descenso es menor a 5 veces por minuto | U2: Se observa ausencia de asimetría (Ej: cuerpo rotado, torsión y/o inclinación de tronco) | V2: La carga es mantenida cerca del cuerpo | W2: El desplazamiento vertical de la carga se realiza entre las caderas y los hombros | X2: Frecuencia máxima de MMC: el levantamiento/descenso es menor a 1 vez por minuto | Y2: Ausencia de cargas mayores a 10 kg | Z2: 8 hr = 10.000 kg | AA2: 1 hora = 1.500 kilos | AB2: 1 minuto = 30 kilos | AC2: 8 hr = 6.000 kg | AD2: 1 hora = 750 kilos | AE2: 1 minuto = 15 kilos | AF2: Ausencia de postura inadecuadas durante el transporte de carga | AG2: Condición Aceptable | AH2: Presencia de temperatura extrema (bajo 16° o superior a los 26° grados Celsius) y sin ropa adecuada que proteja de las temperaturas extremas | AI2: Presencia de suelo resbaladizo, irregular o inestable | AJ2: Presencia de espacio insuficiente para el levantamiento/descenso y transporte de carga que genera posturas incómodas o restricción en el movimiento. | AK2: El tamaño de la carga reduce la visión del trabajador y/o dificulta su movimiento | AL2: El centro de gravedad de la carga no es estable (ej.: líquidos, elementos que se mueven dentro de la carga) | AM2: La forma/configuración de la carga presenta bordes, superficies o protuberancias afiladas | AN2: Las superficies de contacto son demasiado frías o demasiado calientes | AO2: La tarea de levantamiento/descenso o transporte de carga dura más de 8 hrs. | AP2: Posición vertical La ubicación de las manos al inicio o final del levantamiento/descenso de una carga es superior a 155 cm o inferior a 20 cm | AQ2: Desplazamiento vertical La distancia vertical entre el origen y el destino del objeto manipulado es mayor a 135 cm | AR2: Distancia horizontal La distancia horizontal entre el cuerpo y las manos (nudillos) es superior a 55 cm correspondiente a la zona de alcance máximo de brazos | AS2: Asimetría Rotación o inclinación extrema del tronco sin movimientos de los pies | AT2: Frecuencia Corta duración: más de 15 levant./desc. por min, en una tarea que no supere los 60 min seguidos en el turno de trabajo y seguida de al menos 60 min de desc. o tarea liviana (que no implique MMC) | AU2: Frecuencia Media duración: + de 12 levant/desc por min, en una tarea que no supere los 120 min seguidos en el turno de trabajo y seguida de al menos 30 min de descanso o tarea liviana (que no implique MMC). | AV2: Frecuencia Larga duración: más de 8 levantamientos/descensos por minuto, en una tarea que supere los 120 minutos seguidos en el turno de trabajo | AW2: Hombres (18-45 años) 25KG | AX2: Mujeres (18-45 años) 20KG | AY2: Hombres (<18 o >45 años) 20KG | AZ2: Mujeres (<18 o >45 años) 15KG | BA2: Mujer embarazada 3KG | BB2: Distancia de transporte de 20 mt o más 6.000 kg en 8 hr | BC2: Distancia de transporte menos de 20 mt 10.000 kg en 8 hr | BD2: Condición Crítica | BE2: Fecha aplicación identificación avanzada | BF2: Medidas de control (administrativas) | BG2: Medidas de control (Ingeniería) | BH2: Responsable aplicación medida | BI2: Fecha de implementación medidas (Max 90 días) | BJ2: Evidencia
A3: =Inicial!A3 -> 1 | B3: =Inicial!B3 -> Despacho | C3: =Inicial!C3 -> Carton Frezzer | D3: =Inicial!D3 -> Pinchador | E3: =IF(Inicial!L3="SI",Inicial!E3,"N/A") -> 06:00 - 14:00 14:00 - 22:00 22:00 - 06:00 | F3: =IF(Inicial!L3="SI",Inicial!F3,"N/A") -> 0 | G3: =IF(Inicial!L3="SI",Inicial!G3,"N/A") -> 2 | H3: =IF(Inicial!L3="SI",Inicial!H3,"N/A") -> 6 | I3: =IF(Inicial!L3="SI",Inicial!I3,"N/A") -> 0 | J3: NO | K3: SI | L3: SI | M3: SI | N3: SI | O3: SI | P3: SI | Q3: N/A | R3: N/A | S3: N/A | T3: N/A | U3: N/A | V3: N/A | W3: N/A | X3: N/A | Y3: NO | Z3: SI | AA3: SI | AB3: SI | AC3: SI | AD3: SI | AE3: SI | AF3: SI | AG3: {=IF(OR(M3:AF3="NO"),"No aceptable","Aceptable")} -> No aceptable | AH3: NO | AI3: NO | AJ3: NO | AK3: NO | AL3: NO | AM3: NO | AN3: NO | AO3: NO | AP3: NO | AQ3: NO | AR3: NO | AS3: NO | AT3: NO | AU3: NO | AV3: NO | AW3: NO | AX3: N/A | AY3: NO | AZ3: N/A | BA3: N/A | BB3: N/A | BC3: NO | BD3: {=IF(OR(AK3:BC3="SI"),"Critico","No Critico")} -> No Critico
A4: =Inicial!A4 -> 2 | B4: =Inicial!B4 -> Despacho | C4: =Inicial!C4 -> Carton Frezzer | D4: =Inicial!D4 -> Depaletizador | E4: =IF(Inicial!L4="SI",Inicial!E4,"N/A") -> 06:00 - 14:00 14:00 - 22:00 22:00 - 06:00 | F4: =IF(Inicial!L4="SI",Inicial!F4,"N/A") -> 0 | G4: =IF(Inicial!L4="SI",Inicial!G4,"N/A") -> 2 | H4: =IF(Inicial!L4="SI",Inicial!H4,"N/A") -> 24 | I4: =IF(Inicial!L4="SI",Inicial!I4,"N/A") -> 0 | J4: NO | K4: SI | L4: SI | M4: SI | N4: SI | O4: SI | P4: SI | Q4: N/A | R4: N/A | S4: N/A | T4: N/A | U4: SI | V4: SI | W4: SI | X4: NO | Y4: NO | Z4: SI | AA4: SI | AB4: SI | AC4: SI | AD4: SI | AE4: SI | AF4: SI | AG4: {=IF(OR(M4:AF4="NO"),"No aceptable","Aceptable")} -> No aceptable | AH4: NO | AI4: NO | AJ4: NO | AK4: NO | AL4: NO | AM4: NO | AN4: NO | AO4: NO | AP4: NO | AQ4: SI | AR4: NO | AS4: NO | AT4: NO | AU4: NO | AV4: NO | AW4: NO | AX4: NO | AY4: N/A | AZ4: NO | BA4: N/A | BB4: NO | BC4: NO | BD4: No Critico
A5: =Inicial!A5 -> 3 | B5: =Inicial!B5 -> Despacho | C5: =Inicial!C5 -> Carton Frezzer | D5: =Inicial!D5 -> Pinchador | E5: =IF(Inicial!L5="SI",Inicial!E5,"N/A") -> 06:00 - 14:00 14:00 - 22:00 22:00 - 06:00 | F5: =IF(Inicial!L5="SI",Inicial!F5,"N/A") -> 0 | G5: =IF(Inicial!L5="SI",Inicial!G5,"N/A") -> 2 | H5: =IF(Inicial!L5="SI",Inicial!H5,"N/A") -> 24 | I5: =IF(Inicial!L5="SI",Inicial!I5,"N/A") -> 0 | J5: NO | K5: SI | L5: SI | M5: SI | N5: SI | O5: SI | P5: SI | Q5: N/A | R5: N/A | S5: N/A | T5: N/A | U5: SI | V5: SI | W5: SI | X5: NO | Y5: NO | Z5: SI | AA5: SI | AB5: SI | AC5: SI | AD5: SI | AE5: SI | AF5: SI | AG5: {=IF(OR(M5:AF5="NO"),"No aceptable","Aceptable")} -> No aceptable | AH5: NO | AI5: NO | AJ5: NO | AK5: NO | AL5: NO | AM5: NO | AN5: NO | AO5: NO | AP5: NO | AQ5: SI | AR5: NO | AS5: NO | AT5: NO | AU5: NO | AV5: NO | AW5: NO | AX5: NO | AY5: N/A | AZ5: NO | BA5: N/A | BB5: NO | BC5: NO | BD5: No Critico
A6: =Inicial!A6 -> 4 | B6: =Inicial!B6 -> Despacho | C6: =Inicial!C6 -> Despacho congelado | D6: =Inicial!D6 -> Gruero | E6: =IF(Inicial!L6="SI",Inicial!E6,"N/A") -> N/A | F6: =IF(Inicial!L6="SI",Inicial!F6,"N/A") -> N/A | G6: =IF(Inicial!L6="SI",Inicial!G6,"N/A") -> N/A | H6: =IF(Inicial!L6="SI",Inicial!H6,"N/A") -> N/A | I6: =IF(Inicial!L6="SI",Inicial!I6,"N/A") -> N/A | AG6: {=IF(OR(M6:AF6="NO"),"No aceptable","Aceptable")} -> Aceptable | BD6: {=IF(OR(AK6:BC6="SI"),"Critico","No Critico")} -> No Critico
A7: =Inicial!A7 -> 5 | B7: =Inicial!B7 -> Despacho | C7: =Inicial!C7 -> Despacho congelado | D7: =Inicial!D7 -> Transpaletero | E7: =IF(Inicial!L7="SI",Inicial!E7,"N/A") -> N/A | F7: =IF(Inicial!L7="SI",Inicial!F7,"N/A") -> N/A | G7: =IF(Inicial!L7="SI",Inicial!G7,"N/A") -> N/A | H7: =IF(Inicial!L7="SI",Inicial!H7,"N/A") -> N/A | I7: =IF(Inicial!L7="SI",Inicial!I7,"N/A") -> N/A | AG7: {=IF(OR(M7:AF7="NO"),"No aceptable","Aceptable")} -> Aceptable | BD7: {=IF(OR(AK7:BC7="SI"),"Critico","No Critico")} -> No Critico
A8: =Inicial!A8 -> 6 | B8: =Inicial!B8 -> Despacho | C8: =Inicial!C8 -> Despacho congelado | D8: =Inicial!D8 -> Postura de films | E8: =IF(Inicial!L8="SI",Inicial!E8,"N/A") -> N/A | F8: =IF(Inicial!L8="SI",Inicial!F8,"N/A") -> N/A | G8: =IF(Inicial!L8="SI",Inicial!G8,"N/A") -> N/A | H8: =IF(Inicial!L8="SI",Inicial!H8,"N/A") -> N/A | I8: =IF(Inicial!L8="SI",Inicial!I8,"N/A") -> N/A | AG8: {=IF(OR(M8:AF8="NO"),"No aceptable","Aceptable")} -> Aceptable | BD8: {=IF(OR(AK8:BC8="SI"),"Critico","No Critico")} -> No Critico
A9: =Inicial!A9 -> 7 | B9: =Inicial!B9 -> Despacho | C9: =Inicial!C9 -> Despacho Congelado | D9: =Inicial!D9 -> Reprocesos de producto | E9: =IF(Inicial!L9="SI",Inicial!E9,"N/A") -> 06:00 - 14:00 14:00 - 22:00 22:00 - 06:00 | F9: =IF(Inicial!L9="SI",Inicial!F9,"N/A") -> 0 | G9: =IF(Inicial!L9="SI",Inicial!G9,"N/A") -> 2 | H9: =IF(Inicial!L9="SI",Inicial!H9,"N/A") -> 0 | I9: =IF(Inicial!L9="SI",Inicial!I9,"N/A") -> 0 | AG9: {=IF(OR(M9:AF9="NO"),"No aceptable","Aceptable")} -> Aceptable | BD9: {=IF(OR(AK9:BC9="SI"),"Critico","No Critico")} -> No Critico
A10: =Inicial!#REF! -> #REF! | B10: =Inicial!#REF! -> #REF! | C10: =Inicial!#REF! -> #REF! | D10: =Inicial!#REF! -> #REF! | E10: =IF(Inicial!#REF!="SI",Inicial!#REF!,"N/A") -> #REF! | F10: =IF(Inicial!#REF!="SI",Inicial!#REF!,"N/A") -> #REF! | G10: =IF(Inicial!#REF!="SI",Inicial!#REF!,"N/A") -> #REF! | H10: =IF(Inicial!#REF!="SI",Inicial!#REF!,"N/A") -> #REF! | I10: =IF(Inicial!#REF!="SI",Inicial!#REF!,"N/A") -> #REF! | AG10: {=IF(OR(M10:AF10="NO"),"No aceptable","Aceptable")} -> Aceptable | BD10: {=IF(OR(AK10:BC10="SI"),"Critico","No Critico")} -> No Critico
A11: =Inicial!#REF! -> #REF! | B11: =Inicial!#REF! -> #REF! | C11: =Inicial!#REF! -> #REF! | D11: =Inicial!#REF! -> #REF! | E11: =IF(Inicial!#REF!="SI",Inicial!#REF!,"N/A") -> #REF! | F11: =IF(Inicial!#REF!="SI",Inicial!#REF!,"N/A") -> #REF! | G11: =IF(Inicial!#REF!="SI",Inicial!#REF!,"N/A") -> #REF! | H11: =IF(Inicial!#REF!="SI",Inicial!#REF!,"N/A") -> #REF! | I11: =IF(Inicial!#REF!="SI",Inicial!#REF!,"N/A") -> #REF! | AG11: {=IF(OR(M11:AF11="NO"),"No aceptable","Aceptable")} -> Aceptable | BD11: {=IF(OR(AK11:BC11="SI"),"Critico","No Critico")} -> No Critico
A12: =Inicial!#REF! -> #REF! | B12: =Inicial!#REF! -> #REF! | C12: =Inicial!#REF! -> #REF! | D12: =Inicial!#REF! -> #REF! | E12: =IF(Inicial!#REF!="SI",Inicial!#REF!,"N/A") -> #REF! | F12: =IF(Inicial!#REF!="SI",Inicial!#REF!,"N/A") -> #REF! | G12: =IF(Inicial!#REF!="SI",Inicial!#REF!,"N/A") -> #REF! | H12: =IF(Inicial!#REF!="SI",Inicial!#REF!,"N/A") -> #REF! | I12: =IF(Inicial!#REF!="SI",Inicial!#REF!,"N/A") -> #REF! | AG12: {=IF(OR(M12:AF12="NO"),"No aceptable","Aceptable")} -> Aceptable | BD12: {=IF(OR(AK12:BC12="SI"),"Critico","No Critico")} -> No Critico
A13: =Inicial!#REF! -> #REF! | B13: =Inicial!#REF! -> #REF! | C13: =Inicial!#REF! -> #REF! | D13: =Inicial!#REF! -> #REF! | E13: =IF(Inicial!#REF!="SI",Inicial!#REF!,"N/A") -> #REF! | F13: =IF(Inicial!#REF!="SI",Inicial!#REF!,"N/A") -> #REF! | G13: =IF(Inicial!#REF!="SI",Inicial!#REF!,"N/A") -> #REF! | H13: =IF(Inicial!#REF!="SI",Inicial!#REF!,"N/A") -> #REF! | I13: =IF(Inicial!#REF!="SI",Inicial!#REF!,"N/A") -> #REF! | AG13: {=IF(OR(M13:AF13="NO"),"No aceptable","Aceptable")} -> Aceptable | BD13: {=IF(OR(AK13:BC13="SI"),"Critico","No Critico")} -> No Critico
A14: =Inicial!#REF! -> #REF! | B14: =Inicial!#REF! -> #REF! | C14: =Inicial!#REF! -> #REF! | D14: =Inicial!#REF! -> #REF! | E14: =IF(Inicial!#REF!="SI",Inicial!#REF!,"N/A") -> #REF! | F14: =IF(Inicial!#REF!="SI",Inicial!#REF!,"N/A") -> #REF! | G14: =IF(Inicial!#REF!="SI",Inicial!#REF!,"N/A") -> #REF! | H14: =IF(Inicial!#REF!="SI",Inicial!#REF!,"N/A") -> #REF! | I14: =IF(Inicial!#REF!="SI",Inicial!#REF!,"N/A") -> #REF! | AG14: {=IF(OR(M14:AF14="NO"),"No aceptable","Aceptable")} -> Aceptable | BD14: {=IF(OR(AK14:BC14="SI"),"Critico","No Critico")} -> No Critico
A15: =Inicial!#REF! -> #REF! | B15: =Inicial!#REF! -> #REF! | C15: =Inicial!#REF! -> #REF! | D15: =Inicial!#REF! -> #REF! | E15: =IF(Inicial!#REF!="SI",Inicial!#REF!,"N/A") -> #REF! | F15: =IF(Inicial!#REF!="SI",Inicial!#REF!,"N/A") -> #REF! | G15: =IF(Inicial!#REF!="SI",Inicial!#REF!,"N/A") -> #REF! | H15: =IF(Inicial!#REF!="SI",Inicial!#REF!,"N/A") -> #REF! | I15: =IF(Inicial!#REF!="SI",Inicial!#REF!,"N/A") -> #REF! | AG15: {=IF(OR(M15:AF15="NO"),"No aceptable","Aceptable")} -> Aceptable | BD15: {=IF(OR(AK15:BC15="SI"),"Critico","No Critico")} -> No Critico
A16: =Inicial!#REF! -> #REF! | B16: =Inicial!#REF! -> #REF! | C16: =Inicial!#REF! -> #REF! | D16: =Inicial!#REF! -> #REF! | E16: =IF(Inicial!#REF!="SI",Inicial!#REF!,"N/A") -> #REF! | F16: =IF(Inicial!#REF!="SI",Inicial!#REF!,"N/A") -> #REF! | G16: =IF(Inicial!#REF!="SI",Inicial!#REF!,"N/A") -> #REF! | H16: =IF(Inicial!#REF!="SI",Inicial!#REF!,"N/A") -> #REF! | I16: =IF(Inicial!#REF!="SI",Inicial!#REF!,"N/A") -> #REF! | AG16: {=IF(OR(M16:AF16="NO"),"No aceptable","Aceptable")} -> Aceptable | BD16: {=IF(OR(AK16:BC16="SI"),"Critico","No Critico")} -> No Critico
A17: =Inicial!#REF! -> #REF! | B17: =Inicial!#REF! -> #REF! | C17: =Inicial!#REF! -> #REF! | D17: =Inicial!#REF! -> #REF! | E17: =IF(Inicial!#REF!="SI",Inicial!#REF!,"N/A") -> #REF! | F17: =IF(Inicial!#REF!="SI",Inicial!#REF!,"N/A") -> #REF! | G17: =IF(Inicial!#REF!="SI",Inicial!#REF!,"N/A") -> #REF! | H17: =IF(Inicial!#REF!="SI",Inicial!#REF!,"N/A") -> #REF! | I17: =IF(Inicial!#REF!="SI",Inicial!#REF!,"N/A") -> #REF! | AG17: {=IF(OR(M17:AF17="NO"),"No aceptable","Aceptable")} -> Aceptable | BD17: {=IF(OR(AK17:BC17="SI"),"Critico","No Critico")} -> No Critico
A18: =Inicial!#REF! -> #REF! | B18: =Inicial!#REF! -> #REF! | C18: =Inicial!#REF! -> #REF! | D18: =Inicial!#REF! -> #REF! | E18: =IF(Inicial!#REF!="SI",Inicial!#REF!,"N/A") -> #REF! | F18: =IF(Inicial!#REF!="SI",Inicial!#REF!,"N/A") -> #REF! | G18: =IF(Inicial!#REF!="SI",Inicial!#REF!,"N/A") -> #REF! | H18: =IF(Inicial!#REF!="SI",Inicial!#REF!,"N/A") -> #REF! | I18: =IF(Inicial!#REF!="SI",Inicial!#REF!,"N/A") -> #REF! | AG18: {=IF(OR(M18:AF18="NO"),"No aceptable","Aceptable")} -> Aceptable | BD18: {=IF(OR(AK18:BC18="SI"),"Critico","No Critico")} -> No Critico
A19: =Inicial!#REF! -> #REF! | B19: =Inicial!#REF! -> #REF! | C19: =Inicial!#REF! -> #REF! | D19: =Inicial!#REF! -> #REF! | E19: =IF(Inicial!#REF!="SI",Inicial!#REF!,"N/A") -> #REF! | F19: =IF(Inicial!#REF!="SI",Inicial!#REF!,"N/A") -> #REF! | G19: =IF(Inicial!#REF!="SI",Inicial!#REF!,"N/A") -> #REF! | H19: =IF(Inicial!#REF!="SI",Inicial!#REF!,"N/A") -> #REF! | I19: =IF(Inicial!#REF!="SI",Inicial!#REF!,"N/A") -> #REF! | AG19: {=IF(OR(M19:AF19="NO"),"No aceptable","Aceptable")} -> Aceptable | BD19: {=IF(OR(AK19:BC19="SI"),"Critico","No Critico")} -> No Critico
A20: =Inicial!#REF! -> #REF! | B20: =Inicial!#REF! -> #REF! | C20: =Inicial!#REF! -> #REF! | D20: =Inicial!#REF! -> #REF! | E20: =IF(Inicial!#REF!="SI",Inicial!#REF!,"N/A") -> #REF! | F20: =IF(Inicial!#REF!="SI",Inicial!#REF!,"N/A") -> #REF! | G20: =IF(Inicial!#REF!="SI",Inicial!#REF!,"N/A") -> #REF! | H20: =IF(Inicial!#REF!="SI",Inicial!#REF!,"N/A") -> #REF! | I20: =IF(Inicial!#REF!="SI",Inicial!#REF!,"N/A") -> #REF! | AG20: {=IF(OR(M20:AF20="NO"),"No aceptable","Aceptable")} -> Aceptable | BD20: {=IF(OR(AK20:BC20="SI"),"Critico","No Critico")} -> No Critico
A21: =Inicial!#REF! -> #REF! | B21: =Inicial!#REF! -> #REF! | C21: =Inicial!#REF! -> #REF! | D21: =Inicial!#REF! -> #REF! | E21: =IF(Inicial!#REF!="SI",Inicial!#REF!,"N/A") -> #REF! | F21: =IF(Inicial!#REF!="SI",Inicial!#REF!,"N/A") -> #REF! | G21: =IF(Inicial!#REF!="SI",Inicial!#REF!,"N/A") -> #REF! | H21: =IF(Inicial!#REF!="SI",Inicial!#REF!,"N/A") -> #REF! | I21: =IF(Inicial!#REF!="SI",Inicial!#REF!,"N/A") -> #REF! | AG21: {=IF(OR(M21:AF21="NO"),"No aceptable","Aceptable")} -> Aceptable | BD21: {=IF(OR(AK21:BC21="SI"),"Critico","No Critico")} -> No Critico
... A47: =Inicial!#REF! -> #REF! | B47: =Inicial!#REF! -> #REF! | C47: =Inicial!#REF! -> #REF! | D47: =Inicial!#REF! -> #REF! | E47: =IF(Inicial!#REF!="SI",Inicial!#REF!,"N/A") -> #REF! | F47: =IF(Inicial!#REF!="SI",Inicial!#REF!,"N/A") -> #REF! | G47: =IF(Inicial!#REF!="SI",Inicial!#REF!,"N/A") -> #REF! | H47: =IF(Inicial!#REF!="SI",Inicial!#REF!,"N/A") -> #REF! | I47: =IF(Inicial!#REF!="SI",Inicial!#REF!,"N/A") -> #REF! | AG47: {=IF(OR(M47:AF47="NO"),"No aceptable","Aceptable")} -> Aceptable | BD47: {=IF(OR(AK47:BC47="SI"),"Critico","No Critico")} -> No Critico
A48: =Inicial!A10 -> 0 | B48: =Inicial!B10 -> 0 | C48: =Inicial!C10 -> 0 | D48: =Inicial!D10 -> 0 | E48: =IF(Inicial!L10="SI",Inicial!E10,"N/A") -> N/A | F48: =IF(Inicial!L10="SI",Inicial!F10,"N/A") -> N/A | G48: =IF(Inicial!L10="SI",Inicial!G10,"N/A") -> N/A | H48: =IF(Inicial!L10="SI",Inicial!H10,"N/A") -> N/A | I48: =IF(Inicial!L10="SI",Inicial!I10,"N/A") -> N/A | AG48: {=IF(OR(M48:AF48="NO"),"No aceptable","Aceptable")} -> Aceptable | BD48: {=IF(OR(AK48:BC48="SI"),"Critico","No Critico")} -> No Critico
A49: =Inicial!A11 -> 0 | B49: =Inicial!B11 -> 0 | C49: =Inicial!C11 -> 0 | D49: =Inicial!D11 -> 0 | E49: =IF(Inicial!L11="SI",Inicial!E11,"N/A") -> N/A | F49: =IF(Inicial!L11="SI",Inicial!F11,"N/A") -> N/A | G49: =IF(Inicial!L11="SI",Inicial!G11,"N/A") -> N/A | H49: =IF(Inicial!L11="SI",Inicial!H11,"N/A") -> N/A | I49: =IF(Inicial!L11="SI",Inicial!I11,"N/A") -> N/A | AG49: {=IF(OR(M49:AF49="NO"),"No aceptable","Aceptable")} -> Aceptable | BD49: {=IF(OR(AK49:BC49="SI"),"Critico","No Critico")} -> No Critico
A50: =Inicial!A12 -> 0 | B50: =Inicial!B12 -> 0 | C50: =Inicial!C12 -> 0 | D50: =Inicial!D12 -> 0 | E50: =IF(Inicial!L12="SI",Inicial!E12,"N/A") -> N/A | F50: =IF(Inicial!L12="SI",Inicial!F12,"N/A") -> N/A | G50: =IF(Inicial!L12="SI",Inicial!G12,"N/A") -> N/A | H50: =IF(Inicial!L12="SI",Inicial!H12,"N/A") -> N/A | I50: =IF(Inicial!L12="SI",Inicial!I12,"N/A") -> N/A | AG50: {=IF(OR(M50:AF50="NO"),"No aceptable","Aceptable")} -> Aceptable | BD50: {=IF(OR(AK50:BC50="SI"),"Critico","No Critico")} -> No Critico
A51: =Inicial!A13 -> 0 | B51: =Inicial!B13 -> 0 | C51: =Inicial!C13 -> 0 | D51: =Inicial!D13 -> 0 | E51: =IF(Inicial!L13="SI",Inicial!E13,"N/A") -> N/A | F51: =IF(Inicial!L13="SI",Inicial!F13,"N/A") -> N/A | G51: =IF(Inicial!L13="SI",Inicial!G13,"N/A") -> N/A | H51: =IF(Inicial!L13="SI",Inicial!H13,"N/A") -> N/A | I51: =IF(Inicial!L13="SI",Inicial!I13,"N/A") -> N/A | AG51: {=IF(OR(M51:AF51="NO"),"No aceptable","Aceptable")} -> Aceptable | BD51: {=IF(OR(AK51:BC51="SI"),"Critico","No Critico")} -> No Critico
A52: =Inicial!A14 -> 0 | B52: =Inicial!B14 -> 0 | C52: =Inicial!C14 -> 0 | D52: =Inicial!D14 -> 0 | E52: =IF(Inicial!L14="SI",Inicial!E14,"N/A") -> N/A | F52: =IF(Inicial!L14="SI",Inicial!F14,"N/A") -> N/A | G52: =IF(Inicial!L14="SI",Inicial!G14,"N/A") -> N/A | H52: =IF(Inicial!L14="SI",Inicial!H14,"N/A") -> N/A | I52: =IF(Inicial!L14="SI",Inicial!I14,"N/A") -> N/A | AG52: {=IF(OR(M52:AF52="NO"),"No aceptable","Aceptable")} -> Aceptable | BD52: {=IF(OR(AK52:BC52="SI"),"Critico","No Critico")} -> No Critico
