Workbook

Sheet Menú
L5: Assessment of repetitive tasks of the upper limbs (The ART tool)
Y28: Versión 2.0 (2024)

Sheet A1
C2: Assessment of repetitive tasks of the upper limbs (The ART tool)
C4: Sección A: Frecuencia y Movimientos
C6: 1: Movimiento del brazo: Observe el movimiento del brazo y seleccione la categoria que sea más apropiada. Es posible seleccionar puntuaciones intermedias. Evalúe tanto el brazo izquierdo (I), como el brazo derecho (D).
Q13: Puntaje
F14: Los movimientos de los brazos son | H14: Infrecuente (por ejemplo: algún movimiento intermitente) | Q14: V / 0 | R14: Derecho | T14: Izquierdo
R16: Verde / 0 | T16: Verde / 0
H17: Frecuente (por ejemplo, movimiento regular con algunas pausas) | Q17: A / 3
H20: Muy frecuente (por ejemplo, movimientos casi contínuo) | Q20: R / 6
A41: Verde / 0
A42: Ambar / 3
A43: Rojo / 6

Sheet A2
C2: Assessment of repetitive tasks of the upper limbs (The ART tool)
C4: Sección A: Frecuencia y Movimientos
C6: 2: Repetición: Esto se refiere al movimiento del brazo y la mano, pero no de los dedos. Observe el movimiento del brazo y la mano y cuente el número de veces que se repite el mismo patrón de movimiento o uno similar durante un periodo de tiempo determinado (por ejemplo, 1 minuto). Evalúe tanto el brazo izquierdo (I), como el brazo derecho (D).
Q13: Puntaje
F14: El patrón de movimiento similar del brazo y la mano se repite | H14: 10 veces por minuto o menos | Q14: V / 0 | R14: Derecho | T14: Izquierdo
R16: Verde / 0 | T16: Verde / 0
H17: 11-20 veces por minuto | Q17: A / 3
H20: Más de 20 veces por minuto | Q20: R / 6
A55: Verde / 0
A56: Ambar / 3
A57: Rojo / 6

Sheet B1
C2: Assessment of repetitive tasks of the upper limbs (The ART tool)
C4: Sección B: Fuerza
C6: 1: Fuerza: Utilice la siguiente cuadrícula (Cuadro B) para determinar el nivel de fuerza ejercida con la mano y la cantidad de tiempo que se ejerce la fuerza. Es posible seleccionar puntuaciones intermedias en la cuadrícula si es apropiado. Si se ejerce más de un tipo de fuerza, seleccione la puntuación más alta. Hay dos métodos para determinar el nivel de la fuerza de la mano: A.- Pregunte al trabajador si hay alguna acción que requiera esfuerzo muscular del brazo, la mano o dedos. B.- Utilice las descripciones (cuadro A) que figura a continuación para determinar el nivel de fuerza ejercida con la mano. Nota: Si se identifican tales acciones, pedir a trabajador que describa el nivel de fuerza que implica (Ej: Fuerza ligera; moderado; fuerte; muy intenso).
D11: Cuadro A | N11: Cuadro B
D17: Fuerza Ligera | E17: No hay indicios de ningún esfuerzo particular | N17: Descripción | P17: Ligero | R17: Moderado | T17: Fuerte | V17: Muy Intenso
N20: Infrecuente | P20: V / 0 | R20: A / 1 | T20: R / 6 | V20: Cambios requeridos*
D21: Fuerza Moderada | E21: Es necesario realizar fuerza para ejercer la tarea, por ejemplo: Pellizcar o agarrar objetos con algún esfuerzo; Mover palancas o presionar botones con algo de esfuerzo; Empujar o forzar articulos con algún esfuerzo; Usar herramientas con cierto esfuerzo.
N22: Parte del tiempo (15-30%) | P22: V / 0 | R22: A / 2 | T22: R / 9 | V22: Cambios requeridos*
D24: Fuerza Fuerte | E24: La fuerza es obviamente alta, fuerte o pesada | N24: Alrededor de la mitad del tiempo (40-60%) | P24: V / 0 | R24: A / 4 | T24: R / 12 | V24: Cambios requeridos*
N26: Casi todo el tiempo (80% o más) | P26: V / 0 | R26: R / 8 | T26: Cambios requeridos* | V26: Cambios requeridos*
D27: Fuerza muy intensa | E27: La fuerza está cerca del nivel máximo que el trabajador puede aplicar
N29: * Se requieren cambios en la tarea debido a los inaceptables niveles de fuerza.
S31: Seleccionar | T31: Derecho | V31: Izquierdo
T32: Ambar / 2 | V32: Ambar / 2
A60: Verde / 0
A61: Ambar / 1
A62: Ambar / 2
A63: Ambar / 4
A64: Rojo / 8
A65: Rojo / 6
A66: Rojo / 9
A67: Rojo / 12
A68: Rojo / CR

Sheet C1
C2: Assessment of repetitive tasks of the upper limbs (The ART tool)
C4: Sección C: Posturas forzadas/mantenidas (Incomodas)
C6: 1: Postura de cabeza y cuello: Se considera que el cuello está inclinado hacia adelante (flexión) o a los lados (lateralización) o girado (torsión o rotación), si se puede observar un ángulo evidente entre el cuello y la espalda como resultado de la ejecución de la tarea.
D13: La cabeza o el cuello está: | Q13: Puntaje
I14: En una postura casi neutra (cercano a la postura neutra) | Q14: V / 0 | R14: Seleccione Puntaje
R16: Ambar / 1
I17: Inclinado hacia adelante o a los lados o girado parte del tiempo (menor al 50%) | Q17: A / 1
I20: Inclinado hacia adelante o a los lados o girado parte del tiempo (más del 50%) | Q20: R / 2
A70: Verde / 0
A71: Ambar / 1
A72: Rojo / 2

Sheet C2
C2: Assessment of repetitive tasks of the upper limbs (The ART tool)
C4: Sección C: Posturas forzadas/mantenidas (Incomodas)
C6: 2: Postura de la espalda: La postura de la espalda se considera incómoda/forzada si se observan más de 20° de torsión o rotación, inclinación hacia adelante (flexión) o a los lados (lateralización).
D13: La espalda está: | Q13: Puntaje
I14: Cercana a la postura neutral | Q14: V / 0 | R14: Seleccione Puntaje
R16: Ambar / 1
I17: Inclinada hacia adelante, a los lados o girada parte del tiempo | Q17: A / 1
I20: Inclinada hacia adelante, a los lados o girada por más de la mitad del tiempo | Q20: R / 2
A75: Verde / 0
A76: Ambar / 1
A77: Rojo / 2

Sheet C3
C2: Assessment of repetitive tasks of the upper limbs (The ART tool)
C4: Sección C: Posturas forzadas/mantenidas (Incomodas)
C6: 3: Postura del brazo: Se considera que el brazo adopta una postura incómoda si el codo se eleva a la altura del pecho y el brazo no tiene apoyo (Por ejemplo, no se apoya en un banco/escritorio de trabajo).
D13: El codo está: | Q13: Puntaje
I14: Se mantiene cerca del cuerpo o está apoyado | Q14: V / 0 | R14: Derecho | T14: Izquierdo
R16: Ambar / 2 | T16: Ambar / 2
I17: Está elevado y lejos del cuerpo parte del tiempo | Q17: A / 2
I20: Está elevado y lejos del cuerpo más de la mitad del tiempo | Q20: R / 4
A80: Verde / 0
A81: Ambar / 2
A82: Rojo / 4

Sheet C4
C2: Assessment of repetitive tasks of the upper limbs (The ART tool)
C4: Sección C: Posturas forzadas/mantenidas (Incomodas)
C6: 4: Postura de la muñeca: Se considera que la muñeca está en flexión/extensión o desviada (si se puede observar un ángulo evidente en la muñeca)
D13: La muñeca está: | Q13: Puntaje
I14: Casi en posición neutra (casi recta) | Q14: V / 0 | R14: Derecho | T14: Izquierdo
R16: Ambar / 1 | T16: Ambar / 1
I17: Está en flexión/extensión o desviada (lateralización) parte del tiempo | Q17: A / 1
I20: Está en flexión/extensión o desviada (lateralización) más de la mitad del tiempo | Q20: R / 2
A85: Verde / 0
A86: Ambar / 1
A87: Rojo / 2

Sheet C5
C2: Assessment of repetitive tasks of the upper limbs (The ART tool)
C4: Sección C: Posturas forzadas/mantenidas (Incomodas)
C6: 5: Agarre de la mano: Las manos o los dedos sostienen objetos con el siguiente agarre
D13: La muñeca está: | Q13: Puntaje
I14: Agarre fuerte/firme o ausencia de incomodidaes | Q14: V / 0 | R14: Derecho | T14: Izquierdo
R16: Verde / 0 | T16: Verde / 0
I17: Realiza pinza o agarre amplio con los dedos durante parte del tiempo | Q17: A / 1
I20: Realiza pinza o agarre amplio con los dedos más de la mitad del tiempo | Q20: R / 2
A90: Verde / 0
A91: Ambar / 1
A92: Rojo / 2

Sheet D1
C2: Assessment of repetitive tasks of the upper limbs (The ART tool)
C4: Sección D: Factores Adicionales
C6: 1: Pausas: Determine la cantidad máxima de tiempo que los trabajadores realizan la tarea repetitiva sin descanso (interrupciones). Las pausas son cambios o pausas significativas (Por ejemplo, de al menos 5 a 10 minutos) para actividades realizadas por los brazos o las manos. Incluyen los descansos estructurados como los descansos para comer. Tambien incluyen los tiempos dedicados a realizar otras tareas que no implican movimientos repetitivos similares a nivel de brazos (Por ejemplo, una tarea de inspección visual).
E11: El trabajador realiza la tarea de forma continua, sin descanso, por: | G11: Menos de una hora, o hay frecuentes descansos cortos (Por ejemplo, de al menos 10 segundos) cada pocos minutos durante todo el periodo de trabajo | Q11: V / 0
G14: 1 hora a menos de 2 horas | Q14: A / 2 | R14: Seleccionar puntaje
R16: Verde / 0
G17: 2 horas a menos de 3 horas | Q17: A / 4
G20: 3 horas a menos de 4 horas | Q20: R / 6
G23: 4 horas o más | Q23: R / 8
A95: Verde / 0
A96: Ambar / 2
A97: Ambar / 4
A98: Rojo / 6
A99: Rojo / 8

Sheet D2
C2: Assessment of repetitive tasks of the upper limbs (The ART tool)
C4: Sección D: Factores Adicionales
C6: 2: Ritmo de trabajo: Pregunte a los trabajadores sobre cualquier dificultad que puedan tener para mantenerse al día con el trabajo. Seleccione la categoria más apropiada. Si la puntuación es ambar o roja, pida más información sobre este aspecto del trabajo.
G11: No es dificil mantenerse al día con el trabajo | Q11: V / 0 | R11: Seleccionar puntaje
R13: Verde / 0
G15: A veces es dificil mantenerse al día con el trabajo | Q15: A / 1
G19: A menudo es dificil mantenerse al día con el trabajo | Q19: R / 2
A105: Verde / 0
A106: Ambar / 1
A107: Rojo / 2

Sheet D3
C2: Assessment of repetitive tasks of the upper limbs (The ART tool)
C4: Sección D: Factores Adicionales
C6: 3: Otros Factores: Identificar cualquier otro factor que esté presente en la tarea (evalúe brazo derecho y brazo izquierdo), Por ejemplo:
D11: Otros Factores
D12: Los guantes afectan al agarre y hacen más dificil realizar la manipulación | S12: Puntaje
L13: No hay factores presentes | S13: V / 0 | T13: Derecho | V13: Izquierdo
D14: Una Herramienta (Por ejemplo un martillo) se utiliza para golpear dos o más veces por minuto
T15: Verde / 0 | V15: Verde / 0
D16: La mano se utiliza como herramientas (por ejemplo, martillar) y se golpea diez o más veces por hora | L16: Un factor está presente | S16: A / 1
D18: La herramienta, el espacio de trabajo o estación de trabajo causa compresión sobre la piel
L19: Dos o más factores están presentes | S19: R / 2
D20: La herramienta o la pieza de trabajo causan molestias o fatiga/calambres en la mano o dedos
D22: La mano/el brazo está expuesto a vibración
D24: La tarea requiere movimientos finos y precisos de la mano o los dedos;
D26: Los trabajadores están expuesto al frío o a corrientes de aire o agarran herramientas frías
D29: Los niveles de iluminación son inadecuados
A110: Verde / 0
A111: Ambar / 1
A112: Rojo / 2

Sheet D4
C2: Assessment of repetitive tasks of the upper limbs (The ART tool)
C4: Sección D: Factores Adicionales
C6: 4: Duración: Determine la cantidad de tiempo que un trabajador realiza la tarea repetitiva en un día o turno representativo (típico), excluyendo los descansos. Seleccione la categoría más apropiada.
I12: Duración de la tarea de un trabajador
I14: Menos de 2 horas | N14: Multiplicar por 0,5 | Q14: Seleccionar
I16: 2 Horas a menos de 4 Horas | N16: Multiplicar por 0,75 | Q16: 0.5
I18: 4 Horas a 8 Horas | N18: Multiplicar por 1
I20: Más de 8 Horas | N20: Multiplicar por 1,5
A115: 0.5
A116: 0.75
A117: 1
A118: 1.5

Sheet D5
C2: Assessment of repetitive tasks of the upper limbs (The ART tool)
C4: Sección D: Factores Adicionales
C6: 5: Factores Psicosociales: Los factores psicosociales no reciben puntuación, sin embargo, deben ser considerados a traves de la discusión con los trabajadores, y si están presentes en el lugar de trabajo, se registran en la hoja de puntuación.
G11: Factores Psicosociales | I11: Poco Control sobre cómo realiza el trabajo | R11: No
I13: Incentivos para saltarse los descansos (pausas) o terminar antes de tiempo | R13: No
I15: Trabajo monótono | R15: Si
I17: Altos niveles de atención y concentración | R17: Si
I19: Presión frecuente para cumplir plazos de entrega | R19: No
I21: Falta de apoyo de supervisores o compañeros de trabajo | R21: No
I23: Demanda de trabajo excesiva | R23: No
I25: Entrenamiento o capacitación insuficiente para realizar el trabajo con éxito | R25: No
A120: Si
A121: No

Sheet HojaResultado
C2: Assessment of repetitive tasks of the upper limbs (The ART tool)
D6: Hoja de Descripción de Tarea | O6: Hoja de Puntaje Método Art Tool
D8: Nombre Evaluador | F8: MARIA JOSE SEPULVEDA DURAN | I8: Fecha | O8: Factor de riesgo | T8: Brazo Izquierdo | V8: Brazo Derecho
D9: Empresa | F9: AGROSUPER PLANTA SAN VICENTE | I9: Ubicación | K9: SAN VICENTE | T9: Color | U9: Puntaje | V9: Color | W9: Puntaje
D10: Area de Trabajo | F10: Faenación | I10: Nombre Puesto Trabajo | K10: Eviscerado | O10: A1 Movimientos del brazo | T10: =U10 -> Verde / 0 | U10: ='A1'!T16 -> Verde / 0 | V10: =W10 -> Verde / 0 | W10: ='A1'!R16 -> Verde / 0
D11: Nombre Tarea | F11: Transferidor | I11: Duración Tarea | K11: 50 MIN | O11: A2 Repetición | T11: =U11 -> Verde / 0 | U11: ='A2'!T16 -> Verde / 0 | V11: =W11 -> Verde / 0 | W11: ='A2'!R16 -> Verde / 0
D12: Descripción de la Tarea | O12: B1 Fuerza | T12: =U12 -> Ambar / 2 | U12: ='B1'!V32 -> Ambar / 2 | V12: =W12 -> Ambar / 2 | W12: ='B1'!T32 -> Ambar / 2
D13: Recuelga aves de forma bimanual que caen del transferidor de líneas y la que tienen solo una pata colgada. Ademas de retirar aves en mal estado para depositarlo en bandeja y luego llevar a meson de expurgo | O13: C1 Postura Cabeza/Cuello | T13: =U13 -> Ambar / 1 | U13: ='C1'!R16 -> Ambar / 1 | V13: =W13 -> Ambar / 1 | W13: ='C1'!R16 -> Ambar / 1
O14: C2 Postura Espalda | T14: =U14 -> Ambar / 1 | U14: ='C2'!R16 -> Ambar / 1 | V14: =W14 -> Ambar / 1 | W14: ='C2'!R16 -> Ambar / 1
O15: C3 Postura de Brazo | T15: =U15 -> Ambar / 2 | U15: ='C3'!T16 -> Ambar / 2 | V15: =W15 -> Ambar / 2 | W15: ='C3'!R16 -> Ambar / 2
O16: C4 Postura de Muñeca | T16: =U16 -> Ambar / 1 | U16: ='C4'!T16 -> Ambar / 1 | V16: =W16 -> Ambar / 1 | W16: ='C4'!R16 -> Ambar / 1
O17: C5 Agarre mano/dedos | T17: =U17 -> Verde / 0 | U17: ='C5'!T16 -> Verde / 0 | V17: =W17 -> Verde / 0 | W17: ='C5'!R16 -> Verde / 0
O18: D1 Pausas | T18: =U18 -> Verde / 0 | U18: ='D1'!R16 -> Verde / 0 | V18: =W18 -> Verde / 0 | W18: ='D1'!R16 -> Verde / 0
O19: D2 Ritmo de trabajo | T19: =U19 -> Verde / 0 | U19: ='D2'!R13 -> Verde / 0 | V19: =W19 -> Verde / 0 | W19: ='D2'!R13 -> Verde / 0
D20: ¿Cuál es el peso de los objetos manipulados? (Si los pesos superan los 8 kilogramos y requieren de manejo manual de cargas, considere usar MAC) | J20: AVE 2,9 KILOS | O20: D3 Otros Factores | T20: =U20 -> Verde / 0 | U20: ='D3'!V15 -> Verde / 0 | V20: =W20 -> Verde / 0 | W20: ='D3'!T15 -> Verde / 0
O21: Puntaje de la tarea | T21: Brazo Izquierdo | U21: =IFERROR(SUM(RIGHT(U10,1),RIGHT(U11,1),RIGHT(U12,1),RIGHT(U13,1),RIGHT(U14,1),RIGHT(U15,1),RIGHT(U16,1),RIGHT(U17,1),RIGHT(U18,1),RIGHT(U19,1),RIGHT(U20,1)),"Peso de Carga Inaceptable") -> 7 | V21: Brazo Derecho | W21: =IFERROR(SUM(RIGHT(W10,1),RIGHT(W11,1),RIGHT(W12,1),RIGHT(W13,1),RIGHT(W14,1),RIGHT(W15,1),RIGHT(W16,1),RIGHT(W17,1),RIGHT(W18,1),RIGHT(W19,1),RIGHT(W20,1)),"Peso de Carga Inaceptable") -> 7
D22: ¿Qué lado del cuerpo está mayormente involucrado? (Marque con X) | G22: Izquierdo | I22: Derecho | K22: Ambos | O22: D4 Multiplicador de la duración | U22: ='D4'!Q16 -> 0.5 | W22: ='D4'!Q16 -> 0.5
L23: X | O23: Puntaje de Exposición Total | U23: =U21*U22 -> 3.5 | W23: =W21*W22 -> 3.5
D24: ¿Qué herramienta manual es utilizada? | J24: NO UTILIZA | O24: Mantener las condiciones de la tarea. Sugerencia de incorporación de otro colaborador a la tarea en contingencias para evitar posturas forzadas de espalda, brazos y muñecas. Agregar pausas compensatorias.
D25: Datos de producción (si está disponible), unidades por jornada, hora | J25: 13.500 AVES POR HORA
D26: ¿Cuan a menudo se repite la tarea?, cada segundo, minutos, horas | J26: 1 VEZ POR TURNO
D27: ¿Cuánto tiempo está el trabajador realizando la tarea? | J27: 50 MINUTOS | O27: Puntaje de Exposición | S27: Nivel de Exposición Propuesto
D28: ¿Con qué frecuencia realiza la tarea? (ej.: diariamente, semanalmente, etc. | J28: DIARIAMENTE | O28: 0 a 11 puntos | S28: Bajo | T28: Considere circunstacias individuales
D29: ¿Con qué frecuencia realiza la tarea en la organización? (diariamente, etc.) | J29: DIARIAMENTE | O29: 12 a 21 puntos | S29: Medio | T29: Se requiere investigación adicional
D30: ¿Los trabajadores rotan a otras tareas? Si es así, ¿qué tareas? | J30: SI , POR 14 TAREAS MÁS | O30: 22 o más puntos | S30: Alto | T30: Se requiere urgentemente investigación adicional
D32: Marca los descansos en el turno según como se distribuyen en la siguiente línea de tiempo (cuadro)
D33: Actividad | E33: PO | G33: PNO | H33: PO | I33: PC | K33: PNO | L33: PO | M33: TPIS
D35: Tiempo | E35: 5 | G35: 20 | H35: 3 | I35: 45 | K35: 20 | L35: 3 | M35: 30
A50: Verde / 0
A51: Ambar / 3
A52: Rojo / 6
A55: Verde / 0
A56: Ambar / 3
A57: Rojo / 6
A60: Verde / 0
A61: Ambar / 1
A62: Ambar / 2
A63: Ambar / 4
A64: Rojo / 8
A65: Rojo / 6
...

Sheet MatrizArtTool
G5: Matriz Método Assessment of repetitive tasks of the upper limbs (The ART tool)
B6: Nombre Evaluador | C6: Fecha | D6: Area de Trabajo | E6: Puesto de trabajo | F6: Tarea | G6: Duración de la tarea | H6: Sección A1 Derecha | I6: Sección A2 Derecha | J6: Sección B1 Derecha | K6: Sección C1 Derecha | L6: Sección C2 Derecha | M6: Sección C3 Derecha | N6: Sección C4 Derecha | O6: Sección C5 Derecha | P6: Sección D1 Derecha | Q6: Sección D2 Derecha | R6: Sección D3 Derecha | S6: Puntaje | T6: Sección D4 Derecha | U6: Puntaje Total Derecha | V6: Sección A1 Izquierda | W6: Sección A2 Izquierda | X6: Sección B1 Izquierda | Y6: Sección C1 Izquierda | Z6: Sección C2 Izquierda | AA6: Sección C3 Izquierda | AB6: Sección C4 Izquierda | AC6: Sección C5 Izquierda | AD6: Sección D1 Izquierda | AE6: Sección D2 Izquierda | AF6: Sección D3 Izquierda | AG6: Puntaje | AH6: Sección D4 Izquierda | AI6: Puntaje Total Izquierda | AJ6: Medida de Control | AK6: Inicio Implementación | AL6: Puntaje Re-evaluación Derecho | AM6: Puntaje Re-evaluación Izquierdo

Sheet SobreArtTool
B2: ART TOOL (Assessment of repetitive tasks of the upper limbs)
B4: La herramienta de evaluación de tareas repetitivas ART TOOL está diseñada para ayudar a evaluar el riesgo de tareas que requieren movimientos repetitivos de las extremidades superiores (brazos y manos). Ayuda a evaluar algunos de los factores de riesgos más comunes en el trabajo (por ejemplo movimientos repetitivo que contribuyen al desarrollo de trastornos de las extremidades superiores (TME-EESS).
B7: Las tareas repetitivas se componen de una secuencia de acciones de las extremidades superiores, de corta duración, que se repiten una y otra vez, y que casi siempre son iguales (por ejemplo, coser un trozo de tela, fabricar una pieza, empaquetar un artículo, entre otros).
B9: ART TOOL es adecuado para tareas que:
B10: *Implican acciones de las extremidades superiores; Que se repita cada pocos minutos, o incluso con más frecuencia; Que ocurren durante al menos 1 a 2 horas por día o turno.
B11: Se utiliza tipicamente en tareas de puestos de trabajo que desarrollan por ejemplo ensamblaje, producción, procesamiento, empaque, embalaje y clasificación, así como trabajos que impliquen el uso regular de la mano con instrumentos.
B15: La evaluación se divide en cuatro etapas:
B16: Etapa A: Frecuencia y repetición de movimientos
B17: Etapa B: Fuerza
B18: Etapa C: Posturas Incómodas
B19: Etapa D: Factores Adicionales
B21: Para cada etapa, debe seguir el diagrama de flujo y/o la guía de evaluación para determinar el nivel de riesgo para cada factor de riesgo. Los niveles de riesgo se clasifican según la siguiente tabla:
C24: Verde | E24: Nivel de riesgo bajo
C25: Ambar | E25: Nivel de riesgo medio, debe examinar la tarea detalladamente
C26: Rojo | E26: Alto nivel de riesgo, son necesarias acciones inmediatas
C33: Diagrama de Flujo Art-Tool
B61: Más información sobre ART, incluida la formación en línea sobre cómo utilizar la herramienta, se puede encontrar en www.hse.gov.uk/msd/uld/art.
