Workbook

Sheet Portada
A1: 1. ANTECEDENTES DE LA EMPRESA | F1: N° de Puestos | G1: Evaluados | H1: Pendientes
A2: Razón Social | B2: FAENADORA SAN VICENTE LTDA | C2: RUT Empresa | D2: 78483600-2 | F2: =COUNTIF(Datos!B:B,"Faenación") -> 61 | G2: =COUNTIF(Datos!T:T,"SI") -> 59 | H2: =COUNTIF(Datos!T:T,"NO") -> 2
A3: Actividad Económica | B3: Explotación de mataderos de aves y de otros tipos de animales n.c.p. | C3: Código CIIU
A4: Dirección | B4: CARRETERA H 66 G KM 19,2 | C4: Comuna | D4: SAN VICENTE
A5: Nombre Representante Legal | B5: SANDRA CALDERON
A6: Organismo administrador al que está adherido | B6: INSTITUTO SALUD DEL TRABAJADOR | C6: Fecha inicio | D6: 45440
A7: 2.- CENTRO DE TRABAJO O LUGAR DE TRABAJO
A8: Nombre del centro de trabajo | B8: Faenación | C8: Nº de trabajadores centro de trabajo
A9: Dirección | B9: CARRETERA H 66 G KM 19,2 | C9: Hombres | D9: 1515
A10: Comuna | B10: SAN VICENTE | C10: Mujeres | D10: 497
A11: 3.- RESPONSABLE IMPLEMENTACIÓN PROTOCOLO
A12: Nombre responsable | B12: CONSTANZA ANDREA MUÑOZ CARO | C12: Teléfono | D12: 722312747
A13: Cargo | B13: SUPERVISORA DE ACTIVIDADES ERGONOMICAS
A14: Correo electrónico | B14: CAMUNOZC@AGROSUPER.COM

Sheet Datos
A1: N° | B1: Área de trabajo | C1: Sección | D1: Tareas del puesto de trabajo | E1: Descripción de la tarea | F1: Horario de funcionamiento | G1: Horas extras POR DIA | H1: Horas extras POR SEMANA | I1: N° Trabajadores Expuestos HOMBRE | J1: N° Trabajadores Expuestos MUJER | K1: Tipo de contrato | L1: Tipo de remuneración | M1: Duración (min) | N1: Pausas de Trabajo | O1: Rotación de tarea | P1: Equipos y Herramienta | Q1: Características de los ambientes y espacios de trabajo (Espacios, barreras arquitectónicas, flujo de tránsito) | R1: Características y disposición espacial del puesto de trabajo (Ubicación de los elementos de trabajo, disposición física del espacio de trabajo) | S1: Características y herramientas utilizadas (Descripción de equipos, herramientas utilizadas, herramientas vibrantes, uso de EPP) | T1: Evaluacion SI/NO | U1: Evaluacion a solicitar
A2: 1 | B2: Faenación | C2: Colgado | D2: Colgado de aves | E2: Tomar de ave de forma Bimanual y colgarla de las extremidades posteriores en línea aéreas de proceso | F2: 03:35 a 11:50 - 11:50 a 21:10 | G2: N/A | H2: 2 | I2: 36 | J2: 0 | K2: indefinido | L2: Variable | M2: 240 min | N2: Pausa preparatoria | O2: SI | P2: N/A | Q2: Flujo de transito demarcado, cuenta con plataformas regulables para la altura al colgar el ave, cuenta con tarimas que forman pasillos para su transito | R2: Espacio fisico bajo techo, mesa a la altura de la cadera con tarima para adaptabilidad a la altura de la mesa de trabajo | S2: Usan EPP tales como Calzado de seguridad, Fonos, guantes de nitrilo modelo solvex. | T2: SI
A3: 2 | B3: Faenación | C3: Colgado | D3: Revision de contenedores | E3: Verificar de forma visual que en contenedores no queden aves, si hay aves deben tomarlas con ambas manos y retirarlas para luego depositarlas en linea o batea | F3: 03:35 a 11:50 - 11:50 a 21:11 | G3: N/A | H3: 2 | I3: 36 | J3: 0 | K3: Indefinido | L3: Variable | M3: 60 Min | N3: Pausa preparatoria | O3: SI | P3: N/A | Q3: Flujo de transito demarcado, cuenta con plataformas regulables para la altura al colgar el ave, cuenta con tarimas que forman pasillos para su transito, cuenta con piso para poder sentarse | R3: Espacio fisico bajo techo, piso para utilizar mientras llega el contenedor | S3: Usan EPP tales como Calzado de seguridad, Fonos, guantes de nitrilo modelo solvex. | T3: SI
A4: 3 | B4: Faenación | C4: Colgado | D4: Extracción de pollo mortecino | E4: Verificar de forma visual aves muertas antes de entrar a CO2 para retirar mediante un herramienta (pinza) y depositar en batea | F4: 03:35 a 11:50 - 11:50 a 21:12 | G4: N/A | H4: 2 | I4: 36 | J4: 0 | K4: Indefinido | L4: Variable | M4: 60 min | N4: Pausa preparatoria | O4: SI | P4: Pinza | Q4: Flujo de transito demarcado, cuenta con plataformas regulables para la altura al colgar el ave, cuenta con tarimas que forman pasillos para su transito | R4: Espacio fisico bajo techo, mesa a la altura de la cadera con tarima para adaptabilidad a la altura de la mesa de trabajo | S4: Usan EPP tales como Calzado de seguridad, Fonos, guantes de nitrilo modelo solvex.Utilizan herramienta para el retiro del ave una pinza que tiene 2 enganches para tomar el ave. | T4: SI
A5: 4 | B5: Faenación | C5: Colgado | D5: Gruero | E5: Descarga y carga de pallet de jabas con aves desde camión a plataforma y viceversa. Revisión visual del sistema hidráulico y las condiciones de la maquinaria. Carga de combustible. | F5: 03:35 a 11:50 - 11:50 a 21:13 | G5: N/A | H5: 2 | I5: 36 | J5: 0 | K5: Indefinido | L5: Variable | M5: 430 min | N5: Pausa preparatoria | O5: SI | P5: N/A | Q5: Flujo de transito demarcado, cuenta con plataformas regulables para la altura al colgar el ave, cuenta con tarimas que forman pasillos para su transito | S5: Usan EPP tales como Calzado de seguridad, Fonos y casco. Usan equipo rodante grua orquilla | T5: NO
A6: 5 | B6: Faenación | C6: Colgado | D6: Jefe de línea | E6: Encargado de coordinar productivas y personal dentro de las lineas | F6: 03:35 a 11:50 - 11:50 a 21:14 | G6: N/A | H6: 2 | I6: 36 | J6: 0 | K6: Indefinido | L6: Variable | M6: 430 Min | N6: Pausa preparatoria | O6: SI | P6: N/A | Q6: Flujo de transito demarcado, cuenta con plataformas regulables para la altura al colgar el ave, cuenta con tarimas que forman pasillos para su transito | R6: Espacio fisico bajo techo sin exposicion a radiacion uv | S6: Usa EPP tales como calzado de seguridad, casco y fonos, ademas usa dentro de sus labores radio de comunicación interna. | T6: SI
A7: 6 | B7: Faenación | C7: Colgado | D7: Secretario | E7: Colaborador ingresa datos de guia de despacho en computador | F7: 03:35 a 11:50 - 11:50 a 21:15 | G7: N/A | H7: 2 | I7: 36 | J7: 0 | K7: Indefinido | L7: Variable | M7: 430 Min | N7: Pausa preparatoria | O7: SI | P7: Computador | Q7: Flujo de transito demarcado, cuenta con plataformas regulables para la altura al colgar el ave, cuenta con tarimas que forman pasillos para su transito | R7: Espacio fisico bajo techo sin exposicion a radiacion uv | S7: Usa EPP tales como calzado de seguridad, casco y fonos, ademas usa dentro de sus labores radio de comunicación interna. | T7: SI
A8: 7 | B8: Faenación | C8: Colgado | D8: Recepcion de guia | E8: Acercarse a Camion de aves y solicitar guia de despacho, tomarla y llevarla a oficina de colgado, remplaza a colabores dentro de la linea | F8: 03:35 a 11:50 - 11:50 a 21:16 | G8: N/A | H8: 2 | I8: 36 | J8: 0 | K8: Indefinido | L8: Variable | M8: 430 min | N8: Pausa preparatoria | O8: SI | P8: N/A | Q8: Flujo de transito demarcado, cuenta con plataformas regulables para la altura al colgar el ave, cuenta con tarimas que forman pasillos para su transito | R8: Espacio fisico bajo techo sin exposicion a radiacion uv | S8: Usa EPP tales como calzado de seguridad, casco y fonos chaleco reflectante. | T8: SI
A9: 8 | B9: Faenación | C9: Colgado | D9: Encargado de PC | E9: Realiza regulación del funcionamiento y frecuencia de las diferentes líneas y máquinas del área que le corresponda Realiza registros y controles del proceso. Ordena Entrada y Salida de Camiones del Galpón de Espera y Galpón de Descarga Reemplaza a Colaboradores para ir al Baño | F9: 03:35 a 11:50 - 11:50 a 21:17 | G9: N/A | H9: 2 | I9: 36 | J9: 0 | K9: Indefinido | L9: Variable | M9: 430 Min | N9: Pausa preparatoria | O9: SI | P9: Computador | Q9: Flujo de transito demarcado, cuenta con plataformas regulables para la altura al colgar el ave, cuenta con tarimas que forman pasillos para su transito | R9: Espacio fisico bajo techo sin exposicion a radiacion uv | S9: Usa EPP tales como calzado de seguridad, casco, fonos y guantes anticorte, ademas usa dentro de sus labores radio de comunicación interna. | T9: SI
A10: 9 | B10: Faenación | C10: Sacrificio | D10: Pollo Chico | E10: Colaborados deposita pollos reprocesados para ser reprocesados. | F10: 03:30 - 11:50 / 11:50 - 21:15 | G10: N/A | H10: 2 | I10: 8 | J10: 2 | K10: Indefinido | L10: Variable | M10: 50 Min | N10: Pausa preparatoria | O10: SI | P10: Cuchillo - Rapid Still | Q10: Flujo de transito demarcado, sin obstaculos. | R10: Mesa a la altura de la cadera para realizar corte sobre esta, espacio con temperatura ambiente y sin exposicion a Rayos ultravioleta | S10: Usa EPP tales como Fonos, calzado de seguridad, Guantes anticorte. | T10: SI
A11: 10 | B11: Faenación | C11: Sacrificio | D11: Desgollador | E11: Observa aves que pasan por linea repasando cortes de carótidas fallidos por maquinaria. Afila Cuchillos con Rapid Still | F11: 03:30 - 11:50 / 11:50 - 21:15 | G11: N/A | H11: 2 | I11: 8 | J11: 2 | K11: Indefinido | L11: Variable | M11: 120 Min | N11: Pausa preparatoria | O11: SI | P11: Cuchillo - Rapid Still | Q11: Flujo de transito demarcado, transita sobre tarimas para porder pasar de un sector a otro, pasa por abajo de lineas aereas | R11: Cuenta con silla parado sentado para realizar la labor, ademas cuenta con tarima para brindar altura a la mesa de trabajo si es necesario, sin exposicion a rayos ultravioleta | S11: Usa EPP tales como Fonos, Guantes anticorte y calzado de seguridad, utiliza como herramienta de corte un cuchillo y un rapid Still | T11: SI
A12: 11 | B12: Faenación | C12: Sacrificio | D12: Repase de pluma | E12: Realiza inspección visual y retiro de plumas de aves en la línea aérea. Recuelga ave que viene de una pata.Apoya en recolgado de aves caídas y reprocesadas | F12: 03:30 - 11:50 / 11:50 - 21:15 | G12: N/A | H12: 2 | I12: 8 | J12: 2 | K12: Indefinido | L12: Variable | M12: 120 Min | N12: Pausa preparatoria | O12: SI | P12: N/A | Q12: Flujo de transito demarcado, sin obstaculos. | R12: Cuenta con linea aerea a la altura de la cabeza, trabajao sobre tarima que aisla humedad, y bajo techo sin exposicn a radiacion uv | S12: Usa EPP tales como Fonos, calzado de seguridad, | T12: SI
A13: 12 | B13: Faenación | C13: Eviscerado | D13: Maquinista sacrificio | E13: Realiza regulación del funcionamiento y frecuencia de las diferentes líneas y máquinas del área que le corresponda | F13: 03:30 - 11:50 / 11:50 - 21:15 | G13: N/A | H13: 2 | I13: 87 | J13: 28 | K13: Indefinido | L13: Variable | M13: 486 Min | N13: Pausa preparatoria | O13: SI | P13: Maquina critica | Q13: Flujo de transito demarcado, sin obstaculos. | S13: Usa EPP tales como Fonos, calzado de seguridad, | T13: SI
A14: 13 | B14: Faenación | C14: Eviscerado | D14: Maquinista eviscerado | E14: Realiza regulación del funcionamiento y frecuencia de las diferentes líneas y máquinas del área que le corresponda.Realiza registros y controles del proceso. | F14: 03:30 - 11:50 / 11:50 - 21:15 | G14: N/A | H14: 2 | I14: 87 | J14: 28 | K14: Indefinido | L14: Variable | M14: 486 Min | N14: Pausa preparatoria | O14: SI | P14: Maquina critica | Q14: Flujo de transito demarcado, sin obstaculos. | R14: Sin mesa de trabajo. | S14: Usa EPP tales como Fonos, calzado de seguridad, | T14: SI
A15: 14 | B15: Faenación | C15: Eviscerado | D15: Transferidor | E15: Recuelga aves de forma bimanual que caen del transferidor de líneas y la que tienen solo una pata colgada. Ademas de retirar aves en mal estado para depositarlo en bandeja y luego llevar a meson de expurgo | F15: 03:30 - 11:50 / 11:50 - 21:15 | G15: N/A | H15: 2 | I15: 87 | J15: 28 | K15: Indefinido | L15: Variable | M15: 50 Min | N15: Pausa preparatoria | O15: SI | P15: N/A | Q15: Flujo de transito demarcado, sin obstaculos. | R15: Linea a la altura de la cadera, bajo techo sin exposiicion a radiacion uv. | S15: Usa EPP tales como Fonos, calzado de seguridad, | T15: SI
A16: 15 | B16: Faenación | C16: Eviscerado | D16: Expurgo Visceras | E16: Realiza Expurgo profundo. Extrae mediante corte con cuchillo las alteraciones y patologias de las Aves no aptas para el cosumo humano. | F16: 03:30 - 11:50 / 11:50 - 21:15 | G16: N/A | H16: 2 | I16: 87 | J16: 28 | K16: Indefinido | L16: Variable | M16: 50 Min | N16: Pausa preparatoria | O16: SI | P16: Cuchillo - Rapid Still | Q16: Flujo de transito demarcado, sin obstaculos. | R16: Linea a la altura de la cadera, bajo techo sin exposiicion a radiacion uv. | S16: Usa EPP tales como Fonos, Guantes anticorte y calzado de seguridad, utiliza como herramienta de corte un cuchillo y un rapid Still | T16: SI
A17: 16 | B17: Faenación | C17: Eviscerado | D17: Repaso de contre | E17: Repasa contres por rodillos de máquina SEMIL. Extraccion de cuticula | F17: 03:30 - 11:50 / 11:50 - 21:15 | G17: N/A | H17: 2 | I17: 87 | J17: 28 | K17: Indefinido | L17: Variable | M17: 50 Min | N17: Pausa preparatoria | O17: SI | P17: Maquina peladora de contres | Q17: Flujo de transito demarcado, sin obstaculos. | R17: Linea a la altura de la cadera, bajo techo sin exposiicion a radiacion uv, mesa de trabajo a la cadera | S17: Usa EPP tales como Fonos, Guantes anticorte y calzado de seguridad | T17: SI
A18: 17 | B18: Faenación | C18: Eviscerado | D18: Panas | E18: Se realiza inspección visual, selección limpieza y segragación productos. Se extraen productos adicionales a pana (bilis-corazon) | F18: 03:30 - 11:50 / 11:50 - 21:15 | G18: N/A | H18: 2 | I18: 87 | J18: 28 | K18: Indefinido | L18: Variable | M18: 50 Min | N18: Pausa preparatoria | O18: SI | P18: N/A | Q18: Puesto de trabajo demarcado, y con flujo libre acceso | R18: Mesa a ala altura adecuada para realizar la labor, plano de trabajo liso, sin exposicion a radiacion uv | S18: Usa EPP tales como Fonos, Guantes y calzado de seguridad | T18: SI
A19: 18 | B19: Faenación | C19: Eviscerado | D19: Expurgo Inscision | E19: Supervision de carcasa para verificar calidad del producto. | F19: 03:30 - 11:50 / 11:50 - 21:15 | G19: N/A | H19: 2 | I19: 87 | J19: 28 | K19: Indefinido | L19: Variable | M19: 50 Min | N19: Pausa preparatoria | O19: SI | P19: Cuchillo - Rapid Still | Q19: Flujo de transito demarcado, sin obstaculos. | R19: Linea a la altura de la cadera, bajo techo sin exposiicion a radiacion uv. | S19: Usa EPP tales como Fonos, Guantes anticorte y calzado de seguridad, utiliza como herramienta de corte un cuchillo y un rapid Still | T19: SI
A20: 19 | B20: Faenación | C20: Eviscerado | D20: Lavado/ Aspirado | E20: Recuperacion de peritonitis. Lavado y aspirado pollo para reproceso. | F20: 03:30 - 11:50 / 11:50 - 21:15 | G20: N/A | H20: 2 | I20: 87 | J20: 28 | K20: Indefinido | L20: Variable | M20: 50 Min | N20: Pausa preparatoria | O20: SI | P20: Aspiradora | Q20: Puesto de trabajo demarcado, con flujo libre de acceso | R20: Mesa de trabajo y aspiradora a la altura de la cadera | S20: Usa EPP tales como Fonos, Guantes y calzado de seguridad | T20: SI
A21: 20 | B21: Faenación | C21: Eviscerado | D21: Repase de visceras | E21: Realiza inspección visual a las carcasas de aves para detectar si tienen restos de vísceras. Descuelga ave de canal y cuelga en gancho amarillo para reproceso | F21: 03:30 - 11:50 / 11:50 - 21:15 | G21: N/A | H21: 2 | I21: 87 | J21: 28 | K21: Indefinido | L21: Variable | M21: 50 Min | N21: Pausa preparatoria | O21: SI | P21: N/A | Q21: Flujo de transito demarcado, al salir del PT debe agacharse | R21: Linea aerea que pasa frente a su nariz | S21: Usa EPP tales como Fonos, Calzado de segurida y gafas | T21: SI
A22: 21 | B22: Faenación | C22: Eviscerado | D22: Recolgado | E22: Realiza un recolgado de las aves expurgadas | F22: 03:30 - 11:50 / 11:50 - 21:15 | G22: N/A | H22: 2 | I22: 87 | J22: 28 | K22: Indefinido | L22: Variable | M22: 60 Min | N22: Pausa preparatoria | O22: SI | P22: N/A | Q22: Puesto de trabajo demarcado, con flujo libre de acceso | R22: Mesa de trabajo de forma frontal con tolva para contencion de aves | S22: Usa EPP tales como fonos, calzado de seguridad | T22: SI
A23: 22 | B23: Faenación | C23: Eviscerado | D23: Expurgo de Ala | E23: Retirar toda Ala que presenta alteracion y asi reprocesar pollo. | F23: 03:30 - 11:50 / 11:50 - 21:15 | G23: N/A | H23: 2 | I23: 87 | J23: 28 | K23: Indefinido | L23: Variable | M23: 50 Min | N23: Pausa preparatoria | O23: SI | P23: Cuchillo - Rapid Still | Q23: Puesto de trabajo sobre tarima con demarcacion en color amarillo | R23: Puesto de trabajo sobre tarima sin mesa de trabajo. | S23: Uso de EPP tales como guantes anticorte, calzado de seguridad, gafas | T23: SI
A24: 23 | B24: Faenación | C24: Eviscerado | D24: Punto de inspeccion | E24: Descuelga de la línea aves marcadas por técnicos del SAG . Cuelga aves marcadas por técnicos del SAG en línea de reproceso | F24: 03:30 - 11:50 / 11:50 - 21:15 | G24: N/A | H24: 2 | I24: 87 | J24: 28 | K24: Indefinido | L24: Variable | M24: 100 min | N24: Pausa preparatoria | O24: SI | P24: N/A | Q24: Puesto de trabajado lateral a linea aerea con demarcacion de pisos, silla parado sentado | R24: Sin mesa de trabajo linea aerea a la altura del hombro | S24: Uso de EPP tales como guantes anticorte, calzado de seguridad, gafas | T24: SI
A25: 24 | B25: Faenación | C25: Eviscerado | D25: Revision post lavadora | E25: Ultima inspeccion de pollo, para verificar ausencia de patologia. | F25: 03:30 - 11:50 / 11:50 - 21:15 | G25: N/A | H25: 2 | I25: 87 | J25: 28 | K25: Indefinido | L25: Variable | M25: 50 Min | N25: Pausa preparatoria | O25: SI | P25: N/A | Q25: Puesto de trabajo sobre tarima con demarcacion en color amarillo | R25: Puesto de trabajo sobre tarima sin mesa de trabajo. | S25: Uso de EPP tales como guantes anticorte, calzado de seguridad, gafas | T25: SI
A26: 25 | B26: Faenación | C26: Eviscerado | D26: Recuperacion de peritonitis | E26: Recolecta las carcasas que tengan buche penduloso. Transporta producto a estacion de reproceso (Ascitis, aeroceculitis y buche con alimento). Extrae buche y cogote de ave utilizando cuchillo. Realiza lavado interno y externo con lavado de canal | F26: 03:30 - 11:50 / 11:50 - 21:15 | G26: N/A | H26: 2 | I26: 87 | J26: 28 | K26: Indefinido | L26: Variable | M26: 50 Min | N26: Pausa preparatoria | O26: SI | T26: SI
A27: 26 | B27: Faenación | C27: Eviscerado | D27: Decomiso | E27: Recolecta bandejas con producto para decomiso . Traslada estas bandejas en carro con ruedas desde recolección a pesas. Realiza pesaje de producto en decomiso. Se dispone decomiso en trituradora a bacio triturador o bins de ser necesario. | F27: 03:30 - 11:50 / 11:50 - 21:15 | G27: N/A | H27: 2 | I27: 87 | J27: 0 | K27: Indefinido | L27: Variable | M27: 120 Min | N27: Pausa preparatoria | O27: SI | P27: Carro de arrastre | Q27: Zonas demarcadas y ibres de obstaculos | R27: Elementos con asa de agarre correspondiente | S27: uso de zapatos de seguridad, uso Fonos, y gafas | T27: SI
A28: 27 | B28: Faenación | C28: Eviscerado | D28: Auroceculitis | E28: Recolecta de gancheras todas las carcasas que tengan buche penduloso, Transporta producto a estación de reproceso (ascitis, aerosaculitis y buche con alimento) Extrae buche y cogote de ave utilizando cuchillo. Realizar lavado interno y externo del canal con ducha de pedal | F28: 03:30 - 11:50 / 11:50 - 21:15 | G28: N/A | H28: 2 | I28: 87 | J28: 28 | K28: Indefinido | L28: Variable | M28: 50 Min | N28: Pausa preparatoria | O28: SI | P28: cuchillo | Q28: Flujo de transito demarcado, cuenta con plataformas regulables para la altura al colgar el ave, cuenta con tarimas que forman pasillos para su transito | R28: Espacio fisico bajo techo sin exposicion a radiacion uv | S28: EPP como proteccion auditiva, calzado de seguridad, gafas y guantes anticorte | T28: SI
A29: 28 | B29: Faenación | C29: Eviscerado | D29: Jefe de línea | E29: Realizar labores de digitación computacional para el envío y recepción de correos electrónicos, preparación de ppt, y otros documentos. Supervisa en terreno de la correcta ejecución de los procedimientos de trabajo. Revisa superficies y maquinarias de trabajo. Programa puestos para colaboradores. Ejecuta Reuniones con jefaturas y colaboradores | F29: 03:30 - 11:50 / 11:50 - 21:15 | G29: N/A | H29: 2 | I29: 87 | J29: 28 | K29: Indefinido | L29: Variable | M29: 486 Min | N29: Pausa preparatoria | O29: SI | P29: computador | Q29: Flujo de transito demarcado, cuenta con plataformas regulables para la altura al colgar el ave, cuenta con tarimas que forman pasillos para su transito | R29: Espacio fisico bajo techo sin exposicion a radiacion uv | S29: Usa EPP tales como calzado de seguridad, casco y fonos, ademas usa dentro de sus labores radio de comunicación interna. | T29: SI
A30: 29 | B30: Faenación | C30: Eviscerado | D30: Supervisor | E30: Realizar labores de digitación computacional para el envío y recepción de correos electrónicos, preparación de ppt, y otros documentos.Supervisa en terreno de la correcta ejecución de los procedimientos de trabajo. Revisa superficies y maquinarias de trabajo.Programa puestos para colaboradores. Ejecuta Reuniones con jefaturas y colaboradores | F30: 03:30 - 11:50 / 11:50 - 21:15 | G30: N/A | H30: 2 | I30: 87 | J30: 28 | K30: Indefinido | L30: Variable | M30: 486 Min | N30: Pausa preparatoria - Pausa compensatoria | O30: SI | P30: Computador | Q30: Flujo de transito demarcado, cuenta con plataformas regulables para la altura al colgar el ave, cuenta con tarimas que forman pasillos para su transito | R30: Espacio fisico bajo techo sin exposicion a radiacion uv | S30: Usa EPP tales como calzado de seguridad, casco y fonos, ademas usa dentro de sus labores radio de comunicación interna. | T30: SI
A31: 30 | B31: Faenación | C31: Garras | D31: Cinta Decomiso | E31: Clasifica garras que vienen por la cinta tomandola con su mano y depositandola en otra linea esto es dependiendo del calibre y defectos que tengan. Reproceso de garras. | F31: 04:05 - 12:25 / 12:15 A 21:45 | G31: N/A | H31: 2 | I31: 23 | J31: 17 | K31: Indefinido | L31: Variable | M31: 60 Min | N31: Pausa preparatoria - Pausa compensatoria | O31: SI | P31: N/A | Q31: Pisos demarcados para transito sin barreras que dificulten el flujo de transito. | R31: Espacio fisico bajo techo sin exposicion a radiacion uv | S31: EPP como proteccion auditiva, calzado de seguridad y gafas | T31: SI | U31: Mov Repetitivo
A32: 31 | B32: Faenación | C32: Garras | D32: Embolsado Tolva/Seleccionador de Garras en Tolva | E32: Selecciona garras, las introduce a bolsa hasta completar. Con ambas manos saca bolsa desde el tacho y las desplaza a pesadora | F32: 04:05 - 12:25 / 12:15 A 21:45 | G32: N/A | H32: 2 | I32: 23 | J32: 17 | K32: Indefinido | L32: Variable | M32: 180 Min | N32: Pausa preparatoria - Pausa compensatoria | O32: SI | P32: N/A | Q32: Pisos demarcados para transito sin barreras que dificulten el flujo de transito. | R32: Mesa de trabajo a la altura necesaria libre de rayos uv | S32: EPP como proteccion auditiva, calzado de seguridad y gafas | T32: SI | U32: Mov Repetitivo (Amarillo) - MMC Levantamiento (Rojo)
A33: 32 | B33: Faenación | C33: Garras | D33: Pesador de garras | E33: Operario verifica peso de bolsa y deposita o retira producto para obtener peso adecuado, luego toma la bolsa la introduce en caja y la posiciona en la linea | F33: 04:05 - 12:25 / 12:15 A 21:45 | G33: N/A | H33: 2 | I33: 23 | J33: 17 | K33: Indefinido | L33: Variable | M33: 180 min | N33: Pausa preparatoria - Pausa compensatoria | O33: SI | P33: N/A | Q33: Pisos demarcados para transito sin barreras que dificulten el flujo de transito. | R33: Mesa de trabajo con polines para desplazamiento de cajas | S33: EPP como proteccion auditiva, calzado de seguridad y gafas | T33: SI | U33: Mov Repetitivo (Amarillo) - MMC Levantamiento (Amarillo)
A34: 33 | B34: Faenación | C34: Garras | D34: Repaso de callos | E34: El operario repasador de callos debe tomar la garra y pasarla por un orificio con un disco giratorio y abrasivo el cual se encargar de quitar el callo de la garra. | F34: 04:05 - 12:25 / 12:15 A 21:45 | G34: N/A | H34: 2 | I34: 23 | J34: 17 | K34: Indefinido | L34: Variable | M34: 180 Min | N34: Pausa preparatoria - Pausa compensatoria | O34: SI | P34: Maquina critica | Q34: Pisos demarcados para transito sin barreras que dificulten el flujo de transito. | R34: Puesto de trabajo espacio libre movilidad, mesa de alcance a la altura de 80 cm | S34: EPP como proteccion auditiva, calzado de seguridad y gafas | T34: SI | U34: Mov Repetitivo (Amarillo)
A35: 34 | B35: Faenación | C35: Garras | D35: Traslado de Garra Larga | E35: Se trasladan producto seleccionado (garra larga) desde tolvas. | F35: 04:05 - 12:25 / 12:15 A 21:45 | G35: N/A | H35: 2 | I35: 23 | J35: 17 | K35: Indefinido | L35: Variable | M35: 60 Min | N35: Pausa preparatoria - Pausa compensatoria | O35: SI | P35: N/A | Q35: Pisos demarcados para transito sin barreras que dificulten el flujo de transito. | R35: Puesto de trabajo con altura de la mesa de trabajo a la cadera sin exposicion a UV | S35: EPP como proteccion auditiva, calzado de seguridad y gafas | T35: SI | U35: Mov Repetitivo (Verde) - MMC Levantamiento (AMARILLO) - Empiuje (VERDE)
A36: 35 | B36: Faenación | C36: Garras | D36: Seleccionador de garra | E36: Selecciona garras, las introduce a bolsa hasta completar su llenado. | F36: 04:05 - 12:25 / 12:15 A 21:45 | G36: N/A | H36: 2 | I36: 23 | J36: 17 | K36: Indefinido | L36: Variable | M36: 180 min | N36: Pausa preparatoria - Pausa compensatoria | O36: SI | P36: N/A | Q36: Pisos demarcados para transito sin barreras que dificulten el flujo de transito. | S36: EPP como proteccion auditiva, calzado de seguridad y gafas | T36: SI | U36: Mov Repetitivo
A37: 36 | B37: Faenación | C37: Garras | D37: Embalando garras | E37: Colaborador tapa caja, indentifica tipo de etiqueta para luego depositarla en linea. | F37: 04:05 - 12:25 / 12:15 A 21:45 | G37: N/A | H37: 2 | I37: 23 | J37: 17 | K37: Indefinido | L37: Variable | M37: 120 Min | N37: Pausa preparatoria - Pausa compensatoria | O37: SI | P37: N/A | Q37: Pisos demarcados para transito sin barreras que dificulten el flujo de transito. | R37: Mesa de trabajo a la altura de la cadera con mesa de polines para desplazamiento de carga | S37: EPP como proteccion auditiva, calzado de seguridad y gafas | T37: SI | U37: Mov Repetitivo (Amarillo) - MMC Empuje (Verde)
A38: 37 | B38: Faenación | C38: Garras | D38: Cortadora de garra larga | E38: Colaboradora pone garras en maquina cortadora de nudillos, en espaciador de manera ordenada, para que maquina realice corte. Toma garras de bandeja y las deposita en recipiente para luego depositar una a una en espaciador. | F38: 04:05 - 12:25 / 12:15 A 21:45 | G38: N/A | H38: 2 | I38: 23 | J38: 17 | K38: Indefinido | L38: Variable | M38: 478 Min | N38: Pausa preparatoria - Pausa compensatoria | O38: SI | P38: N/A | Q38: Pisos demarcados para transito sin barreras que dificulten el flujo de transito. | R38: Equipo critico a la altura correspondiente para su manipulaci´on | S38: EPP como proteccion auditiva, calzado de seguridad y gafas | T38: SI | U38: Mov Repetitivo (Amarillo)
A39: 38 | B39: Faenación | C39: Garras | D39: Etiquetado en mesa de embalaje | E39: Colaborador desplaza caja de 20 kg a mesa de embalaje y etiqueta la caja para luego poner Tapa caja y la desplaza nuevamente a la cinta. | F39: 04:05 - 12:25 / 12:15 A 21:45 | G39: N/A | H39: 2 | I39: 23 | J39: 17 | K39: Indefinido | L39: Variable | M39: 120 min | N39: Pausa preparatoria - Pausa compensatoria | O39: SI | P39: N/A | Q39: Pisos demarcados para transito sin barreras que dificulten el flujo de transito. | R39: Mesa de trabajo a la altura de la cadera con mesa de polines para desplazamiento de carga | S39: EPP como proteccion auditiva, calzado de seguridad y gafas | T39: SI
A40: 39 | B40: Faenación | C40: Garras | D40: Nudillos | E40: Nudillos es depositado en bandeja. Colaborador ayuda ha deposito de este en bandeja, para luego depositar en caja. | F40: 04:05 - 12:25 / 12:15 A 21:45 | G40: N/A | H40: 2 | I40: 23 | J40: 17 | K40: Indefinido | L40: Variable | M40: 60 Min | N40: Pausa preparatoria - Pausa compensatoria | O40: SI | P40: N/A | Q40: Pisos demarcados para transito sin barreras que dificulten el flujo de transito. | R40: Mesa de trabajo a la altura de la cadera | S40: EPP como proteccion auditiva, calzado de seguridad y gafas | T40: SI | U40: Mov Repetitivo
...

Sheet Inicial
A1: N° | C1: Puesto de trabajo | D1: Tareas del puesto de trabajo | E1: Horario de funcionamiento | F1: Horas extras POR DIA | G1: Horas extras POR SEMANA | H1: N° Trabajadores Expuestos HOMBRE | I1: N° Trabajadores Expuestos MUJER | J1: Trabajo repetitivo de miembros superiores. | K1: Postura de trabajo estática - Forzada | L1: MMC Levantamiento/Descenso | M1: MMC Empuje/Arrastre | N1: Manejo manual de pacientes / personas | O1: Vibración de cuerpo completo | P1: Vibración segmento mano – brazo | Q1: Resultado identificación inicial
B2: Area | J2: ¿Existe una o más tareas donde utilice las manos y miembros superiores con una duración total de una hora o más durante la jornada laboral y con un tiempo total de 5 o más horas a la semana? Por ejemplo: Donde se tenga que armar, limpiar, apretar, lanzar, cortar, presionar, desarmar, atornillar, desatornillar, digitar. 1 tarea repetitiva: conjunto de ciclos de trabajo realizados por uno o más segmentos de las extremidades superiores, donde repetitividad se caracteriza por al menos uno de los siguientes criterios: i) El tiempo de ciclo es inferior a 30 segundos en promedio. ii) Los mismos patrones biomecánicos se repiten por más del 50% del ciclo. En general, el ritmo de trabajo está determinado por factor externo al trabajador, ejemplo, líneas de producción, velocidad de una máquina, entre otros | K2: Existen posturas de trabajo estáticas de cabeza/cuello, tronco y/o miembros superiores e inferiores, mantenidas durante más de 4 segundos, en la que se pueden dar ligeras variaciones alrededor de un mismo nivel de fuerza generado por los músculos y otras estructuras corporales? Por ejemplo: Donde se observe estar con la cabeza inclinada hacia adelante o atrás, cabeza rotada permanentemente hacia algún lado, hombros situados por delante de las caderas de manera continua, tronco rotado o inclinado para sostener o movilizar objetos | L2: Para el Levantamiento/Descenso/Transporte: ¿Existe levantamiento, descenso o transporte manual de un objeto de 3kg o más? Por ejemplo: Se observa que levanta, sostiene, transporta, desplaza, moviliza, ubica con precisión ordenando, apila, paletiza. | M2: Tracción/Empuje ¿Existe empuje o arrastre de una carga utilizando el cuerpo completo con 1 o 2 manos? Se observa el empuje y/o arrastre de diferentes maneras carros, plataformas con rueda, superficies deslizantes, detención de objetos en movimiento, camillas, camas, sillas de rueda, paletizadores, grúas de uso manual mecanizadas, formas de tracción y empuje hechizas, carretillas. No se considera empuje y arrastre carros motorizados y controlados manualmente (conducción) | N2: ¿Se realiza alguna actividad que requiere fuerza para empujar, tirar, levantar, descender, transferir o de alguna manera mover o sostener una persona o parte del cuerpo de una persona? *NOTA: La condición a identificar debe incluir la actividad de manipulación, ya sea que se realice con o sin dispositivos de asistencia. Esta condición está determinada por el riesgo asociado a las características de la carga humana que requiere control sensible de la masa corporal por parte del operador. | O2: Están los trabajadores en contacto con una fuente de vibración de cuerpo entero perceptible por el trabajador/a? Se presenta en cercanía de máquinas donde se percibe la vibración, superficies vibrantes donde se está de pie o sentado como en maquinaria pesada y de conducción. | P2: Están los trabajadores/as en contacto con una fuente de vibración perceptible por el trabajador del segmento mano-brazo? Por ejemplo: Se presenta en situaciones de manejo de herramientas neumáticas o eléctricas, atornilladores o destornilladores neumáticos o eléctricos, uso de herramientas con impacto como martillos, cinceles, herramientas percutoras como taladros
A3: =Datos!A2 -> 1 | B3: =Datos!B2 -> Faenación | C3: =Datos!C2 -> Colgado | D3: =Datos!D2 -> Colgado de aves | E3: =Datos!F2 -> 03:35 a 11:50 - 11:50 a 21:10 | F3: =Datos!G2 -> N/A | G3: =Datos!H2 -> 2 | H3: =Datos!I2 -> 36 | I3: =Datos!J2 -> 0 | J3: SI | K3: NO | L3: NO | M3: NO | N3: NO | O3: NO | P3: NO | Q3: =IF(AND(J3="NO",K3="NO",L3="NO",M3="NO",N3="NO",O3="NO",P3="NO"),"Ausencia total del riesgo, reevaluar cada 3 años con nueva identificación inicial","Aplicar identificación avanzada-condición aceptable para cada tipo de factor de riesgo identificado") -> Aplicar identificación avanzada-condición aceptable para cada tipo de factor de riesgo identificado
A4: =Datos!A3 -> 2 | B4: =Datos!B3 -> Faenación | C4: =Datos!C3 -> Colgado | D4: =Datos!D3 -> Revision de contenedores | E4: =Datos!F3 -> 03:35 a 11:50 - 11:50 a 21:11 | F4: =Datos!G3 -> N/A | G4: =Datos!H3 -> 2 | H4: =Datos!I3 -> 36 | I4: =Datos!J3 -> 0 | J4: SI | K4: NO | L4: NO | M4: NO | N4: NO | O4: NO | P4: NO | Q4: =IF(AND(J4="NO",K4="NO",L4="NO",M4="NO",N4="NO",O4="NO",P4="NO"),"Ausencia total del riesgo, reevaluar cada 3 años con nueva identificación inicial","Aplicar identificación avanzada-condición aceptable para cada tipo de factor de riesgo identificado") -> Aplicar identificación avanzada-condición aceptable para cada tipo de factor de riesgo identificado
A5: =Datos!A4 -> 3 | B5: =Datos!B4 -> Faenación | C5: =Datos!C4 -> Colgado | D5: =Datos!D4 -> Extracción de pollo mortecino | E5: =Datos!F4 -> 03:35 a 11:50 - 11:50 a 21:12 | F5: =Datos!G4 -> N/A | G5: =Datos!H4 -> 2 | H5: =Datos!I4 -> 36 | I5: =Datos!J4 -> 0 | J5: SI | K5: NO | L5: NO | M5: NO | N5: NO | O5: NO | P5: NO | Q5: =IF(AND(J5="NO",K5="NO",L5="NO",M5="NO",N5="NO",O5="NO",P5="NO"),"Ausencia total del riesgo, reevaluar cada 3 años con nueva identificación inicial","Aplicar identificación avanzada-condición aceptable para cada tipo de factor de riesgo identificado") -> Aplicar identificación avanzada-condición aceptable para cada tipo de factor de riesgo identificado
A6: =Datos!A5 -> 4 | B6: =Datos!B5 -> Faenación | C6: =Datos!C5 -> Colgado | D6: =Datos!D5 -> Gruero | E6: =Datos!F5 -> 03:35 a 11:50 - 11:50 a 21:13 | F6: =Datos!G5 -> N/A | G6: =Datos!H5 -> 2 | H6: =Datos!I5 -> 36 | I6: =Datos!J5 -> 0 | J6: NO | K6: NO | L6: NO | M6: NO | N6: NO | O6: NO | P6: NO | Q6: =IF(AND(J6="NO",K6="NO",L6="NO",M6="NO",N6="NO",O6="NO",P6="NO"),"Ausencia total del riesgo, reevaluar cada 3 años con nueva identificación inicial","Aplicar identificación avanzada-condición aceptable para cada tipo de factor de riesgo identificado") -> Ausencia total del riesgo, reevaluar cada 3 años con nueva identificación inicial
A7: =Datos!A6 -> 5 | B7: =Datos!B6 -> Faenación | C7: =Datos!C6 -> Colgado | D7: =Datos!D6 -> Jefe de línea | E7: =Datos!F6 -> 03:35 a 11:50 - 11:50 a 21:14 | F7: =Datos!G6 -> N/A | G7: =Datos!H6 -> 2 | H7: =Datos!I6 -> 36 | I7: =Datos!J6 -> 0 | J7: NO | K7: NO | L7: NO | M7: NO | N7: NO | O7: NO | P7: NO | Q7: =IF(AND(J7="NO",K7="NO",L7="NO",M7="NO",N7="NO",O7="NO",P7="NO"),"Ausencia total del riesgo, reevaluar cada 3 años con nueva identificación inicial","Aplicar identificación avanzada-condición aceptable para cada tipo de factor de riesgo identificado") -> Ausencia total del riesgo, reevaluar cada 3 años con nueva identificación inicial
A8: =Datos!A7 -> 6 | B8: =Datos!B7 -> Faenación | C8: =Datos!C7 -> Colgado | D8: =Datos!D7 -> Secretario | E8: =Datos!F7 -> 03:35 a 11:50 - 11:50 a 21:15 | F8: =Datos!G7 -> N/A | G8: =Datos!H7 -> 2 | H8: =Datos!I7 -> 36 | I8: =Datos!J7 -> 0 | J8: NO | K8: NO | L8: NO | M8: NO | N8: NO | O8: NO | P8: NO | Q8: =IF(AND(J8="NO",K8="NO",L8="NO",M8="NO",N8="NO",O8="NO",P8="NO"),"Ausencia total del riesgo, reevaluar cada 3 años con nueva identificación inicial","Aplicar identificación avanzada-condición aceptable para cada tipo de factor de riesgo identificado") -> Ausencia total del riesgo, reevaluar cada 3 años con nueva identificación inicial
A9: =Datos!A8 -> 7 | B9: =Datos!B8 -> Faenación | C9: =Datos!C8 -> Colgado | D9: =Datos!D8 -> Recepcion de guia | E9: =Datos!F8 -> 03:35 a 11:50 - 11:50 a 21:16 | F9: =Datos!G8 -> N/A | G9: =Datos!H8 -> 2 | H9: =Datos!I8 -> 36 | I9: =Datos!J8 -> 0 | J9: NO | K9: NO | L9: NO | M9: NO | N9: NO | O9: NO | P9: NO | Q9: =IF(AND(J9="NO",K9="NO",L9="NO",M9="NO",N9="NO",O9="NO",P9="NO"),"Ausencia total del riesgo, reevaluar cada 3 años con nueva identificación inicial","Aplicar identificación avanzada-condición aceptable para cada tipo de factor de riesgo identificado") -> Ausencia total del riesgo, reevaluar cada 3 años con nueva identificación inicial
A10: =Datos!A9 -> 8 | B10: =Datos!B9 -> Faenación | C10: =Datos!C9 -> Colgado | D10: =Datos!D9 -> Encargado de PC | E10: =Datos!F9 -> 03:35 a 11:50 - 11:50 a 21:17 | F10: =Datos!G9 -> N/A | G10: =Datos!H9 -> 2 | H10: =Datos!I9 -> 36 | I10: =Datos!J9 -> 0 | J10: NO | K10: NO | L10: NO | M10: NO | N10: NO | O10: NO | P10: NO | Q10: =IF(AND(J10="NO",K10="NO",L10="NO",M10="NO",N10="NO",O10="NO",P10="NO"),"Ausencia total del riesgo, reevaluar cada 3 años con nueva identificación inicial","Aplicar identificación avanzada-condición aceptable para cada tipo de factor de riesgo identificado") -> Ausencia total del riesgo, reevaluar cada 3 años con nueva identificación inicial
A11: =Datos!A10 -> 9 | B11: =Datos!B10 -> Faenación | C11: =Datos!C10 -> Sacrificio | D11: =Datos!D10 -> Pollo Chico | E11: =Datos!F10 -> 03:30 - 11:50 / 11:50 - 21:15 | F11: =Datos!G10 -> N/A | G11: =Datos!H10 -> 2 | H11: =Datos!I10 -> 8 | I11: =Datos!J10 -> 2 | J11: NO | K11: NO | L11: NO | M11: NO | N11: NO | O11: NO | P11: NO | Q11: =IF(AND(J11="NO",K11="NO",L11="NO",M11="NO",N11="NO",O11="NO",P11="NO"),"Ausencia total del riesgo, reevaluar cada 3 años con nueva identificación inicial","Aplicar identificación avanzada-condición aceptable para cada tipo de factor de riesgo identificado") -> Ausencia total del riesgo, reevaluar cada 3 años con nueva identificación inicial
A12: =Datos!A11 -> 10 | B12: =Datos!B11 -> Faenación | C12: =Datos!C11 -> Sacrificio | D12: =Datos!D11 -> Desgollador | E12: =Datos!F11 -> 03:30 - 11:50 / 11:50 - 21:15 | F12: =Datos!G11 -> N/A | G12: =Datos!H11 -> 2 | H12: =Datos!I11 -> 8 | I12: =Datos!J11 -> 2 | J12: SI | K12: NO | L12: NO | M12: NO | N12: NO | O12: NO | P12: NO | Q12: =IF(AND(J12="NO",K12="NO",L12="NO",M12="NO",N12="NO",O12="NO",P12="NO"),"Ausencia total del riesgo, reevaluar cada 3 años con nueva identificación inicial","Aplicar identificación avanzada-condición aceptable para cada tipo de factor de riesgo identificado") -> Aplicar identificación avanzada-condición aceptable para cada tipo de factor de riesgo identificado
A13: =Datos!A12 -> 11 | B13: =Datos!B12 -> Faenación | C13: =Datos!C12 -> Sacrificio | D13: =Datos!D12 -> Repase de pluma | E13: =Datos!F12 -> 03:30 - 11:50 / 11:50 - 21:15 | F13: =Datos!G12 -> N/A | G13: =Datos!H12 -> 2 | H13: =Datos!I12 -> 8 | I13: =Datos!J12 -> 2 | J13: SI | K13: NO | L13: NO | M13: NO | N13: NO | O13: NO | P13: NO | Q13: =IF(AND(J13="NO",K13="NO",L13="NO",M13="NO",N13="NO",O13="NO",P13="NO"),"Ausencia total del riesgo, reevaluar cada 3 años con nueva identificación inicial","Aplicar identificación avanzada-condición aceptable para cada tipo de factor de riesgo identificado") -> Aplicar identificación avanzada-condición aceptable para cada tipo de factor de riesgo identificado
A14: =Datos!A13 -> 12 | B14: =Datos!B13 -> Faenación | C14: =Datos!C13 -> Eviscerado | D14: =Datos!D13 -> Maquinista sacrificio | E14: =Datos!F13 -> 03:30 - 11:50 / 11:50 - 21:15 | F14: =Datos!G13 -> N/A | G14: =Datos!H13 -> 2 | H14: =Datos!I13 -> 87 | I14: =Datos!J13 -> 28 | J14: NO | K14: NO | L14: NO | M14: NO | N14: NO | O14: NO | P14: NO | Q14: =IF(AND(J14="NO",K14="NO",L14="NO",M14="NO",N14="NO",O14="NO",P14="NO"),"Ausencia total del riesgo, reevaluar cada 3 años con nueva identificación inicial","Aplicar identificación avanzada-condición aceptable para cada tipo de factor de riesgo identificado") -> Ausencia total del riesgo, reevaluar cada 3 años con nueva identificación inicial
... A63: =Datos!A62 -> 61 | B63: =Datos!B62 -> Faenación | C63: =Datos!C62 -> Empaque - Chiller | D63: =Datos!D62 -> Jefe de Línea | E63: =Datos!F62 -> 05:30-13:50 / 13:50-23:25 | F63: =Datos!G62 -> N/A | G63: =Datos!H62 -> 2 | H63: =Datos!I62 -> 2 | I63: =Datos!J62 -> 0 | J63: NO | K63: NO | L63: NO | M63: NO | N63: NO | O63: NO | P63: NO | Q63: =IF(AND(J63="NO",K63="NO",L63="NO",M63="NO",N63="NO",O63="NO",P63="NO"),"Ausencia total del riesgo, reevaluar cada 3 años con nueva identificación inicial","Aplicar identificación avanzada-condición aceptable para cada tipo de factor de riesgo identificado") -> Ausencia total del riesgo, reevaluar cada 3 años con nueva identificación inicial
A64: =Datos!A63 -> 0 | B64: =Datos!B63 -> 0 | C64: =Datos!C63 -> 0 | D64: =Datos!D63 -> 0 | E64: =Datos!F63 -> 0 | F64: =Datos!G63 -> 0 | G64: =Datos!H63 -> 0 | H64: =Datos!I63 -> 0 | I64: =Datos!J63 -> 0

Sheet Mov. Rep.
A1: MOVIMIENTO REPETITIVO | F1: Horas extras | H1: N° Trabajadores Expuestos | J1: Tabla II. IDENTIFICACIÓN AVANZADA – Trabajo Repetitivo de Miembros Superiores– Condición Aceptable | Q1: Tabla VI. IDENTIFICACIÓN AVANZADA – Tarea(s) Repetitiva(s) de miembros superiores –– Condición Crítica | X1: Plan de acción
A2: N° | B2: Área de trabajo | C2: Puesto de trabajo | D2: Tareas del puesto de trabajo | E2: Horario de funcionamiento | F2: Por dia | G2: Por Semana | H2: HOMBRE | I2: MUJER | J2: ¿Los miembros superiores trabajan por menos del 50% de la duración total de la tarea repetitiva? | K2: ¿Los codos se mantienen por debajo del nivel de los hombros por al menos el 90% del total de la duración de la(s) tarea(s) repetitiva? | L2: ¿Existe esfuerzo moderado ejercido por el trabajador (Percepción de Esfuerzo máximo 4 según Escala de Borg CR-10) ejercidas por el trabajador por no más de 1 hora mientras dura la(s) tarea(s) repetitiva? | M2: Ausencias de esfuerzo máximo (esfuerzo percibido = 5 o más en la Escala de Borg CR-10) | N2: Presencia de pausas programadas (excluyendo la pausa para almuerzo) | O2: ¿La duración total de las tareas repetitivas no excede las 4 horas totales dentro de la jornada laboral? | P2: Condición Aceptable | Q2: ¿Las acciones técnicas del miembro superior son tan rápidas que no se pueden contar con una simple observación directa? | R2: Uno o ambos brazos están realizando la tarea con el codo sobre el nivel del hombro por el 50% o más, del tiempo total de trabajo repetitivo | S2: ¿Se utiliza agarre en “pinza" (o todo tipo de tomada usando las puntas de los dedos) por más del 80% de la duración total del trabajo repetitivo? | T2: ¿Se aplica fuerza máxima por el trabajador (esfuerzo percibido = 5 o más en la Escala de Borg CR-10) por 10% o más del tiempo total de la tarea repetitiva? | U2: ¿No hay más de una pausa (Incluyendo el almuerzo) en un turno de 8 horas? | V2: ¿La duración total de las tareas repetitivas excede 4 horas totales dentro de la jornada laboral? | W2: Condición Crítica | X2: Fecha aplicación identificación avanzada | Y2: Medidas de control (administrativas) | Z2: Medidas de control (Ingeniería) | AA2: Responsable aplicación medida | AB2: Fecha de implementación medidas (Max 90 días) | AC2: Evidencia
A3: =Inicial!A3 -> 1 | B3: =Inicial!B3 -> Faenación | C3: =Inicial!C3 -> Colgado | D3: =Inicial!D3 -> Colgado de aves | E3: =IF(Inicial!J3="SI",Inicial!E3,"N/A") -> 03:35 a 11:50 - 11:50 a 21:10 | F3: =IF(Inicial!J3="SI",Inicial!F3,"N/A") -> N/A | G3: =IF(Inicial!J3="SI",Inicial!G3,"N/A") -> 2 | H3: =IF(Inicial!J3="SI",Inicial!H3,"N/A") -> 36 | I3: =IF(Inicial!J3="SI",Inicial!I3,"N/A") -> 0 | J3: NO | K3: SI | L3: SI | M3: SI | N3: SI | O3: SI | P3: =IF(OR(J3="NO",K3="NO",L3="NO",M3="NO",N3="NO",O3="NO"),"No Aceptable","Aceptable") -> No Aceptable | Q3: NO | R3: NO | S3: NO | T3: NO | U3: NO | V3: SI | W3: =IF(AND(Q3="NO",R3="NO",S3="NO",T3="NO",U3="NO",V3="NO"),"No Critico","Critico") -> Critico | Y3: Esto es una medida administrativa de ejemmplo | Z3: Esto es una medida Ingenieria de ejemmplo | AA3: Este es el responsable | AB3: 46023
A4: =Inicial!A4 -> 2 | B4: =Inicial!B4 -> Faenación | C4: =Inicial!C4 -> Colgado | D4: =Inicial!D4 -> Revision de contenedores | E4: =IF(Inicial!J4="SI",Inicial!E4,"N/A") -> 03:35 a 11:50 - 11:50 a 21:11 | F4: =IF(Inicial!J4="SI",Inicial!F4,"N/A") -> N/A | G4: =IF(Inicial!J4="SI",Inicial!G4,"N/A") -> 2 | H4: =IF(Inicial!J4="SI",Inicial!H4,"N/A") -> 36 | I4: =IF(Inicial!J4="SI",Inicial!I4,"N/A") -> 0 | J4: NO | K4: SI | L4: SI | M4: SI | N4: SI | O4: SI | P4: =IF(OR(J4="NO",K4="NO",L4="NO",M4="NO",N4="NO",O4="NO"),"No Aceptable","Aceptable") -> No Aceptable | Q4: NO | R4: NO | S4: NO | T4: NO | U4: NO | V4: NO | W4: =IF(AND(Q4="NO",R4="NO",S4="NO",T4="NO",U4="NO",V4="NO"),"No Critico","Critico") -> No Critico | X4: 45566
A5: =Inicial!A5 -> 3 | B5: =Inicial!B5 -> Faenación | C5: =Inicial!C5 -> Colgado | D5: =Inicial!D5 -> Extracción de pollo mortecino | E5: =IF(Inicial!J5="SI",Inicial!E5,"N/A") -> 03:35 a 11:50 - 11:50 a 21:12 | F5: =IF(Inicial!J5="SI",Inicial!F5,"N/A") -> N/A | G5: =IF(Inicial!J5="SI",Inicial!G5,"N/A") -> 2 | H5: =IF(Inicial!J5="SI",Inicial!H5,"N/A") -> 36 | I5: =IF(Inicial!J5="SI",Inicial!I5,"N/A") -> 0 | J5: SI | K5: SI | L5: SI | M5: SI | N5: NO | O5: SI | P5: =IF(OR(J5="NO",K5="NO",L5="NO",M5="NO",N5="NO",O5="NO"),"No Aceptable","Aceptable") -> No Aceptable | Q5: NO | R5: NO | S5: NO | T5: NO | U5: NO | V5: NO | W5: =IF(AND(Q5="NO",R5="NO",S5="NO",T5="NO",U5="NO",V5="NO"),"No Critico","Critico") -> No Critico | X5: 45566
A6: =Inicial!A6 -> 4 | B6: =Inicial!B6 -> Faenación | C6: =Inicial!C6 -> Colgado | D6: =Inicial!D6 -> Gruero | E6: =IF(Inicial!J6="SI",Inicial!E6,"N/A") -> N/A | F6: =IF(Inicial!J6="SI",Inicial!F6,"N/A") -> N/A | G6: =IF(Inicial!J6="SI",Inicial!G6,"N/A") -> N/A | H6: =IF(Inicial!J6="SI",Inicial!H6,"N/A") -> N/A | I6: =IF(Inicial!J6="SI",Inicial!I6,"N/A") -> N/A | P6: =IF(OR(J6="NO",K6="NO",L6="NO",M6="NO",N6="NO",O6="NO"),"No Aceptable","Aceptable") -> Aceptable | W6: =IF(AND(Q6="NO",R6="NO",S6="NO",T6="NO",U6="NO",V6="NO"),"No Critico","Critico") -> Critico
A7: =Inicial!A7 -> 5 | B7: =Inicial!B7 -> Faenación | C7: =Inicial!C7 -> Colgado | D7: =Inicial!D7 -> Jefe de línea | E7: =IF(Inicial!J7="SI",Inicial!E7,"N/A") -> N/A | F7: =IF(Inicial!J7="SI",Inicial!F7,"N/A") -> N/A | G7: =IF(Inicial!J7="SI",Inicial!G7,"N/A") -> N/A | H7: =IF(Inicial!J7="SI",Inicial!H7,"N/A") -> N/A | I7: =IF(Inicial!J7="SI",Inicial!I7,"N/A") -> N/A | P7: =IF(OR(J7="NO",K7="NO",L7="NO",M7="NO",N7="NO",O7="NO"),"No Aceptable","Aceptable") -> Aceptable | W7: =IF(AND(Q7="NO",R7="NO",S7="NO",T7="NO",U7="NO",V7="NO"),"No Critico","Critico") -> Critico
A8: =Inicial!A8 -> 6 | B8: =Inicial!B8 -> Faenación | C8: =Inicial!C8 -> Colgado | D8: =Inicial!D8 -> Secretario | E8: =IF(Inicial!J8="SI",Inicial!E8,"N/A") -> N/A | F8: =IF(Inicial!J8="SI",Inicial!F8,"N/A") -> N/A | G8: =IF(Inicial!J8="SI",Inicial!G8,"N/A") -> N/A | H8: =IF(Inicial!J8="SI",Inicial!H8,"N/A") -> N/A | I8: =IF(Inicial!J8="SI",Inicial!I8,"N/A") -> N/A | P8: =IF(OR(J8="NO",K8="NO",L8="NO",M8="NO",N8="NO",O8="NO"),"No Aceptable","Aceptable") -> Aceptable | W8: =IF(AND(Q8="NO",R8="NO",S8="NO",T8="NO",U8="NO",V8="NO"),"No Critico","Critico") -> Critico
A9: =Inicial!A9 -> 7 | B9: =Inicial!B9 -> Faenación | C9: =Inicial!C9 -> Colgado | D9: =Inicial!D9 -> Recepcion de guia | E9: =IF(Inicial!J9="SI",Inicial!E9,"N/A") -> N/A | F9: =IF(Inicial!J9="SI",Inicial!F9,"N/A") -> N/A | G9: =IF(Inicial!J9="SI",Inicial!G9,"N/A") -> N/A | H9: =IF(Inicial!J9="SI",Inicial!H9,"N/A") -> N/A | I9: =IF(Inicial!J9="SI",Inicial!I9,"N/A") -> N/A | P9: =IF(OR(J9="NO",K9="NO",L9="NO",M9="NO",N9="NO",O9="NO"),"No Aceptable","Aceptable") -> Aceptable | W9: =IF(AND(Q9="NO",R9="NO",S9="NO",T9="NO",U9="NO",V9="NO"),"No Critico","Critico") -> Critico
A10: =Inicial!A10 -> 8 | B10: =Inicial!B10 -> Faenación | C10: =Inicial!C10 -> Colgado | D10: =Inicial!D10 -> Encargado de PC | E10: =IF(Inicial!J10="SI",Inicial!E10,"N/A") -> N/A | F10: =IF(Inicial!J10="SI",Inicial!F10,"N/A") -> N/A | G10: =IF(Inicial!J10="SI",Inicial!G10,"N/A") -> N/A | H10: =IF(Inicial!J10="SI",Inicial!H10,"N/A") -> N/A | I10: =IF(Inicial!J10="SI",Inicial!I10,"N/A") -> N/A | P10: =IF(OR(J10="NO",K10="NO",L10="NO",M10="NO",N10="NO",O10="NO"),"No Aceptable","Aceptable") -> Aceptable | W10: =IF(AND(Q10="NO",R10="NO",S10="NO",T10="NO",U10="NO",V10="NO"),"No Critico","Critico") -> Critico
A11: =Inicial!A11 -> 9 | B11: =Inicial!B11 -> Faenación | C11: =Inicial!C11 -> Sacrificio | D11: =Inicial!D11 -> Pollo Chico | E11: =IF(Inicial!J11="SI",Inicial!E11,"N/A") -> N/A | F11: =IF(Inicial!J11="SI",Inicial!F11,"N/A") -> N/A | G11: =IF(Inicial!J11="SI",Inicial!G11,"N/A") -> N/A | H11: =IF(Inicial!J11="SI",Inicial!H11,"N/A") -> N/A | I11: =IF(Inicial!J11="SI",Inicial!I11,"N/A") -> N/A | P11: =IF(OR(J11="NO",K11="NO",L11="NO",M11="NO",N11="NO",O11="NO"),"No Aceptable","Aceptable") -> Aceptable | W11: =IF(AND(Q11="NO",R11="NO",S11="NO",T11="NO",U11="NO",V11="NO"),"No Critico","Critico") -> Critico
A12: =Inicial!A12 -> 10 | B12: =Inicial!B12 -> Faenación | C12: =Inicial!C12 -> Sacrificio | D12: =Inicial!D12 -> Desgollador | E12: =IF(Inicial!J12="SI",Inicial!E12,"N/A") -> 03:30 - 11:50 / 11:50 - 21:15 | F12: =IF(Inicial!J12="SI",Inicial!F12,"N/A") -> N/A | G12: =IF(Inicial!J12="SI",Inicial!G12,"N/A") -> 2 | H12: =IF(Inicial!J12="SI",Inicial!H12,"N/A") -> 8 | I12: =IF(Inicial!J12="SI",Inicial!I12,"N/A") -> 2 | J12: NO | K12: SI | L12: SI | M12: SI | N12: NO | O12: SI | P12: =IF(OR(J12="NO",K12="NO",L12="NO",M12="NO",N12="NO",O12="NO"),"No Aceptable","Aceptable") -> No Aceptable | Q12: NO | R12: NO | S12: NO | T12: NO | U12: NO | V12: NO | W12: =IF(AND(Q12="NO",R12="NO",S12="NO",T12="NO",U12="NO",V12="NO"),"No Critico","Critico") -> No Critico
A13: =Inicial!A13 -> 11 | B13: =Inicial!B13 -> Faenación | C13: =Inicial!C13 -> Sacrificio | D13: =Inicial!D13 -> Repase de pluma | E13: =IF(Inicial!J13="SI",Inicial!E13,"N/A") -> 03:30 - 11:50 / 11:50 - 21:15 | F13: =IF(Inicial!J13="SI",Inicial!F13,"N/A") -> N/A | G13: =IF(Inicial!J13="SI",Inicial!G13,"N/A") -> 2 | H13: =IF(Inicial!J13="SI",Inicial!H13,"N/A") -> 8 | I13: =IF(Inicial!J13="SI",Inicial!I13,"N/A") -> 2 | J13: SI | K13: SI | L13: SI | M13: SI | N13: NO | O13: SI | P13: =IF(OR(J13="NO",K13="NO",L13="NO",M13="NO",N13="NO",O13="NO"),"No Aceptable","Aceptable") -> No Aceptable | Q13: NO | R13: NO | S13: NO | T13: NO | U13: NO | V13: NO | W13: =IF(AND(Q13="NO",R13="NO",S13="NO",T13="NO",U13="NO",V13="NO"),"No Critico","Critico") -> No Critico
A14: =Inicial!A14 -> 12 | B14: =Inicial!B14 -> Faenación | C14: =Inicial!C14 -> Eviscerado | D14: =Inicial!D14 -> Maquinista sacrificio | E14: =IF(Inicial!J14="SI",Inicial!E14,"N/A") -> N/A | F14: =IF(Inicial!J14="SI",Inicial!F14,"N/A") -> N/A | G14: =IF(Inicial!J14="SI",Inicial!G14,"N/A") -> N/A | H14: =IF(Inicial!J14="SI",Inicial!H14,"N/A") -> N/A | I14: =IF(Inicial!J14="SI",Inicial!I14,"N/A") -> N/A | P14: =IF(OR(J14="NO",K14="NO",L14="NO",M14="NO",N14="NO",O14="NO"),"No Aceptable","Aceptable") -> Aceptable | W14: =IF(AND(Q14="NO",R14="NO",S14="NO",T14="NO",U14="NO",V14="NO"),"No Critico","Critico") -> Critico
A15: =Inicial!A15 -> 13 | B15: =Inicial!B15 -> Faenación | C15: =Inicial!C15 -> Eviscerado | D15: =Inicial!D15 -> Maquinista eviscerado | E15: =IF(Inicial!J15="SI",Inicial!E15,"N/A") -> 03:30 - 11:50 / 11:50 - 21:15 | F15: =IF(Inicial!J15="SI",Inicial!F15,"N/A") -> N/A | G15: =IF(Inicial!J15="SI",Inicial!G15,"N/A") -> 2 | H15: =IF(Inicial!J15="SI",Inicial!H15,"N/A") -> 87 | I15: =IF(Inicial!J15="SI",Inicial!I15,"N/A") -> 28 | J15: SI | K15: SI | L15: SI | M15: SI | N15: SI | O15: SI | P15: =IF(OR(J15="NO",K15="NO",L15="NO",M15="NO",N15="NO",O15="NO"),"No Aceptable","Aceptable") -> Aceptable | W15: =IF(AND(Q15="NO",R15="NO",S15="NO",T15="NO",U15="NO",V15="NO"),"No Critico","Critico") -> Critico
A16: =Inicial!A16 -> 14 | B16: =Inicial!B16 -> Faenación | C16: =Inicial!C16 -> Eviscerado | D16: =Inicial!D16 -> Transferidor | E16: =IF(Inicial!J16="SI",Inicial!E16,"N/A") -> 03:30 - 11:50 / 11:50 - 21:15 | F16: =IF(Inicial!J16="SI",Inicial!F16,"N/A") -> N/A | G16: =IF(Inicial!J16="SI",Inicial!G16,"N/A") -> 2 | H16: =IF(Inicial!J16="SI",Inicial!H16,"N/A") -> 87 | I16: =IF(Inicial!J16="SI",Inicial!I16,"N/A") -> 28 | J16: SI | K16: SI | L16: SI | M16: SI | N16: NO | O16: SI | P16: =IF(OR(J16="NO",K16="NO",L16="NO",M16="NO",N16="NO",O16="NO"),"No Aceptable","Aceptable") -> No Aceptable | Q16: NO | R16: NO | S16: NO | T16: NO | U16: NO | V16: NO | W16: =IF(AND(Q16="NO",R16="NO",S16="NO",T16="NO",U16="NO",V16="NO"),"No Critico","Critico") -> No Critico
A17: =Inicial!A17 -> 15 | B17: =Inicial!B17 -> Faenación | C17: =Inicial!C17 -> Eviscerado | D17: =Inicial!D17 -> Expurgo Visceras | E17: =IF(Inicial!J17="SI",Inicial!E17,"N/A") -> 03:30 - 11:50 / 11:50 - 21:15 | F17: =IF(Inicial!J17="SI",Inicial!F17,"N/A") -> N/A | G17: =IF(Inicial!J17="SI",Inicial!G17,"N/A") -> 2 | H17: =IF(Inicial!J17="SI",Inicial!H17,"N/A") -> 87 | I17: =IF(Inicial!J17="SI",Inicial!I17,"N/A") -> 28 | J17: NO | K17: SI | L17: SI | M17: SI | N17: NO | O17: SI | P17: =IF(OR(J17="NO",K17="NO",L17="NO",M17="NO",N17="NO",O17="NO"),"No Aceptable","Aceptable") -> No Aceptable | Q17: NO | R17: NO | S17: NO | T17: NO | U17: NO | V17: NO | W17: =IF(AND(Q17="NO",R17="NO",S17="NO",T17="NO",U17="NO",V17="NO"),"No Critico","Critico") -> No Critico
A18: =Inicial!A18 -> 16 | B18: =Inicial!B18 -> Faenación | C18: =Inicial!C18 -> Eviscerado | D18: =Inicial!D18 -> Repaso de contre | E18: =IF(Inicial!J18="SI",Inicial!E18,"N/A") -> 03:30 - 11:50 / 11:50 - 21:15 | F18: =IF(Inicial!J18="SI",Inicial!F18,"N/A") -> N/A | G18: =IF(Inicial!J18="SI",Inicial!G18,"N/A") -> 2 | H18: =IF(Inicial!J18="SI",Inicial!H18,"N/A") -> 87 | I18: =IF(Inicial!J18="SI",Inicial!I18,"N/A") -> 28 | J18: NO | K18: SI | L18: SI | M18: SI | N18: NO | O18: SI | P18: =IF(OR(J18="NO",K18="NO",L18="NO",M18="NO",N18="NO",O18="NO"),"No Aceptable","Aceptable") -> No Aceptable | Q18: NO | R18: NO | S18: NO | T18: NO | U18: NO | V18: NO | W18: =IF(AND(Q18="NO",R18="NO",S18="NO",T18="NO",U18="NO",V18="NO"),"No Critico","Critico") -> No Critico
A19: =Inicial!A19 -> 17 | B19: =Inicial!B19 -> Faenación | C19: =Inicial!C19 -> Eviscerado | D19: =Inicial!D19 -> Panas | E19: =IF(Inicial!J19="SI",Inicial!E19,"N/A") -> 03:30 - 11:50 / 11:50 - 21:15 | F19: =IF(Inicial!J19="SI",Inicial!F19,"N/A") -> N/A | G19: =IF(Inicial!J19="SI",Inicial!G19,"N/A") -> 2 | H19: =IF(Inicial!J19="SI",Inicial!H19,"N/A") -> 87 | I19: =IF(Inicial!J19="SI",Inicial!I19,"N/A") -> 28 | J19: NO | K19: SI | L19: SI | M19: SI | N19: NO | O19: SI | P19: =IF(OR(J19="NO",K19="NO",L19="NO",M19="NO",N19="NO",O19="NO"),"No Aceptable","Aceptable") -> No Aceptable | Q19: NO | R19: NO | S19: NO | T19: NO | U19: NO | V19: NO | W19: =IF(AND(Q19="NO",R19="NO",S19="NO",T19="NO",U19="NO",V19="NO"),"No Critico","Critico") -> No Critico
A20: =Inicial!A20 -> 18 | B20: =Inicial!B20 -> Faenación | C20: =Inicial!C20 -> Eviscerado | D20: =Inicial!D20 -> Expurgo Inscision | E20: =IF(Inicial!J20="SI",Inicial!E20,"N/A") -> 03:30 - 11:50 / 11:50 - 21:15 | F20: =IF(Inicial!J20="SI",Inicial!F20,"N/A") -> N/A | G20: =IF(Inicial!J20="SI",Inicial!G20,"N/A") -> 2 | H20: =IF(Inicial!J20="SI",Inicial!H20,"N/A") -> 87 | I20: =IF(Inicial!J20="SI",Inicial!I20,"N/A") -> 28 | J20: NO | K20: SI | L20: SI | M20: SI | N20: NO | O20: SI | P20: =IF(OR(J20="NO",K20="NO",L20="NO",M20="NO",N20="NO",O20="NO"),"No Aceptable","Aceptable") -> No Aceptable | Q20: NO | R20: NO | S20: NO | T20: NO | U20: NO | V20: NO | W20: =IF(AND(Q20="NO",R20="NO",S20="NO",T20="NO",U20="NO",V20="NO"),"No Critico","Critico") -> No Critico
A21: =Inicial!A21 -> 19 | B21: =Inicial!B21 -> Faenación | C21: =Inicial!C21 -> Eviscerado | D21: =Inicial!D21 -> Lavado/ Aspirado | E21: =IF(Inicial!J21="SI",Inicial!E21,"N/A") -> 03:30 - 11:50 / 11:50 - 21:15 | F21: =IF(Inicial!J21="SI",Inicial!F21,"N/A") -> N/A | G21: =IF(Inicial!J21="SI",Inicial!G21,"N/A") -> 2 | H21: =IF(Inicial!J21="SI",Inicial!H21,"N/A") -> 87 | I21: =IF(Inicial!J21="SI",Inicial!I21,"N/A") -> 28 | J21: NO | K21: SI | L21: SI | M21: SI | N21: NO | O21: SI | P21: =IF(OR(J21="NO",K21="NO",L21="NO",M21="NO",N21="NO",O21="NO"),"No Aceptable","Aceptable") -> No Aceptable | Q21: NO | R21: NO | S21: NO | T21: NO | U21: NO | V21: NO | W21: =IF(AND(Q21="NO",R21="NO",S21="NO",T21="NO",U21="NO",V21="NO"),"No Critico","Critico") -> No Critico
A22: =Inicial!A22 -> 20 | B22: =Inicial!B22 -> Faenación | C22: =Inicial!C22 -> Eviscerado | D22: =Inicial!D22 -> Repase de visceras | E22: =IF(Inicial!J22="SI",Inicial!E22,"N/A") -> N/A | F22: =IF(Inicial!J22="SI",Inicial!F22,"N/A") -> N/A | G22: =IF(Inicial!J22="SI",Inicial!G22,"N/A") -> N/A | H22: =IF(Inicial!J22="SI",Inicial!H22,"N/A") -> N/A | I22: =IF(Inicial!J22="SI",Inicial!I22,"N/A") -> N/A | P22: =IF(OR(J22="NO",K22="NO",L22="NO",M22="NO",N22="NO",O22="NO"),"No Aceptable","Aceptable") -> Aceptable | W22: =IF(AND(Q22="NO",R22="NO",S22="NO",T22="NO",U22="NO",V22="NO"),"No Critico","Critico") -> Critico
A23: =Inicial!A23 -> 21 | B23: =Inicial!B23 -> Faenación | C23: =Inicial!C23 -> Eviscerado | D23: =Inicial!D23 -> Recolgado | E23: =IF(Inicial!J23="SI",Inicial!E23,"N/A") -> 03:30 - 11:50 / 11:50 - 21:15 | F23: =IF(Inicial!J23="SI",Inicial!F23,"N/A") -> N/A | G23: =IF(Inicial!J23="SI",Inicial!G23,"N/A") -> 2 | H23: =IF(Inicial!J23="SI",Inicial!H23,"N/A") -> 87 | I23: =IF(Inicial!J23="SI",Inicial!I23,"N/A") -> 28 | J23: SI | K23: SI | L23: SI | M23: SI | N23: NO | O23: SI | P23: =IF(OR(J23="NO",K23="NO",L23="NO",M23="NO",N23="NO",O23="NO"),"No Aceptable","Aceptable") -> No Aceptable | Q23: NO | R23: NO | S23: NO | T23: NO | U23: NO | V23: NO | W23: =IF(AND(Q23="NO",R23="NO",S23="NO",T23="NO",U23="NO",V23="NO"),"No Critico","Critico") -> No Critico
A24: =Inicial!A24 -> 22 | B24: =Inicial!B24 -> Faenación | C24: =Inicial!C24 -> Eviscerado | D24: =Inicial!D24 -> Expurgo de Ala | E24: =IF(Inicial!J24="SI",Inicial!E24,"N/A") -> 03:30 - 11:50 / 11:50 - 21:15 | F24: =IF(Inicial!J24="SI",Inicial!F24,"N/A") -> N/A | G24: =IF(Inicial!J24="SI",Inicial!G24,"N/A") -> 2 | H24: =IF(Inicial!J24="SI",Inicial!H24,"N/A") -> 87 | I24: =IF(Inicial!J24="SI",Inicial!I24,"N/A") -> 28 | J24: NO | K24: SI | L24: SI | M24: SI | N24: NO | O24: SI | P24: =IF(OR(J24="NO",K24="NO",L24="NO",M24="NO",N24="NO",O24="NO"),"No Aceptable","Aceptable") -> No Aceptable | Q24: NO | R24: NO | S24: NO | T24: NO | U24: NO | V24: NO | W24: =IF(AND(Q24="NO",R24="NO",S24="NO",T24="NO",U24="NO",V24="NO"),"No Critico","Critico") -> No Critico
A25: =Inicial!A25 -> 23 | B25: =Inicial!B25 -> Faenación | C25: =Inicial!C25 -> Eviscerado | D25: =Inicial!D25 -> Punto de inspeccion | E25: =IF(Inicial!J25="SI",Inicial!E25,"N/A") -> 03:30 - 11:50 / 11:50 - 21:15 | F25: =IF(Inicial!J25="SI",Inicial!F25,"N/A") -> N/A | G25: =IF(Inicial!J25="SI",Inicial!G25,"N/A") -> 2 | H25: =IF(Inicial!J25="SI",Inicial!H25,"N/A") -> 87 | I25: =IF(Inicial!J25="SI",Inicial!I25,"N/A") -> 28 | J25: SI | K25: SI | L25: SI | M25: SI | N25: NO | O25: SI | P25: =IF(OR(J25="NO",K25="NO",L25="NO",M25="NO",N25="NO",O25="NO"),"No Aceptable","Aceptable") -> No Aceptable | Q25: NO | R25: NO | S25: NO | T25: NO | U25: NO | V25: NO | W25: =IF(AND(Q25="NO",R25="NO",S25="NO",T25="NO",U25="NO",V25="NO"),"No Critico","Critico") -> No Critico
